<?xml version="1.0" encoding="utf-8"?>
<robot name="ur10e_robot" path="ur_description/urdf/ur10e.urdf">
	<transmission name="shoulder_pan_trans">
		<type>transmission_interface/SimpleTransmission</type>
		<joint name="shoulder_pan_joint">
			<hardwareInterface>hardware_interface/PositionJointInterface</hardwareInterface>
		</joint>
		<actuator name="shoulder_pan_motor">
			<mechanicalReduction>1</mechanicalReduction>
		</actuator>
	</transmission>
	<transmission name="shoulder_lift_trans">
		<type>transmission_interface/SimpleTransmission</type>
		<joint name="shoulder_lift_joint">
			<hardwareInterface>hardware_interface/PositionJointInterface</hardwareInterface>
		</joint>
		<actuator name="shoulder_lift_motor">
			<mechanicalReduction>1</mechanicalReduction>
		</actuator>
	</transmission>
	<transmission name="elbow_trans">
		<type>transmission_interface/SimpleTransmission</type>
		<joint name="elbow_joint">
			<hardwareInterface>hardware_interface/PositionJointInterface</hardwareInterface>
		</joint>
		<actuator name="elbow_motor">
			<mechanicalReduction>1</mechanicalReduction>
		</actuator>
	</transmission>
	<transmission name="wrist_1_trans">
		<type>transmission_interface/SimpleTransmission</type>
		<joint name="wrist_1_joint">
			<hardwareInterface>hardware_interface/PositionJointInterface</hardwareInterface>
		</joint>
		<actuator name="wrist_1_motor">
			<mechanicalReduction>1</mechanicalReduction>
		</actuator>
	</transmission>
	<transmission name="wrist_2_trans">
		<type>transmission_interface/SimpleTransmission</type>
		<joint name="wrist_2_joint">
			<hardwareInterface>hardware_interface/PositionJointInterface</hardwareInterface>
		</joint>
		<actuator name="wrist_2_motor">
			<mechanicalReduction>1</mechanicalReduction>
		</actuator>
	</transmission>
	<transmission name="wrist_3_trans">
		<type>transmission_interface/SimpleTransmission</type>
		<joint name="wrist_3_joint">
			<hardwareInterface>hardware_interface/PositionJointInterface</hardwareInterface>
		</joint>
		<actuator name="wrist_3_motor">
			<mechanicalReduction>1</mechanicalReduction>
		</actuator>
	</transmission>
	<link name="base_link"></link>
	<link name="base_link_inertia">
		<visual>
			<origin rpy="0 0 3.141592653589793" xyz="0 0 0"></origin>
			<geometry>
				<mesh filename="package://ur_description/meshes/ur10e/visual/base.dae"></mesh>
			</geometry>
			<material name="LightGrey">
				<color rgba="0.7 0.7 0.7 1.0"></color>
			</material>
		</visual>
		<collision>
			<geometry>
				<sphere radius="0.107272"></sphere>
			</geometry>
			<origin xyz="6.441097259521497e-07 1.1639127731323243e-05 0.0496443499687567" rpy="0 0 0"></origin>
		</collision>
		<inertial>
			<mass value="4.0"></mass>
			<origin rpy="0 0 0" xyz="0 0 0"></origin>
			<inertia ixx="0.0061063308908" ixy="0.0" ixz="0.0" iyy="0.0061063308908" iyz="0.0" izz="0.01125"></inertia>
		</inertial>
	</link>
	<link name="shoulder_link">
		<visual>
			<origin rpy="0 0 3.141592653589793" xyz="0 0 0"></origin>
			<geometry>
				<mesh filename="package://ur_description/meshes/ur10e/visual/shoulder.dae"></mesh>
			</geometry>
			<material name="LightGrey">
				<color rgba="0.7 0.7 0.7 1.0"></color>
			</material>
		</visual>
		<collision>
			<geometry>
				<sphere radius="0.122019"></sphere>
			</geometry>
			<origin xyz="-0.00029029834541131595 -0.008731248094137434 -0.001250573391652493" rpy="0 0 0"></origin>
		</collision>
		<inertial>
			<mass value="7.778"></mass>
			<origin rpy="0 0 0" xyz="0 0 0"></origin>
			<inertia ixx="0.03147431257693659" ixy="0.0" ixz="0.0" iyy="0.03147431257693659" iyz="0.0" izz="0.021875624999999996"></inertia>
		</inertial>
	</link>
	<link name="upper_arm_link">
		<visual>
			<origin rpy="1.5707963267948966 0 -1.5707963267948966" xyz="0 0 0.1762"></origin>
			<geometry>
				<mesh filename="package://ur_description/meshes/ur10e/visual/upperarm.dae"></mesh>
			</geometry>
			<material name="LightGrey">
				<color rgba="0.7 0.7 0.7 1.0"></color>
			</material>
		</visual>
		<collision>
			<geometry>
				<sphere radius="0.092386"></sphere>
			</geometry>
			<origin xyz="-0.6070419690375328 1.428049325942994e-06 0.16623906538414956" rpy="0 0 0"></origin>
		</collision>
		<collision>
			<geometry>
				<sphere radius="0.107354"></sphere>
			</geometry>
			<origin xyz="0.00041303096246719795 5.428049325942993e-06 0.17160506538414955" rpy="0 0 0"></origin>
		</collision>
		<collision>
			<geometry>
				<sphere radius="0.104797"></sphere>
			</geometry>
			<origin xyz="-0.5168849690375328 3.4280493259429935e-06 0.16899706538414955" rpy="0 0 0"></origin>
		</collision>
		<collision>
			<geometry>
				<sphere radius="0.10311"></sphere>
			</geometry>
			<origin xyz="-0.42341096903753284 9.428049325942994e-06 0.17053706538414956" rpy="0 0 0"></origin>
		</collision>
		<collision>
			<geometry>
				<sphere radius="0.111557"></sphere>
			</geometry>
			<origin xyz="-0.32826696903753283 1.2428049325942994e-05 0.17244706538414956" rpy="0 0 0"></origin>
		</collision>
		<collision>
			<geometry>
				<sphere radius="0.113496"></sphere>
			</geometry>
			<origin xyz="-0.2252829690375328 1.8428049325942992e-05 0.17491006538414955" rpy="0 0 0"></origin>
		</collision>
		<collision>
			<geometry>
				<sphere radius="0.11601"></sphere>
			</geometry>
			<origin xyz="-0.1291979690375328 2.6428049325942993e-05 0.17046706538414957" rpy="0 0 0"></origin>
		</collision>
		<collision>
			<geometry>
				<sphere radius="0.1175"></sphere>
			</geometry>
			<origin xyz="-0.02926196903753281 6.4280493259429935e-06 0.17915506538414955" rpy="0 0 0"></origin>
		</collision>
		<inertial>
			<mass value="12.93"></mass>
			<origin rpy="0 1.5707963267948966 0" xyz="-0.306 0.0 0.175"></origin>
			<inertia ixx="0.42175380379841093" ixy="0.0" ixz="0.0" iyy="0.42175380379841093" iyz="0.0" izz="0.03636562499999999"></inertia>
		</inertial>
	</link>
	<link name="forearm_link">
		<visual>
			<origin rpy="1.5707963267948966 0 -1.5707963267948966" xyz="0 0 0.0393"></origin>
			<geometry>
				<mesh filename="package://ur_description/meshes/ur10e/visual/forearm.dae"></mesh>
			</geometry>
			<material name="LightGrey">
				<color rgba="0.7 0.7 0.7 1.0"></color>
			</material>
		</visual>
		<collision>
			<geometry>
				<sphere radius="0.077019"></sphere>
			</geometry>
			<origin xyz="-0.5630055789709092 6.197440385818482e-06 0.0494461657419205" rpy="0 0 0"></origin>
		</collision>
		<collision>
			<geometry>
				<sphere radius="0.081708"></sphere>
			</geometry>
			<origin xyz="-0.48916857897090915 -8.025596141815185e-07 0.0491121657419205" rpy="0 0 0"></origin>
		</collision>
		<collision>
			<geometry>
				<sphere radius="0.079711"></sphere>
			</geometry>
			<origin xyz="-0.4060235789709091 -5.802559614181519e-06 0.0465401657419205" rpy="0 0 0"></origin>
		</collision>
		<collision>
			<geometry>
				<sphere radius="0.083293"></sphere>
			</geometry>
			<origin xyz="-0.3313565789709091 -1.1802559614181519e-05 0.0518921657419205" rpy="0 0 0"></origin>
		</collision>
		<collision>
			<geometry>
				<sphere radius="0.081784"></sphere>
			</geometry>
			<origin xyz="-0.2526825789709091 -1.880255961418152e-05 0.048549165741920496" rpy="0 0 0"></origin>
		</collision>
		<collision>
			<geometry>
				<sphere radius="0.087833"></sphere>
			</geometry>
			<origin xyz="-0.16280557897090914 0.0008421974403858185 0.046586165741920496" rpy="0 0 0"></origin>
		</collision>
		<collision>
			<geometry>
				<sphere radius="0.088772"></sphere>
			</geometry>
			<origin xyz="-0.07611557897090912 -0.00018180255961418152 0.0427021657419205" rpy="0 0 0"></origin>
		</collision>
		<collision>
			<geometry>
				<sphere radius="0.072633"></sphere>
			</geometry>
			<origin xyz="-0.0009155789709091033 0.0003531974403858185 0.057430165741920496" rpy="0 0 0"></origin>
		</collision>
		<inertial>
			<mass value="3.87"></mass>
			<origin rpy="0 1.5707963267948966 0" xyz="-0.285775 0.0 0.0393"></origin>
			<inertia ixx="0.11079302548902206" ixy="0.0" ixz="0.0" iyy="0.11079302548902206" iyz="0.0" izz="0.010884375"></inertia>
		</inertial>
	</link>
	<link name="wrist_1_link">
		<visual>
			<origin rpy="1.5707963267948966 0 0" xyz="0 0 -0.135"></origin>
			<geometry>
				<mesh filename="package://ur_description/meshes/ur10e/visual/wrist1.dae"></mesh>
			</geometry>
			<material name="LightGrey">
				<color rgba="0.7 0.7 0.7 1.0"></color>
			</material>
		</visual>
		<collision>
			<geometry>
				<sphere radius="0.079587"></sphere>
			</geometry>
			<origin xyz="-3.246590495109558e-06 -0.008833108022451398 -0.010040264912605295" rpy="0 0 0"></origin>
		</collision>
		<inertial>
			<mass value="1.96"></mass>
			<origin rpy="0 0 0" xyz="0 0 0"></origin>
			<inertia ixx="0.005108247956699999" ixy="0.0" ixz="0.0" iyy="0.005108247956699999" iyz="0.0" izz="0.005512499999999999"></inertia>
		</inertial>
	</link>
	<link name="wrist_2_link">
		<visual>
			<origin rpy="0 0 0" xyz="0 0 -0.12"></origin>
			<geometry>
				<mesh filename="package://ur_description/meshes/ur10e/visual/wrist2.dae"></mesh>
			</geometry>
			<material name="LightGrey">
				<color rgba="0.7 0.7 0.7 1.0"></color>
			</material>
		</visual>
		<collision>
			<geometry>
				<sphere radius="0.081313"></sphere>
			</geometry>
			<origin xyz="-0.00031414731042869374 0.00797893117351033 -0.0026956766253854966" rpy="0 0 0"></origin>
		</collision>
		<inertial>
			<mass value="1.96"></mass>
			<origin rpy="0 0 0" xyz="0 0 0"></origin>
			<inertia ixx="0.005108247956699999" ixy="0.0" ixz="0.0" iyy="0.005108247956699999" iyz="0.0" izz="0.005512499999999999"></inertia>
		</inertial>
	</link>
	<link name="wrist_3_link">
		<visual>
			<origin rpy="1.5707963267948966 0 0" xyz="0 0 -0.1168"></origin>
			<geometry>
				<mesh filename="package://ur_description/meshes/ur10e/visual/wrist3.dae"></mesh>
			</geometry>
			<material name="LightGrey">
				<color rgba="0.7 0.7 0.7 1.0"></color>
			</material>
		</visual>
		<collision>
			<geometry>
				<sphere radius="0.052616"></sphere>
			</geometry>
			<origin xyz="-0.00017564292037487028 -0.0007414466705322198 -0.0244805331659317" rpy="0 0 0"></origin>
		</collision>
		<inertial>
			<mass value="0.202"></mass>
			<origin rpy="0 0 0" xyz="0.0 0.0 -0.025"></origin>
			<inertia ixx="0.00014434577559500002" ixy="0.0" ixz="0.0" iyy="0.00014434577559500002" iyz="0.0" izz="0.00020452500000000002"></inertia>
		</inertial>
	</link>
	<link name="base"></link>
	<link name="flange"></link>
	<link name="tool0"></link>
	<joint name="base_link-base_link_inertia" type="fixed">
		<parent link="base_link"></parent>
		<child link="base_link_inertia"></child>
		<origin rpy="0 0 3.141592653589793" xyz="0 0 0"></origin>
	</joint>
	<joint name="shoulder_pan_joint" type="revolute">
		<parent link="base_link_inertia"></parent>
		<child link="shoulder_link"></child>
		<origin rpy="0 0 0" xyz="0 0 0.1807"></origin>
		<axis xyz="0 0 1"></axis>
		<limit effort="330.0" lower="-6.283185307179586" upper="6.283185307179586" velocity="2.0943951023931953"></limit>
		<dynamics damping="0" friction="0"></dynamics>
	</joint>
	<joint name="shoulder_lift_joint" type="revolute">
		<parent link="shoulder_link"></parent>
		<child link="upper_arm_link"></child>
		<origin rpy="1.570796327 0 0" xyz="0 0 0"></origin>
		<axis xyz="0 0 1"></axis>
		<limit effort="330.0" lower="-6.283185307179586" upper="6.283185307179586" velocity="2.0943951023931953"></limit>
		<dynamics damping="0" friction="0"></dynamics>
	</joint>
	<joint name="elbow_joint" type="revolute">
		<parent link="upper_arm_link"></parent>
		<child link="forearm_link"></child>
		<origin rpy="0 0 0" xyz="-0.6127 0 0"></origin>
		<axis xyz="0 0 1"></axis>
		<limit effort="150.0" lower="-3.141592653589793" upper="3.141592653589793" velocity="3.141592653589793"></limit>
		<dynamics damping="0" friction="0"></dynamics>
	</joint>
	<joint name="wrist_1_joint" type="revolute">
		<parent link="forearm_link"></parent>
		<child link="wrist_1_link"></child>
		<origin rpy="0 0 0" xyz="-0.57155 0 0.17415"></origin>
		<axis xyz="0 0 1"></axis>
		<limit effort="56.0" lower="-6.283185307179586" upper="6.283185307179586" velocity="3.141592653589793"></limit>
		<dynamics damping="0" friction="0"></dynamics>
	</joint>
	<joint name="wrist_2_joint" type="revolute">
		<parent link="wrist_1_link"></parent>
		<child link="wrist_2_link"></child>
		<origin rpy="1.570796327 0 0" xyz="0 -0.11985 -2.458164590756244e-11"></origin>
		<axis xyz="0 0 1"></axis>
		<limit effort="56.0" lower="-6.283185307179586" upper="6.283185307179586" velocity="3.141592653589793"></limit>
		<dynamics damping="0" friction="0"></dynamics>
	</joint>
	<joint name="wrist_3_joint" type="revolute">
		<parent link="wrist_2_link"></parent>
		<child link="wrist_3_link"></child>
		<origin rpy="1.570796326589793 3.141592653589793 3.141592653589793" xyz="0 0.11655 -2.390480459346185e-11"></origin>
		<axis xyz="0 0 1"></axis>
		<limit effort="56.0" lower="-6.283185307179586" upper="6.283185307179586" velocity="3.141592653589793"></limit>
		<dynamics damping="0" friction="0"></dynamics>
	</joint>
	<joint name="base_link-base_fixed_joint" type="fixed">
		<origin rpy="0 0 3.141592653589793" xyz="0 0 0"></origin>
		<parent link="base_link"></parent>
		<child link="base"></child>
	</joint>
	<joint name="wrist_3-flange" type="fixed">
		<parent link="wrist_3_link"></parent>
		<child link="flange"></child>
		<origin rpy="0 -1.5707963267948966 -1.5707963267948966" xyz="0 0 0"></origin>
	</joint>
	<joint name="flange-tool0" type="fixed">
		<origin rpy="1.5707963267948966 0 1.5707963267948966" xyz="0 0 0"></origin>
		<parent link="flange"></parent>
		<child link="tool0"></child>
	</joint>
</robot>