<?xml version="1.0" encoding="utf-8"?>
<robot name="xarm6" path="assets/xarm6/xarm6.urdf">
	<material name="Black">
		<color rgba="0.0 0.0 0.0 1.0"></color>
	</material>
	<material name="Red">
		<color rgba="0.8 0.0 0.0 1.0"></color>
	</material>
	<material name="White">
		<color rgba="1.0 1.0 1.0 1.0"></color>
	</material>
	<material name="Silver">
		<color rgba="0.753 0.753 0.753 1.0"></color>
	</material>
	<link name="world"></link>
	<link name="link_base">
		<inertial>
			<origin rpy="0 0 0" xyz="0.0 0.0 0.09103"></origin>
			<mass value="2.7"></mass>
			<inertia ixx="0.00494875" ixy="-3.5E-06" ixz="1.25E-05" iyy="0.00494174" iyz="1.67E-06" izz="0.002219"></inertia>
		</inertial>
		<visual>
			<geometry>
				<mesh filename="meshes/visual/link_base.stl"></mesh>
			</geometry>
			<origin rpy="0 0 0" xyz="0 0 0"></origin>
			<material name="White"></material>
		</visual>
		<collision>
			<geometry>
				<sphere radius="0.089454"></sphere>
			</geometry>
			<origin xyz="-0.01166419124496818 -0.0005754772664320648 0.04532696155861658" rpy="0 0 0"></origin>
		</collision>
		<collision>
			<geometry>
				<sphere radius="0.075535"></sphere>
			</geometry>
			<origin xyz="-0.0003881912449681807 -0.0004184772664320648 0.10254696155861659" rpy="0 0 0"></origin>
		</collision>
	</link>
	<link name="link1">
		<inertial>
			<origin rpy="0 0 0" xyz="0.00022 0.02951 -0.0124"></origin>
			<mass value="2.3814"></mass>
			<inertia ixx="0.0058562" ixy="-1.79e-05" ixz="3.55e-06" iyy="0.0050316" iyz="-0.000888336" izz="0.003536652"></inertia>
		</inertial>
		<visual>
			<geometry>
				<mesh filename="meshes/visual/link1.stl"></mesh>
			</geometry>
			<origin rpy="0 0 0" xyz="0 0 0"></origin>
			<material name="White"></material>
		</visual>
		<collision>
			<geometry>
				<sphere radius="0.08192"></sphere>
			</geometry>
			<origin xyz="-7.416808827155959e-05 0.01727372168455009 -0.00023006578689655638" rpy="0 0 0"></origin>
		</collision>
		<collision>
			<geometry>
				<sphere radius="0.072604"></sphere>
			</geometry>
			<origin xyz="-7.316808827155958e-05 -0.0035432783154499096 -0.06717006578689655" rpy="0 0 0"></origin>
		</collision>
	</link>
	<link name="link2">
		<inertial>
			<origin rpy="0 0 0" xyz="0.03881 -0.22783 0.03496"></origin>
			<mass value="2.2675"></mass>
			<inertia ixx="0.028315776" ixy="0.005" ixz="0.00066546" iyy="0.0058" iyz="-0.0045741" izz="0.0273447"></inertia>
		</inertial>
		<visual>
			<geometry>
				<mesh filename="meshes/visual/link2.stl"></mesh>
			</geometry>
			<origin rpy="0 0 0" xyz="0 0 0"></origin>
			<material name="White"></material>
		</visual>
		<collision>
			<geometry>
				<sphere radius="0.070429"></sphere>
			</geometry>
			<origin xyz="0.05334032865414016 -0.28597571535052424 0.020323684615781858" rpy="0 0 0"></origin>
		</collision>
		<collision>
			<geometry>
				<sphere radius="0.072946"></sphere>
			</geometry>
			<origin xyz="0.029714328654140157 -0.2721627153505242 -0.02746531538421814" rpy="0 0 0"></origin>
		</collision>
		<collision>
			<geometry>
				<sphere radius="0.072148"></sphere>
			</geometry>
			<origin xyz="0.00012632865414015718 -0.19517571535052425 -0.0024813153842181412" rpy="0 0 0"></origin>
		</collision>
		<collision>
			<geometry>
				<sphere radius="0.070164"></sphere>
			</geometry>
			<origin xyz="-0.0002066713458598428 -0.11071371535052424 0.014145684615781858" rpy="0 0 0"></origin>
		</collision>
		<collision>
			<geometry>
				<sphere radius="0.067809"></sphere>
			</geometry>
			<origin xyz="-0.0007216713458598444 -0.09764071535052424 0.07503068461578186" rpy="0 0 0"></origin>
		</collision>
		<collision>
			<geometry>
				<sphere radius="0.061795"></sphere>
			</geometry>
			<origin xyz="-0.0003196713458598413 -0.03404371535052424 0.09127368461578186" rpy="0 0 0"></origin>
		</collision>
		<collision>
			<geometry>
				<sphere radius="0.055739"></sphere>
			</geometry>
			<origin xyz="0.0013263286541401569 0.004755284649475777 0.09613268461578187" rpy="0 0 0"></origin>
		</collision>
	</link>
	<link name="link3">
		<inertial>
			<origin rpy="0 0 0" xyz="0.07041 0.11631 0.0107"></origin>
			<mass value="1.875"></mass>
			<inertia ixx="0.0063483" ixy="-0.0015397" ixz="0.00096858" iyy="0.00379758" iyz="0.00186567" izz="0.00595768"></inertia>
		</inertial>
		<visual>
			<geometry>
				<mesh filename="meshes/visual/link3.stl"></mesh>
			</geometry>
			<origin rpy="0 0 0" xyz="0 0 0"></origin>
			<material name="White"></material>
		</visual>
		<collision>
			<geometry>
				<sphere radius="0.074976"></sphere>
			</geometry>
			<origin xyz="0.07788801955269935 0.11286071290145253 0.0004934933898277025" rpy="0 0 0"></origin>
		</collision>
		<collision>
			<geometry>
				<sphere radius="0.069497"></sphere>
			</geometry>
			<origin xyz="0.07401001955269934 0.07588071290145253 0.0621904933898277" rpy="0 0 0"></origin>
		</collision>
		<collision>
			<geometry>
				<sphere radius="0.051436"></sphere>
			</geometry>
			<origin xyz="0.02798301955269935 0.033401712901452524 0.0831634933898277" rpy="0 0 0"></origin>
		</collision>
		<collision>
			<geometry>
				<sphere radius="0.042045"></sphere>
			</geometry>
			<origin xyz="0.008156019552699349 -0.013441287098547472 0.0862824933898277" rpy="0 0 0"></origin>
		</collision>
		<collision>
			<geometry>
				<sphere radius="0.046035"></sphere>
			</geometry>
			<origin xyz="-0.013273980447300653 -2.028709854748345e-05 0.0862034933898277" rpy="0 0 0"></origin>
		</collision>
	</link>
	<link name="link4">
		<inertial>
			<origin rpy="0 0 0" xyz="-0.00018 0.01798 -0.02291"></origin>
			<mass value="1.3192"></mass>
			<inertia ixx="0.004896" ixy="-6.925e-06" ixz="-1.418e-05" iyy="0.00445694" iyz="-0.00023186" izz="0.00134332"></inertia>
		</inertial>
		<visual>
			<geometry>
				<mesh filename="meshes/visual/link4.stl"></mesh>
			</geometry>
			<origin rpy="0 0 0" xyz="0 0 0"></origin>
			<material name="White"></material>
		</visual>
		<collision>
			<geometry>
				<sphere radius="0.061787"></sphere>
			</geometry>
			<origin xyz="-0.0001681281203645851 0.046330798837346907 -0.0036110852885459788" rpy="0 0 0"></origin>
		</collision>
		<collision>
			<geometry>
				<sphere radius="0.054875"></sphere>
			</geometry>
			<origin xyz="0.0002858718796354149 -9.4201162653091e-05 -0.14607108528854598" rpy="0 0 0"></origin>
		</collision>
		<collision>
			<geometry>
				<sphere radius="0.04456"></sphere>
			</geometry>
			<origin xyz="0.008538871879635415 0.06564779883734691 -0.061971085288545974" rpy="0 0 0"></origin>
		</collision>
		<collision>
			<geometry>
				<sphere radius="0.040595"></sphere>
			</geometry>
			<origin xyz="-0.012577128120364585 0.03734079883734691 -0.11898708528854599" rpy="0 0 0"></origin>
		</collision>
		<collision>
			<geometry>
				<sphere radius="0.035913"></sphere>
			</geometry>
			<origin xyz="0.017136871879635415 0.04218379883734691 -0.11418108528854598" rpy="0 0 0"></origin>
		</collision>
		<collision>
			<geometry>
				<sphere radius="0.041213"></sphere>
			</geometry>
			<origin xyz="-0.013302128120364584 0.06958079883734691 -0.07020508528854598" rpy="0 0 0"></origin>
		</collision>
	</link>
	<link name="link5">
		<inertial>
			<origin rpy="0 0 0" xyz="0.0651 0.03096 0.00315"></origin>
			<mass value="1.33854"></mass>
			<inertia ixx="0.00146378" ixy="-0.000450624" ixz="0.000284306" iyy="0.00184192" iyz="0.000130866" izz="0.002333524"></inertia>
		</inertial>
		<visual>
			<geometry>
				<mesh filename="meshes/visual/link5.stl"></mesh>
			</geometry>
			<origin rpy="0 0 0" xyz="0 0 0"></origin>
			<material name="White"></material>
		</visual>
		<collision>
			<geometry>
				<sphere radius="0.065239"></sphere>
			</geometry>
			<origin xyz="0.07562680403686661 0.019540519103842614 -0.00014770430290014964" rpy="0 0 0"></origin>
		</collision>
		<collision>
			<geometry>
				<sphere radius="0.056633"></sphere>
			</geometry>
			<origin xyz="0.005996804036866615 -0.003541480896157384 0.025232295697099852" rpy="0 0 0"></origin>
		</collision>
	</link>
	<link name="link6">
		<inertial>
			<origin rpy="0 0 0" xyz="0 -0.00677 -0.01098"></origin>
			<mass value="0.17"></mass>
			<inertia ixx="9.3e-05" ixy="-0.0" ixz="-0.0" iyy="5.87e-05" iyz="-3.6e-06" izz="0.000132"></inertia>
		</inertial>
		<visual>
			<geometry>
				<mesh filename="meshes/visual/link6.stl"></mesh>
			</geometry>
			<origin rpy="0 0 0" xyz="0 0 0"></origin>
			<material name="Silver"></material>
		</visual>
		<collision>
			<geometry>
				<sphere radius="0.035856"></sphere>
			</geometry>
			<origin xyz="-0.01185003766644001 -0.02305662418782711 -0.013500000350177288" rpy="0 0 0"></origin>
		</collision>
		<collision>
			<geometry>
				<sphere radius="0.040074"></sphere>
			</geometry>
			<origin xyz="9.62333559989927e-07 1.3758121728893458e-06 -0.013500000350177288" rpy="0 0 0"></origin>
		</collision>
	</link>
	<joint name="world_joint" type="fixed">
		<parent link="world"></parent>
		<child link="link_base"></child>
		<origin rpy="0 0 0" xyz="-0.09 0 0"></origin>
	</joint>
	<joint name="joint1" type="revolute">
		<parent link="link_base"></parent>
		<child link="link1"></child>
		<origin rpy="0 0 0" xyz="0 0 0.267"></origin>
		<axis xyz="0 0 1"></axis>
		<limit effort="50.0" lower="-3.1101767270538954" upper="3.1101767270538954" velocity="3.14"></limit>
		<dynamics damping="1.0" friction="1.0"></dynamics>
	</joint>
	<joint name="joint2" type="revolute">
		<parent link="link1"></parent>
		<child link="link2"></child>
		<origin rpy="-1.5708 0 0" xyz="0 0 0"></origin>
		<axis xyz="0 0 1"></axis>
		<limit effort="50.0" lower="-2.059" upper="2.0944" velocity="3.14"></limit>
		<dynamics damping="1.0" friction="1.0"></dynamics>
	</joint>
	<joint name="joint3" type="revolute">
		<parent link="link2"></parent>
		<child link="link3"></child>
		<origin rpy="0 0 0" xyz="0.0535 -0.2845 0"></origin>
		<axis xyz="0 0 1"></axis>
		<limit effort="32.0" lower="-3.1101767270538954" upper="0.19198" velocity="3.14"></limit>
		<dynamics damping="1.0" friction="1.0"></dynamics>
	</joint>
	<joint name="joint4" type="revolute">
		<parent link="link3"></parent>
		<child link="link4"></child>
		<origin rpy="-1.5708 0 0" xyz="0.0775 0.3425 0"></origin>
		<axis xyz="0 0 1"></axis>
		<limit effort="32.0" lower="-3.1101767270538954" upper="3.1101767270538954" velocity="3.14"></limit>
		<dynamics damping="1.0" friction="1.0"></dynamics>
	</joint>
	<joint name="joint5" type="revolute">
		<parent link="link4"></parent>
		<child link="link5"></child>
		<origin rpy="1.5708 0 0" xyz="0 0 0"></origin>
		<axis xyz="0 0 1"></axis>
		<limit effort="32.0" lower="-1.69297" upper="3.1101767270538954" velocity="3.14"></limit>
		<dynamics damping="1.0" friction="1.0"></dynamics>
	</joint>
	<joint name="joint6" type="revolute">
		<parent link="link5"></parent>
		<child link="link6"></child>
		<origin rpy="-1.5708 0 0" xyz="0.076 0.097 0"></origin>
		<axis xyz="0 0 1"></axis>
		<limit effort="20.0" lower="-3.1101767270538954" upper="3.1101767270538954" velocity="3.14"></limit>
		<dynamics damping="1.0" friction="1.0"></dynamics>
	</joint>
	<ros2_control name="ign_ros2_control/IgnitionSystem" type="system">
		<hardware>
			<plugin>ign_ros2_control/IgnitionSystem</plugin>
		</hardware>
		<joint name="joint1">
			<command_interface name="position">
				<param name="min">-3.1101767270538954</param>
				<param name="max">3.1101767270538954</param>
			</command_interface>
			<command_interface name="velocity">
				<param name="min">-3.14</param>
				<param name="max">3.14</param>
			</command_interface>
			<state_interface name="position"></state_interface>
			<state_interface name="velocity"></state_interface>
		</joint>
		<joint name="joint2">
			<command_interface name="position">
				<param name="min">-2.059</param>
				<param name="max">2.0944</param>
			</command_interface>
			<command_interface name="velocity">
				<param name="min">-3.14</param>
				<param name="max">3.14</param>
			</command_interface>
			<state_interface name="position"></state_interface>
			<state_interface name="velocity"></state_interface>
		</joint>
		<joint name="joint3">
			<command_interface name="position">
				<param name="min">-3.1101767270538954</param>
				<param name="max">0.19198</param>
			</command_interface>
			<command_interface name="velocity">
				<param name="min">-3.14</param>
				<param name="max">3.14</param>
			</command_interface>
			<state_interface name="position"></state_interface>
			<state_interface name="velocity"></state_interface>
		</joint>
		<joint name="joint4">
			<command_interface name="position">
				<param name="min">-3.1101767270538954</param>
				<param name="max">3.1101767270538954</param>
			</command_interface>
			<command_interface name="velocity">
				<param name="min">-3.14</param>
				<param name="max">3.14</param>
			</command_interface>
			<state_interface name="position"></state_interface>
			<state_interface name="velocity"></state_interface>
		</joint>
		<joint name="joint5">
			<command_interface name="position">
				<param name="min">-1.69297</param>
				<param name="max">3.1101767270538954</param>
			</command_interface>
			<command_interface name="velocity">
				<param name="min">-3.14</param>
				<param name="max">3.14</param>
			</command_interface>
			<state_interface name="position"></state_interface>
			<state_interface name="velocity"></state_interface>
		</joint>
		<joint name="joint6">
			<command_interface name="position">
				<param name="min">-3.1101767270538954</param>
				<param name="max">3.1101767270538954</param>
			</command_interface>
			<command_interface name="velocity">
				<param name="min">-3.14</param>
				<param name="max">3.14</param>
			</command_interface>
			<state_interface name="position"></state_interface>
			<state_interface name="velocity"></state_interface>
		</joint>
	</ros2_control>
	<transmission name="tran1">
		<type>transmission_interface/SimpleTransmission</type>
		<joint name="joint1">
			<hardwareInterface>hardware_interface/PositionJointInterface</hardwareInterface>
		</joint>
		<actuator name="motor1">
			<hardwareInterface>hardware_interface/PositionJointInterface</hardwareInterface>
			<mechanicalReduction>100</mechanicalReduction>
		</actuator>
	</transmission>
	<transmission name="tran2">
		<type>transmission_interface/SimpleTransmission</type>
		<joint name="joint2">
			<hardwareInterface>hardware_interface/PositionJointInterface</hardwareInterface>
		</joint>
		<actuator name="motor2">
			<hardwareInterface>hardware_interface/PositionJointInterface</hardwareInterface>
			<mechanicalReduction>100</mechanicalReduction>
		</actuator>
	</transmission>
	<transmission name="tran3">
		<type>transmission_interface/SimpleTransmission</type>
		<joint name="joint3">
			<hardwareInterface>hardware_interface/PositionJointInterface</hardwareInterface>
		</joint>
		<actuator name="motor3">
			<hardwareInterface>hardware_interface/PositionJointInterface</hardwareInterface>
			<mechanicalReduction>100</mechanicalReduction>
		</actuator>
	</transmission>
	<transmission name="tran4">
		<type>transmission_interface/SimpleTransmission</type>
		<joint name="joint4">
			<hardwareInterface>hardware_interface/PositionJointInterface</hardwareInterface>
		</joint>
		<actuator name="motor4">
			<hardwareInterface>hardware_interface/PositionJointInterface</hardwareInterface>
			<mechanicalReduction>100</mechanicalReduction>
		</actuator>
	</transmission>
	<transmission name="tran5">
		<type>transmission_interface/SimpleTransmission</type>
		<joint name="joint5">
			<hardwareInterface>hardware_interface/PositionJointInterface</hardwareInterface>
		</joint>
		<actuator name="motor5">
			<hardwareInterface>hardware_interface/PositionJointInterface</hardwareInterface>
			<mechanicalReduction>100</mechanicalReduction>
		</actuator>
	</transmission>
	<transmission name="tran6">
		<type>transmission_interface/SimpleTransmission</type>
		<joint name="joint6">
			<hardwareInterface>hardware_interface/PositionJointInterface</hardwareInterface>
		</joint>
		<actuator name="motor6">
			<hardwareInterface>hardware_interface/PositionJointInterface</hardwareInterface>
			<mechanicalReduction>100</mechanicalReduction>
		</actuator>
	</transmission>
	<gazebo reference="link_base">
		<selfCollide>true</selfCollide>
	</gazebo>
	<gazebo reference="link1">
		<selfCollide>true</selfCollide>
	</gazebo>
	<gazebo reference="link2">
		<selfCollide>true</selfCollide>
	</gazebo>
	<gazebo reference="link3">
		<selfCollide>true</selfCollide>
	</gazebo>
	<gazebo reference="link4">
		<selfCollide>true</selfCollide>
	</gazebo>
	<gazebo reference="link5">
		<selfCollide>true</selfCollide>
	</gazebo>
	<gazebo reference="link6">
		<selfCollide>true</selfCollide>
	</gazebo>
</robot>