<?xml version="1.0" encoding="utf-8"?>
<robot name="fetch" path="assets/fetch/fetch_simple.urdf">
	<link name="base_link">
		<inertial>
			<origin rpy="0 0 0" xyz="-0.0036 0.0 0.0014"></origin>
			<mass value="70.1294"></mass>
			<inertia ixx="1.225" ixy="0.0099" ixz="0.0062" iyy="1.2853" iyz="-0.0034" izz="0.987"></inertia>
		</inertial>
		<visual>
			<origin rpy="0 0 0" xyz="0 0 0"></origin>
			<geometry>
				<mesh filename="package://meshes/base_link.dae"></mesh>
			</geometry>
			<material name="">
				<color rgba="0.356 0.361 0.376 1"></color>
			</material>
		</visual>
		<collision>
			<geometry>
				<sphere radius="0.229153"></sphere>
			</geometry>
			<origin xyz="-0.08670633713436125 0.044748625229358664 0.16151586150666747" rpy="0 0 0"></origin>
		</collision>
		<collision>
			<geometry>
				<sphere radius="0.225567"></sphere>
			</geometry>
			<origin xyz="-0.08464633713436126 -0.05277737477064133 0.16401486150666747" rpy="0 0 0"></origin>
		</collision>
		<collision>
			<geometry>
				<sphere radius="0.213846"></sphere>
			</geometry>
			<origin xyz="0.06341866286563874 -0.08447837477064134 0.1710298615066675" rpy="0 0 0"></origin>
		</collision>
		<collision>
			<geometry>
				<sphere radius="0.220734"></sphere>
			</geometry>
			<origin xyz="0.08629766286563874 0.05490262522935867 0.1675318615066675" rpy="0 0 0"></origin>
		</collision>
		<collision>
			<geometry>
				<sphere radius="0.203801"></sphere>
			</geometry>
			<origin xyz="0.11487166286563874 -0.029189374770641333 0.18144786150666747" rpy="0 0 0"></origin>
		</collision>
		<collision>
			<geometry>
				<sphere radius="0.214064"></sphere>
			</geometry>
			<origin xyz="0.044376662865638745 0.08810162522935867 0.17415186150666748" rpy="0 0 0"></origin>
		</collision>
	</link>
	<link name="torso_lift_link">
		<inertial>
			<origin rpy="0 0 0" xyz="-0.0013 -0.0009 0.2935"></origin>
			<mass value="10.7796"></mass>
			<inertia ixx="0.3354" ixy="0.0" ixz="-0.0162" iyy="0.3354" iyz="-0.0006" izz="0.0954"></inertia>
		</inertial>
		<visual>
			<origin rpy="0 0 0" xyz="0 0 0"></origin>
			<geometry>
				<mesh filename="package://meshes/torso_lift_link.dae"></mesh>
			</geometry>
			<material name="">
				<color rgba="1 1 1 1"></color>
			</material>
		</visual>
		<collision>
			<geometry>
				<sphere radius="0.145393"></sphere>
			</geometry>
			<origin xyz="-0.06209968426072597 0.05750512358474731 0.11952028459882738" rpy="0 0 0"></origin>
		</collision>
		<collision>
			<geometry>
				<sphere radius="0.141651"></sphere>
			</geometry>
			<origin xyz="-0.05865768426072597 -0.05611087641525269 0.11629828459882738" rpy="0 0 0"></origin>
		</collision>
		<collision>
			<geometry>
				<sphere radius="0.139988"></sphere>
			</geometry>
			<origin xyz="-0.06502968426072597 -0.05378787641525269 0.28603628459882735" rpy="0 0 0"></origin>
		</collision>
		<collision>
			<geometry>
				<sphere radius="0.1279"></sphere>
			</geometry>
			<origin xyz="-0.06196768426072597 -0.05783787641525269 0.4394152845988274" rpy="0 0 0"></origin>
		</collision>
		<collision>
			<geometry>
				<sphere radius="0.130686"></sphere>
			</geometry>
			<origin xyz="-0.060714684260725967 0.05888512358474731 0.28795728459882736" rpy="0 0 0"></origin>
		</collision>
		<collision>
			<geometry>
				<sphere radius="0.131901"></sphere>
			</geometry>
			<origin xyz="-0.06562568426072597 0.05344412358474731 0.44030428459882737" rpy="0 0 0"></origin>
		</collision>
		<collision>
			<geometry>
				<sphere radius="0.06561"></sphere>
			</geometry>
			<origin xyz="0.10826811259543896 0.0003488245974183076 0.22420377048540116" rpy="0 0 0"></origin>
		</collision>
		<collision>
			<geometry>
				<sphere radius="0.062936"></sphere>
			</geometry>
			<origin xyz="0.10486111259543895 -0.00021017540258169243 0.20946477048540116" rpy="0 0 0"></origin>
		</collision>
		<collision>
			<geometry>
				<sphere radius="0.055376"></sphere>
			</geometry>
			<origin xyz="0.06696111259543897 -0.012252175402581693 0.23075977048540117" rpy="0 0 0"></origin>
		</collision>
		<collision>
			<geometry>
				<sphere radius="0.050524"></sphere>
			</geometry>
			<origin xyz="0.06409711259543896 0.014706824597418308 0.23273777048540117" rpy="0 0 0"></origin>
		</collision>
		<collision>
			<geometry>
				<sphere radius="0.042346"></sphere>
			</geometry>
			<origin xyz="0.059047112595438954 0.019863824597418308 0.18993277048540116" rpy="0 0 0"></origin>
		</collision>
		<collision>
			<geometry>
				<sphere radius="0.038069"></sphere>
			</geometry>
			<origin xyz="0.056551112595438956 -0.022364175402581694 0.18743677048540117" rpy="0 0 0"></origin>
		</collision>
		<collision>
			<geometry>
				<sphere radius="0.078879"></sphere>
			</geometry>
			<origin xyz="0.0247519383216165 0.037568008342849527 0.507900196794634" rpy="0 0 0"></origin>
		</collision>
		<collision>
			<geometry>
				<sphere radius="0.051082"></sphere>
			</geometry>
			<origin xyz="-0.014272061678383505 -0.001146991657150474 0.5322491967946341" rpy="0 0 0"></origin>
		</collision>
		<collision>
			<geometry>
				<sphere radius="0.079967"></sphere>
			</geometry>
			<origin xyz="0.0280549383216165 -0.03591299165715047 0.505108196794634" rpy="0 0 0"></origin>
		</collision>
		<collision>
			<geometry>
				<sphere radius="0.063929"></sphere>
			</geometry>
			<origin xyz="0.0871389383216165 0.0014050083428495258 0.522431196794634" rpy="0 0 0"></origin>
		</collision>
		<collision>
			<geometry>
				<sphere radius="0.054798"></sphere>
			</geometry>
			<origin xyz="0.028926938321616497 0.029618008342849524 0.4564241967946341" rpy="0 0 0"></origin>
		</collision>
		<collision>
			<geometry>
				<sphere radius="0.060059"></sphere>
			</geometry>
			<origin xyz="0.030106938321616497 -0.029524991657150473 0.46180719679463406" rpy="0 0 0"></origin>
		</collision>
	</link>
	<link name="head_pan_link">
		<inertial>
			<origin rpy="0 0 0" xyz="0.0321 0.0161 0.0390"></origin>
			<mass value="2.2556"></mass>
			<inertia ixx="0.0129" ixy="0.0002" ixz="0.0007" iyy="0.0095" iyz="-0.0" izz="0.0184"></inertia>
		</inertial>
		<visual>
			<origin rpy="0 0 0" xyz="0 0 0"></origin>
			<geometry>
				<mesh filename="package://meshes/head_pan_link.dae"></mesh>
			</geometry>
			<material name="">
				<color rgba="0.356 0.361 0.376 1"></color>
			</material>
		</visual>
		<collision>
			<geometry>
				<sphere radius="0.086337"></sphere>
			</geometry>
			<origin xyz="0.10632076003432273 0.07839447835421563 0.05114388624737412" rpy="0 0 0"></origin>
		</collision>
		<collision>
			<geometry>
				<sphere radius="0.086521"></sphere>
			</geometry>
			<origin xyz="-0.007742239965677265 0.07654047835421562 0.044036886247374125" rpy="0 0 0"></origin>
		</collision>
		<collision>
			<geometry>
				<sphere radius="0.090649"></sphere>
			</geometry>
			<origin xyz="0.09012076003432273 -0.0009105216457843724 0.050127886247374125" rpy="0 0 0"></origin>
		</collision>
		<collision>
			<geometry>
				<sphere radius="0.081706"></sphere>
			</geometry>
			<origin xyz="-0.04829123996567727 -0.0015005216457843725 0.03601288624737412" rpy="0 0 0"></origin>
		</collision>
		<collision>
			<geometry>
				<sphere radius="0.086932"></sphere>
			</geometry>
			<origin xyz="-0.0017972399656772595 -0.08204252164578438 0.04539788624737412" rpy="0 0 0"></origin>
		</collision>
		<collision>
			<geometry>
				<sphere radius="0.081444"></sphere>
			</geometry>
			<origin xyz="0.11054976003432274 -0.07794852164578438 0.050912886247374126" rpy="0 0 0"></origin>
		</collision>
	</link>
	<link name="head_tilt_link">
		<inertial>
			<origin rpy="0 0 0" xyz="0.0081 0.0025 0.0113"></origin>
			<mass value="0.9087"></mass>
			<inertia ixx="0.0061" ixy="-0.0" ixz="0.0002" iyy="0.0014" iyz="-0.0001" izz="0.0061"></inertia>
		</inertial>
		<visual>
			<origin rpy="0 0 0" xyz="0 0 0"></origin>
			<geometry>
				<mesh filename="package://meshes/head_tilt_link.dae"></mesh>
			</geometry>
			<material name="">
				<color rgba="0.086 0.506 0.767 1"></color>
			</material>
		</visual>
		<collision>
			<geometry>
				<sphere radius="0.068856"></sphere>
			</geometry>
			<origin xyz="-9.823393446206839e-05 -0.04572349264240265 -0.00021349291652441023" rpy="0 0 0"></origin>
		</collision>
		<collision>
			<geometry>
				<sphere radius="0.069315"></sphere>
			</geometry>
			<origin xyz="-5.423393446206838e-05 0.04527750735759735 -4.5492916524410244e-05" rpy="0 0 0"></origin>
		</collision>
		<collision>
			<geometry>
				<sphere radius="0.061875"></sphere>
			</geometry>
			<origin xyz="0.006240766065537932 -0.0008334926424026489 0.00628250708347559" rpy="0 0 0"></origin>
		</collision>
		<collision>
			<geometry>
				<sphere radius="0.032032"></sphere>
			</geometry>
			<origin xyz="0.029860766065537933 0.07454050735759735 0.02746450708347559" rpy="0 0 0"></origin>
		</collision>
		<collision>
			<geometry>
				<sphere radius="0.025908"></sphere>
			</geometry>
			<origin xyz="0.034691766065537935 -0.07929749264240264 0.02963650708347559" rpy="0 0 0"></origin>
		</collision>
	</link>
	<link name="shoulder_pan_link">
		<inertial>
			<origin rpy="0 0 0" xyz="0.0927 -0.0056 0.0564"></origin>
			<mass value="2.5587"></mass>
			<inertia ixx="0.0043" ixy="-0.0001" ixz="0.001" iyy="0.0087" iyz="-0.0001" izz="0.0087"></inertia>
		</inertial>
		<visual>
			<origin rpy="0 0 0" xyz="0 0 0"></origin>
			<geometry>
				<mesh filename="package://meshes/shoulder_pan_link.dae"></mesh>
			</geometry>
			<material name="">
				<color rgba="1 1 1 1"></color>
			</material>
		</visual>
		<collision>
			<geometry>
				<sphere radius="0.067824"></sphere>
			</geometry>
			<origin xyz="0.0011885354723930458 -0.0007752820948958381 0.00416769302219153" rpy="0 0 0"></origin>
		</collision>
		<collision>
			<geometry>
				<sphere radius="0.05282"></sphere>
			</geometry>
			<origin xyz="0.025711535472393045 -0.01654228209489584 0.047206693022191534" rpy="0 0 0"></origin>
		</collision>
		<collision>
			<geometry>
				<sphere radius="0.066142"></sphere>
			</geometry>
			<origin xyz="0.052108535472393046 -0.015097282094895838 0.01656669302219153" rpy="0 0 0"></origin>
		</collision>
		<collision>
			<geometry>
				<sphere radius="0.060041"></sphere>
			</geometry>
			<origin xyz="0.11312053547239305 -0.026223282094895838 0.04351769302219153" rpy="0 0 0"></origin>
		</collision>
		<collision>
			<geometry>
				<sphere radius="0.053306"></sphere>
			</geometry>
			<origin xyz="0.06394853547239304 -0.026445282094895838 0.06555269302219152" rpy="0 0 0"></origin>
		</collision>
		<collision>
			<geometry>
				<sphere radius="0.056421"></sphere>
			</geometry>
			<origin xyz="0.11117153547239306 -0.026721282094895837 0.06654269302219154" rpy="0 0 0"></origin>
		</collision>
	</link>
	<link name="shoulder_lift_link">
		<inertial>
			<origin rpy="0 0 0" xyz="0.1432 0.0072 -0.0001"></origin>
			<mass value="2.6615"></mass>
			<inertia ixx="0.0028" ixy="-0.0021" ixz="-0.0" iyy="0.0111" iyz="-0.0" izz="0.0112"></inertia>
		</inertial>
		<visual>
			<origin rpy="0 0 0" xyz="0 0 0"></origin>
			<geometry>
				<mesh filename="package://meshes/shoulder_lift_link.dae"></mesh>
			</geometry>
			<material name="">
				<color rgba="0.086 0.506 0.767 1"></color>
			</material>
		</visual>
		<collision>
			<geometry>
				<sphere radius="0.066133"></sphere>
			</geometry>
			<origin xyz="0.10657892179346085 0.0024566331559419657 -0.0005737779012322426" rpy="0 0 0"></origin>
		</collision>
		<collision>
			<geometry>
				<sphere radius="0.061455"></sphere>
			</geometry>
			<origin xyz="0.048948921793460845 0.016149633155941964 0.0018192220987677573" rpy="0 0 0"></origin>
		</collision>
		<collision>
			<geometry>
				<sphere radius="0.057325"></sphere>
			</geometry>
			<origin xyz="-0.002205078206539153 0.023837633155941965 0.014370222098767758" rpy="0 0 0"></origin>
		</collision>
		<collision>
			<geometry>
				<sphere radius="0.056957"></sphere>
			</geometry>
			<origin xyz="0.0044869217934608435 0.023633633155941965 -0.013873777901232242" rpy="0 0 0"></origin>
		</collision>
		<collision>
			<geometry>
				<sphere radius="0.049547"></sphere>
			</geometry>
			<origin xyz="-0.019220078206539155 0.028989633155941965 -0.0048927779012322425" rpy="0 0 0"></origin>
		</collision>
		<collision>
			<geometry>
				<sphere radius="0.05976"></sphere>
			</geometry>
			<origin xyz="0.11304692179346085 -0.004569366844058035 0.0010372220987677574" rpy="0 0 0"></origin>
		</collision>
	</link>
	<link name="upperarm_roll_link">
		<inertial>
			<origin rpy="0 0 0" xyz="0.1165 0.0014 0.0000"></origin>
			<mass value="2.3311"></mass>
			<inertia ixx="0.0019" ixy="-0.0001" ixz="0.0" iyy="0.0045" iyz="0.0" izz="0.0047"></inertia>
		</inertial>
		<visual>
			<origin rpy="0 0 0" xyz="0 0 0"></origin>
			<geometry>
				<mesh filename="package://meshes/upperarm_roll_link.dae"></mesh>
			</geometry>
			<material name="">
				<color rgba="1 1 1 1"></color>
			</material>
		</visual>
		<collision>
			<geometry>
				<sphere radius="0.05755"></sphere>
			</geometry>
			<origin xyz="0.11928514002472163 -0.02396504201680422 0.000224" rpy="0 0 0"></origin>
		</collision>
		<collision>
			<geometry>
				<sphere radius="0.058874"></sphere>
			</geometry>
			<origin xyz="0.08399914002472161 -0.01919704201680422 -0.000451" rpy="0 0 0"></origin>
		</collision>
		<collision>
			<geometry>
				<sphere radius="0.054614"></sphere>
			</geometry>
			<origin xyz="0.04337614002472162 -0.011997042016804219 0.00046" rpy="0 0 0"></origin>
		</collision>
		<collision>
			<geometry>
				<sphere radius="0.049724"></sphere>
			</geometry>
			<origin xyz="-0.010911859975278382 0.01440995798319578 -0.0001" rpy="0 0 0"></origin>
		</collision>
		<collision>
			<geometry>
				<sphere radius="0.056552"></sphere>
			</geometry>
			<origin xyz="-0.0048048599752783805 -0.0035850420168042187 0.008659" rpy="0 0 0"></origin>
		</collision>
		<collision>
			<geometry>
				<sphere radius="0.061103"></sphere>
			</geometry>
			<origin xyz="-0.0010988599752783795 -0.0033170420168042187 -0.004937" rpy="0 0 0"></origin>
		</collision>
	</link>
	<link name="elbow_flex_link">
		<inertial>
			<origin rpy="0 0 0" xyz="0.1279 0.0073 0.0000"></origin>
			<mass value="2.1299"></mass>
			<inertia ixx="0.0024" ixy="-0.0016" ixz="0.0" iyy="0.0082" iyz="-0.0" izz="0.0084"></inertia>
		</inertial>
		<visual>
			<origin rpy="0 0 0" xyz="0 0 0"></origin>
			<geometry>
				<mesh filename="package://meshes/elbow_flex_link.dae"></mesh>
			</geometry>
			<material name="">
				<color rgba="0.086 0.506 0.767 1"></color>
			</material>
		</visual>
		<collision>
			<geometry>
				<sphere radius="0.064146"></sphere>
			</geometry>
			<origin xyz="0.10295095924836398 0.007180592469751836 0.0" rpy="0 0 0"></origin>
		</collision>
		<collision>
			<geometry>
				<sphere radius="0.058855"></sphere>
			</geometry>
			<origin xyz="0.04325595924836398 0.01701659246975184 8.6e-05" rpy="0 0 0"></origin>
		</collision>
		<collision>
			<geometry>
				<sphere radius="0.054212"></sphere>
			</geometry>
			<origin xyz="-0.002915040751636025 0.025234592469751835 -0.007772" rpy="0 0 0"></origin>
		</collision>
		<collision>
			<geometry>
				<sphere radius="0.054302"></sphere>
			</geometry>
			<origin xyz="-0.002454040751636029 0.025146592469751837 0.007967" rpy="0 0 0"></origin>
		</collision>
		<collision>
			<geometry>
				<sphere radius="0.053528"></sphere>
			</geometry>
			<origin xyz="0.11153395924836398 -0.005304407530248164 -0.008037" rpy="0 0 0"></origin>
		</collision>
		<collision>
			<geometry>
				<sphere radius="0.056546"></sphere>
			</geometry>
			<origin xyz="0.10988795924836398 -0.005412407530248164 0.004568" rpy="0 0 0"></origin>
		</collision>
	</link>
	<link name="forearm_roll_link">
		<inertial>
			<origin rpy="0 0 0" xyz="0.1097 -0.0266 0.0000"></origin>
			<mass value="1.6563"></mass>
			<inertia ixx="0.0016" ixy="-0.0003" ixz="0.0" iyy="0.003" iyz="-0.0" izz="0.0035"></inertia>
		</inertial>
		<visual>
			<origin rpy="0 0 0" xyz="0 0 0"></origin>
			<geometry>
				<mesh filename="package://meshes/forearm_roll_link.dae"></mesh>
			</geometry>
			<material name="">
				<color rgba="1 1 1 1"></color>
			</material>
		</visual>
		<collision>
			<geometry>
				<sphere radius="0.062236"></sphere>
			</geometry>
			<origin xyz="0.013972399821817874 -0.009681588537275793 0.003954" rpy="0 0 0"></origin>
		</collision>
		<collision>
			<geometry>
				<sphere radius="0.057137"></sphere>
			</geometry>
			<origin xyz="0.07165339982181787 -0.039596588537275795 -0.00205" rpy="0 0 0"></origin>
		</collision>
		<collision>
			<geometry>
				<sphere radius="0.050055"></sphere>
			</geometry>
			<origin xyz="0.003079399821817874 0.009963411462724208 0.00439" rpy="0 0 0"></origin>
		</collision>
		<collision>
			<geometry>
				<sphere radius="0.042626"></sphere>
			</geometry>
			<origin xyz="0.11991139982181787 -0.05431658853727579 0.013371" rpy="0 0 0"></origin>
		</collision>
		<collision>
			<geometry>
				<sphere radius="0.040908"></sphere>
			</geometry>
			<origin xyz="0.12260339982181787 -0.0554865885372758 -0.01553" rpy="0 0 0"></origin>
		</collision>
		<collision>
			<geometry>
				<sphere radius="0.049105"></sphere>
			</geometry>
			<origin xyz="0.003066399821817875 0.0039994114627242075 -0.013559" rpy="0 0 0"></origin>
		</collision>
	</link>
	<link name="wrist_flex_link">
		<inertial>
			<origin rpy="0 0 0" xyz="0.0882 0.0009 -0.0001"></origin>
			<mass value="1.725"></mass>
			<inertia ixx="0.0018" ixy="-0.0001" ixz="-0.0" iyy="0.0042" iyz="0.0" izz="0.0042"></inertia>
		</inertial>
		<visual>
			<origin rpy="0 0 0" xyz="0 0 0"></origin>
			<geometry>
				<mesh filename="package://meshes/wrist_flex_link.dae"></mesh>
			</geometry>
			<material name="">
				<color rgba="0.086 0.506 0.767 1"></color>
			</material>
		</visual>
		<collision>
			<geometry>
				<sphere radius="0.063895"></sphere>
			</geometry>
			<origin xyz="0.002162376998424531 0.013531943645954135 -2.7718855679032412e-05" rpy="0 0 0"></origin>
		</collision>
		<collision>
			<geometry>
				<sphere radius="0.063629"></sphere>
			</geometry>
			<origin xyz="0.05837337699842453 0.007263943645954134 0.00026928114432096757" rpy="0 0 0"></origin>
		</collision>
		<collision>
			<geometry>
				<sphere radius="0.064611"></sphere>
			</geometry>
			<origin xyz="0.05812437699842453 -0.0010470563540458657 1.128114432096759e-05" rpy="0 0 0"></origin>
		</collision>
		<collision>
			<geometry>
				<sphere radius="0.06356"></sphere>
			</geometry>
			<origin xyz="0.021979376998424532 -0.0017230563540458661 2.2811443209675885e-06" rpy="0 0 0"></origin>
		</collision>
		<collision>
			<geometry>
				<sphere radius="0.057426"></sphere>
			</geometry>
			<origin xyz="-0.0051576230015754725 -0.009069056354045866 0.004897281144320967" rpy="0 0 0"></origin>
		</collision>
		<collision>
			<geometry>
				<sphere radius="0.048356"></sphere>
			</geometry>
			<origin xyz="-0.006642623001575473 -0.016122056354045865 -0.012664718855679033" rpy="0 0 0"></origin>
		</collision>
	</link>
	<link name="wrist_roll_link">
		<inertial>
			<origin rpy="0 0 0" xyz="0.0095 0.0004 -0.0002"></origin>
			<mass value="0.1354"></mass>
			<inertia ixx="0.0001" ixy="0.0" ixz="0.0" iyy="0.0001" iyz="0.0" izz="0.0001"></inertia>
		</inertial>
		<visual>
			<origin rpy="0 0 0" xyz="0 0 0"></origin>
			<geometry>
				<mesh filename="package://meshes/wrist_roll_link.dae"></mesh>
			</geometry>
			<material name="">
				<color rgba="1 1 1 1"></color>
			</material>
		</visual>
		<collision>
			<geometry>
				<sphere radius="0.030008"></sphere>
			</geometry>
			<origin xyz="-0.0028085242533385756 -0.002143 0.02858423160904646" rpy="0 0 0"></origin>
		</collision>
		<collision>
			<geometry>
				<sphere radius="0.030879"></sphere>
			</geometry>
			<origin xyz="-0.0027675242533385758 -0.025428 0.01219223160904646" rpy="0 0 0"></origin>
		</collision>
		<collision>
			<geometry>
				<sphere radius="0.031421"></sphere>
			</geometry>
			<origin xyz="-0.0020715242533385757 -0.020792 -0.013728768390953541" rpy="0 0 0"></origin>
		</collision>
		<collision>
			<geometry>
				<sphere radius="0.031893"></sphere>
			</geometry>
			<origin xyz="-0.0019565242533385757 0.021545 0.01329323160904646" rpy="0 0 0"></origin>
		</collision>
		<collision>
			<geometry>
				<sphere radius="0.030646"></sphere>
			</geometry>
			<origin xyz="-0.0028035242533385758 0.025419 -0.01263276839095354" rpy="0 0 0"></origin>
		</collision>
		<collision>
			<geometry>
				<sphere radius="0.031"></sphere>
			</geometry>
			<origin xyz="-0.0026395242533385757 -7.5e-05 -0.02815476839095354" rpy="0 0 0"></origin>
		</collision>
	</link>
	<link name="gripper_link">
		<inertial>
			<origin rpy="0 0 0" xyz="-0.0900 -0.0001 -0.0017"></origin>
			<mass value="1.5175"></mass>
			<inertia ixx="0.0013" ixy="-0.0" ixz="0.0" iyy="0.0019" iyz="-0.0" izz="0.0024"></inertia>
		</inertial>
		<visual>
			<origin rpy="0 0 0" xyz="0 0 0"></origin>
			<geometry>
				<mesh filename="package://meshes/gripper_link.dae"></mesh>
			</geometry>
		</visual>
		<collision>
			<geometry>
				<sphere radius="0.0453"></sphere>
			</geometry>
			<origin xyz="-0.10794928617030383 0.026057649558544158 0.0013195182496905328" rpy="0 0 0"></origin>
		</collision>
		<collision>
			<geometry>
				<sphere radius="0.047315"></sphere>
			</geometry>
			<origin xyz="-0.06114528617030382 0.02437364955854416 0.0013145182496905328" rpy="0 0 0"></origin>
		</collision>
		<collision>
			<geometry>
				<sphere radius="0.047456"></sphere>
			</geometry>
			<origin xyz="-0.06173628617030383 -0.023311350441455842 0.0026575182496905328" rpy="0 0 0"></origin>
		</collision>
		<collision>
			<geometry>
				<sphere radius="0.049653"></sphere>
			</geometry>
			<origin xyz="-0.10425928617030382 -0.02235535044145584 0.0012205182496905327" rpy="0 0 0"></origin>
		</collision>
		<collision>
			<geometry>
				<sphere radius="0.049857"></sphere>
			</geometry>
			<origin xyz="-0.10345228617030383 0.006275649558544158 0.0004935182496905327" rpy="0 0 0"></origin>
		</collision>
		<collision>
			<geometry>
				<sphere radius="0.008016"></sphere>
			</geometry>
			<origin xyz="-0.03686928617030383 -0.04627835044145584 -0.020895481750309468" rpy="0 0 0"></origin>
		</collision>
	</link>
	<link name="r_gripper_finger_link">
		<inertial>
			<origin rpy="0 0 0" xyz="-0.01 0 0"></origin>
			<mass value="0.0798"></mass>
			<inertia ixx="0.002" ixy="0" ixz="0" iyy="0" iyz="0" izz="0"></inertia>
		</inertial>
		<visual>
			<origin rpy="0 0 0" xyz="0 0.101425 0"></origin>
			<geometry>
				<mesh filename="package://meshes/r_gripper_finger_link.STL"></mesh>
			</geometry>
			<material name="">
				<color rgba="0.356 0.361 0.376 1"></color>
			</material>
		</visual>
		<collision>
			<geometry>
				<sphere radius="0.011949"></sphere>
			</geometry>
			<origin xyz="0.01872696816921234 -0.007713186271786689 0.005332233873844147" rpy="0 0 0"></origin>
		</collision>
		<collision>
			<geometry>
				<sphere radius="0.011922"></sphere>
			</geometry>
			<origin xyz="0.01876496816921234 -0.007711186271786689 -0.005325766126155853" rpy="0 0 0"></origin>
		</collision>
		<collision>
			<geometry>
				<sphere radius="0.012019"></sphere>
			</geometry>
			<origin xyz="0.0008249681692123399 -0.007712186271786689 -0.005382766126155854" rpy="0 0 0"></origin>
		</collision>
		<collision>
			<geometry>
				<sphere radius="0.012013"></sphere>
			</geometry>
			<origin xyz="0.00024296816921233992 -0.007702186271786689 0.005347233873844146" rpy="0 0 0"></origin>
		</collision>
		<collision>
			<geometry>
				<sphere radius="0.012192"></sphere>
			</geometry>
			<origin xyz="-0.01739503183078766 -0.007716186271786689 -0.005418766126155853" rpy="0 0 0"></origin>
		</collision>
		<collision>
			<geometry>
				<sphere radius="0.012053"></sphere>
			</geometry>
			<origin xyz="-0.01767103183078766 -0.0076971862717866895 0.005347233873844146" rpy="0 0 0"></origin>
		</collision>
	</link>
	<link name="l_gripper_finger_link">
		<inertial>
			<origin rpy="0 0 0" xyz="-0.01 0 0"></origin>
			<mass value="0.0798"></mass>
			<inertia ixx="0.002" ixy="0" ixz="0" iyy="0" iyz="0" izz="0"></inertia>
		</inertial>
		<visual>
			<origin rpy="0 0 0" xyz="0 -0.101425 0"></origin>
			<geometry>
				<mesh filename="package://meshes/l_gripper_finger_link.STL"></mesh>
			</geometry>
			<material name="">
				<color rgba="0.356 0.361 0.376 1"></color>
			</material>
		</visual>
		<collision>
			<geometry>
				<sphere radius="0.011978"></sphere>
			</geometry>
			<origin xyz="-0.017711263091951607 0.00770262304830551 -0.005397128760322928" rpy="0 0 0"></origin>
		</collision>
		<collision>
			<geometry>
				<sphere radius="0.01242"></sphere>
			</geometry>
			<origin xyz="-0.01716526309195161 0.00772262304830551 0.005337871239677072" rpy="0 0 0"></origin>
		</collision>
		<collision>
			<geometry>
				<sphere radius="0.011905"></sphere>
			</geometry>
			<origin xyz="0.0008857369080483913 0.00772962304830551 0.005373871239677072" rpy="0 0 0"></origin>
		</collision>
		<collision>
			<geometry>
				<sphere radius="0.011748"></sphere>
			</geometry>
			<origin xyz="0.01895173690804839 0.00773962304830551 0.005361871239677072" rpy="0 0 0"></origin>
		</collision>
		<collision>
			<geometry>
				<sphere radius="0.012168"></sphere>
			</geometry>
			<origin xyz="0.01843773690804839 0.00771562304830551 -0.005220128760322928" rpy="0 0 0"></origin>
		</collision>
		<collision>
			<geometry>
				<sphere radius="0.012119"></sphere>
			</geometry>
			<origin xyz="0.0002447369080483913 0.00770962304830551 -0.005320128760322928" rpy="0 0 0"></origin>
		</collision>
	</link>
	<link name="torso_fixed_link">
		<inertial>
			<origin rpy="0 0 0" xyz="-0.0722 0.0057 0.2656"></origin>
			<mass value="13.2775"></mass>
			<inertia ixx="0.3861" ixy="0.0015" ixz="-0.0102" iyy="0.3388" iyz="0.0117" izz="0.1018"></inertia>
		</inertial>
		<visual>
			<origin rpy="0 0 0" xyz="0 0 0"></origin>
			<geometry>
				<mesh filename="package://meshes/torso_fixed_link.dae"></mesh>
			</geometry>
			<material name="">
				<color rgba="0.086 0.506 0.767 1"></color>
			</material>
		</visual>
		<collision>
			<geometry>
				<sphere radius="0.127795"></sphere>
			</geometry>
			<origin xyz="-0.08946894928320064 0.06422321999466035 0.34241254623571593" rpy="0 0 0"></origin>
		</collision>
		<collision>
			<geometry>
				<sphere radius="0.121805"></sphere>
			</geometry>
			<origin xyz="-0.08625194928320064 -0.07646778000533966 0.341016546235716" rpy="0 0 0"></origin>
		</collision>
		<collision>
			<geometry>
				<sphere radius="0.125705"></sphere>
			</geometry>
			<origin xyz="-0.08806794928320064 0.06485921999466035 0.040388546235715944" rpy="0 0 0"></origin>
		</collision>
		<collision>
			<geometry>
				<sphere radius="0.125029"></sphere>
			</geometry>
			<origin xyz="-0.08736794928320063 -0.07694578000533965 0.04901554623571594" rpy="0 0 0"></origin>
		</collision>
		<collision>
			<geometry>
				<sphere radius="0.129548"></sphere>
			</geometry>
			<origin xyz="-0.09006494928320063 -0.06540178000533965 0.18938154623571593" rpy="0 0 0"></origin>
		</collision>
		<collision>
			<geometry>
				<sphere radius="0.122286"></sphere>
			</geometry>
			<origin xyz="-0.08579594928320064 0.08235421999466035 0.19090354623571593" rpy="0 0 0"></origin>
		</collision>
	</link>
	<link name="head_camera_link"></link>
	<link name="head_camera_rgb_frame"></link>
	<link name="head_camera_rgb_optical_frame"></link>
	<link name="head_camera_depth_frame"></link>
	<link name="head_camera_depth_optical_frame"></link>
	<joint name="torso_lift_joint" type="prismatic">
		<origin rpy="-6.123E-17 0 0" xyz="-0.086875 0 0.37743"></origin>
		<parent link="base_link"></parent>
		<child link="torso_lift_link"></child>
		<axis xyz="0 0 1"></axis>
		<limit effort="450.0" lower="0" upper="0.38615" velocity="0.1"></limit>
		<dynamics damping="100.0"></dynamics>
	</joint>
	<joint name="head_pan_joint" type="fixed">
		<origin rpy="0 0 0" xyz="0.053125 0 0.603001417713939"></origin>
		<parent link="torso_lift_link"></parent>
		<child link="head_pan_link"></child>
		<axis xyz="0 0 1"></axis>
	</joint>
	<joint name="head_tilt_joint" type="fixed">
		<origin rpy="0 0 0" xyz="0.14253 0 0.057999"></origin>
		<parent link="head_pan_link"></parent>
		<child link="head_tilt_link"></child>
		<axis xyz="0 1 0"></axis>
	</joint>
	<joint name="shoulder_pan_joint" type="revolute">
		<origin rpy="0 0 0" xyz="0.119525 0 0.34858"></origin>
		<parent link="torso_lift_link"></parent>
		<child link="shoulder_pan_link"></child>
		<axis xyz="0 0 1"></axis>
		<dynamics damping="1.0"></dynamics>
		<limit effort="33.82" lower="-1.6056" upper="1.6056" velocity="1.256"></limit>
	</joint>
	<joint name="shoulder_lift_joint" type="revolute">
		<origin rpy="0 0 0" xyz="0.117 0 0.0599999999999999"></origin>
		<parent link="shoulder_pan_link"></parent>
		<child link="shoulder_lift_link"></child>
		<axis xyz="0 1 0"></axis>
		<dynamics damping="1.0"></dynamics>
		<limit effort="131.76" lower="-1.221" upper="1.518" velocity="1.454"></limit>
	</joint>
	<joint name="upperarm_roll_joint" type="revolute">
		<origin rpy="0 0 0" xyz="0.219 0 0"></origin>
		<parent link="shoulder_lift_link"></parent>
		<child link="upperarm_roll_link"></child>
		<axis xyz="1 0 0"></axis>
		<dynamics damping="5.0"></dynamics>
		<limit effort="76.94" velocity="1.571" lower="-3.14159" upper="3.14159"></limit>
	</joint>
	<joint name="elbow_flex_joint" type="revolute">
		<origin rpy="0 0 0" xyz="0.133 0 0"></origin>
		<parent link="upperarm_roll_link"></parent>
		<child link="elbow_flex_link"></child>
		<axis xyz="0 1 0"></axis>
		<dynamics damping="1.0"></dynamics>
		<limit effort="66.18" lower="-2.251" upper="2.251" velocity="1.521"></limit>
	</joint>
	<joint name="forearm_roll_joint" type="revolute">
		<origin rpy="0 0 0" xyz="0.197 0 0"></origin>
		<parent link="elbow_flex_link"></parent>
		<child link="forearm_roll_link"></child>
		<axis xyz="1 0 0"></axis>
		<dynamics damping="5.0"></dynamics>
		<limit effort="29.35" velocity="1.571" lower="-3.14159" upper="3.14159"></limit>
	</joint>
	<joint name="wrist_flex_joint" type="revolute">
		<origin rpy="0 0 0" xyz="0.1245 0 0"></origin>
		<parent link="forearm_roll_link"></parent>
		<child link="wrist_flex_link"></child>
		<axis xyz="0 1 0"></axis>
		<dynamics damping="1.0"></dynamics>
		<limit effort="25.7" lower="-2.16" upper="2.16" velocity="2.268"></limit>
	</joint>
	<joint name="wrist_roll_joint" type="revolute">
		<origin rpy="0 0 0" xyz="0.1385 0 0"></origin>
		<parent link="wrist_flex_link"></parent>
		<child link="wrist_roll_link"></child>
		<axis xyz="1 0 0"></axis>
		<limit effort="7.36" velocity="2.268" lower="-3.14159" upper="3.14159"></limit>
		<dynamics damping="5.0"></dynamics>
	</joint>
	<joint name="gripper_axis" type="fixed">
		<origin rpy="0 0 0" xyz="0.16645 0 0"></origin>
		<parent link="wrist_roll_link"></parent>
		<child link="gripper_link"></child>
		<axis xyz="0 1 0"></axis>
	</joint>
	<joint name="r_gripper_finger_joint" type="fixed">
		<origin rpy="0 0 0" xyz="0 0.065425 0"></origin>
		<parent link="gripper_link"></parent>
		<child link="r_gripper_finger_link"></child>
		<axis xyz="0 1 0"></axis>
	</joint>
	<joint name="l_gripper_finger_joint" type="fixed">
		<origin rpy="0 0 0" xyz="0 -0.065425 0"></origin>
		<parent link="gripper_link"></parent>
		<child link="l_gripper_finger_link"></child>
		<axis xyz="0 -1 0"></axis>
	</joint>
	<joint name="torso_fixed_joint" type="fixed">
		<origin rpy="-6.12303176911189E-17 0 0" xyz="-0.086875 0 0.377425"></origin>
		<parent link="base_link"></parent>
		<child link="torso_fixed_link"></child>
		<axis xyz="0 1 0"></axis>
	</joint>
	<joint name="head_camera_joint" type="fixed">
		<origin rpy="0 0 0" xyz="0.055 0 0.0225"></origin>
		<parent link="head_tilt_link"></parent>
		<child link="head_camera_link"></child>
	</joint>
	<joint name="head_camera_rgb_joint" type="fixed">
		<origin rpy="0 0 0" xyz="0 0.02 0"></origin>
		<parent link="head_camera_link"></parent>
		<child link="head_camera_rgb_frame"></child>
	</joint>
	<joint name="head_camera_rgb_optical_joint" type="fixed">
		<origin rpy="-1.57079632679 0 -1.57079632679" xyz="0 0 0"></origin>
		<parent link="head_camera_rgb_frame"></parent>
		<child link="head_camera_rgb_optical_frame"></child>
	</joint>
	<joint name="head_camera_depth_joint" type="fixed">
		<origin rpy="0 0 0" xyz="0 0.045 0"></origin>
		<parent link="head_camera_link"></parent>
		<child link="head_camera_depth_frame"></child>
	</joint>
	<joint name="head_camera_depth_optical_joint" type="fixed">
		<origin rpy="-1.57079632679 0 -1.57079632679" xyz="0 0 0"></origin>
		<parent link="head_camera_depth_frame"></parent>
		<child link="head_camera_depth_optical_frame"></child>
	</joint>
</robot>