<?xml version="1.0" encoding="utf-8"?>
<robot name="fetch" path="assets/fetch/fetch_simple.urdf">
	<link name="base_link">
		<inertial>
			<origin rpy="0 0 0" xyz="-0.0036 0.0 0.0014"></origin>
			<mass value="70.1294"></mass>
			<inertia ixx="1.225" ixy="0.0099" ixz="0.0062" iyy="1.2853" iyz="-0.0034" izz="0.987"></inertia>
		</inertial>
		<visual>
			<origin rpy="0 0 0" xyz="0 0 0"></origin>
			<geometry>
				<mesh filename="package://meshes/base_link.dae"></mesh>
			</geometry>
			<material name="">
				<color rgba="0.356 0.361 0.376 1"></color>
			</material>
		</visual>
		<collision>
			<geometry>
				<sphere radius="0.209715"></sphere>
			</geometry>
			<origin xyz="-0.07904908817266512 0.05102631609969301 -0.00226498058874109" rpy="0 0 0"></origin>
		</collision>
		<collision>
			<geometry>
				<sphere radius="0.204358"></sphere>
			</geometry>
			<origin xyz="0.04697991182733487 0.076696316099693 0.0017750194112589098" rpy="0 0 0"></origin>
		</collision>
		<collision>
			<geometry>
				<sphere radius="0.204678"></sphere>
			</geometry>
			<origin xyz="-0.07980608817266513 -0.05722268390030699 0.0016900194112589098" rpy="0 0 0"></origin>
		</collision>
		<collision>
			<geometry>
				<sphere radius="0.206523"></sphere>
			</geometry>
			<origin xyz="0.046349911827334875 -0.07559268390030699 0.00046101941125890975" rpy="0 0 0"></origin>
		</collision>
		<collision>
			<geometry>
				<sphere radius="0.119672"></sphere>
			</geometry>
			<origin xyz="-0.16635808817266512 -0.00381868390030699 0.07470001941125891" rpy="0 0 0"></origin>
		</collision>
		<collision>
			<geometry>
				<sphere radius="0.206366"></sphere>
			</geometry>
			<origin xyz="0.09538291182733487 0.00638931609969301 0.0007070194112589103" rpy="0 0 0"></origin>
		</collision>
		<collision>
			<geometry>
				<sphere radius="0.164214"></sphere>
			</geometry>
			<origin xyz="0.10071891182733488 0.08698631609969301 0.03745301941125891" rpy="0 0 0"></origin>
		</collision>
		<collision>
			<geometry>
				<sphere radius="0.160226"></sphere>
			</geometry>
			<origin xyz="0.11175191182733488 -0.084965683900307 0.04551401941125891" rpy="0 0 0"></origin>
		</collision>
	</link>
	<link name="torso_lift_link">
		<inertial>
			<origin rpy="0 0 0" xyz="-0.0013 -0.0009 0.2935"></origin>
			<mass value="10.7796"></mass>
			<inertia ixx="0.3354" ixy="0.0" ixz="-0.0162" iyy="0.3354" iyz="-0.0006" izz="0.0954"></inertia>
		</inertial>
		<visual>
			<origin rpy="0 0 0" xyz="0 0 0"></origin>
			<geometry>
				<mesh filename="package://meshes/torso_lift_link.dae"></mesh>
			</geometry>
			<material name="">
				<color rgba="1 1 1 1"></color>
			</material>
		</visual>
		<collision>
			<geometry>
				<sphere radius="0.122065"></sphere>
			</geometry>
			<origin xyz="-0.001181861660188252 -0.04986958509574601 0.15834502588046478" rpy="0 0 0"></origin>
		</collision>
		<collision>
			<geometry>
				<sphere radius="0.126248"></sphere>
			</geometry>
			<origin xyz="0.002046138339811748 0.05510541490425399 0.14946902588046476" rpy="0 0 0"></origin>
		</collision>
		<collision>
			<geometry>
				<sphere radius="0.132491"></sphere>
			</geometry>
			<origin xyz="-0.0013288616601882521 -0.05121258509574601 0.014485025880464773" rpy="0 0 0"></origin>
		</collision>
		<collision>
			<geometry>
				<sphere radius="0.12478"></sphere>
			</geometry>
			<origin xyz="-0.0011868616601882521 0.051597414904253985 0.0009440258804647734" rpy="0 0 0"></origin>
		</collision>
		<collision>
			<geometry>
				<sphere radius="0.133871"></sphere>
			</geometry>
			<origin xyz="-0.001449861660188252 -0.053067585095746016 -0.14534497411953523" rpy="0 0 0"></origin>
		</collision>
		<collision>
			<geometry>
				<sphere radius="0.134936"></sphere>
			</geometry>
			<origin xyz="-0.001058861660188252 0.05209441490425399 -0.1444119741195352" rpy="0 0 0"></origin>
		</collision>
		<collision>
			<geometry>
				<sphere radius="0.029644"></sphere>
			</geometry>
			<origin xyz="0.05337813833981175 0.12087541490425399 -0.21746597411953522" rpy="0 0 0"></origin>
		</collision>
		<collision>
			<geometry>
				<sphere radius="0.075243"></sphere>
			</geometry>
			<origin xyz="0.035025138339811746 -0.08851758509574602 -0.18747297411953523" rpy="0 0 0"></origin>
		</collision>
		<collision>
			<geometry>
				<sphere radius="0.058888"></sphere>
			</geometry>
			<origin xyz="0.014975979504110427 4.427090518643737e-05 -0.005406080091327666" rpy="0 0 0"></origin>
		</collision>
		<collision>
			<geometry>
				<sphere radius="0.040877"></sphere>
			</geometry>
			<origin xyz="-0.028686020495889576 0.018402270905186438 -0.023599080091327666" rpy="0 0 0"></origin>
		</collision>
		<collision>
			<geometry>
				<sphere radius="0.039214"></sphere>
			</geometry>
			<origin xyz="-0.029908020495889576 -0.019295729094813564 -0.024282080091327665" rpy="0 0 0"></origin>
		</collision>
		<collision>
			<geometry>
				<sphere radius="0.040376"></sphere>
			</geometry>
			<origin xyz="-0.029552020495889574 -0.019197729094813563 0.019524919908672334" rpy="0 0 0"></origin>
		</collision>
		<collision>
			<geometry>
				<sphere radius="0.038675"></sphere>
			</geometry>
			<origin xyz="-0.031216020495889573 0.020589270905186436 0.018243919908672336" rpy="0 0 0"></origin>
		</collision>
		<collision>
			<geometry>
				<sphere radius="0.035519"></sphere>
			</geometry>
			<origin xyz="0.002858979504110427 0.018439270905186437 0.026378919908672336" rpy="0 0 0"></origin>
		</collision>
		<collision>
			<geometry>
				<sphere radius="0.050126"></sphere>
			</geometry>
			<origin xyz="0.019815979504110428 -0.009911729094813563 0.017944919908672335" rpy="0 0 0"></origin>
		</collision>
		<collision>
			<geometry>
				<sphere radius="0.044396"></sphere>
			</geometry>
			<origin xyz="0.028092979504110428 0.009925270905186438 0.022930919908672336" rpy="0 0 0"></origin>
		</collision>
		<collision>
			<geometry>
				<sphere radius="0.060914"></sphere>
			</geometry>
			<origin xyz="-0.007007271258362201 -0.030783140552517796 -0.39673148898670196" rpy="0 0 0"></origin>
		</collision>
		<collision>
			<geometry>
				<sphere radius="0.059262"></sphere>
			</geometry>
			<origin xyz="-0.007593271258362201 0.027007859447482203 -0.40783948898670197" rpy="0 0 0"></origin>
		</collision>
		<collision>
			<geometry>
				<sphere radius="0.061581"></sphere>
			</geometry>
			<origin xyz="0.003139728741637799 0.0361348594474822 -0.360135488986702" rpy="0 0 0"></origin>
		</collision>
		<collision>
			<geometry>
				<sphere radius="0.049577"></sphere>
			</geometry>
			<origin xyz="0.0514687287416378 0.011249859447482203 -0.348077488986702" rpy="0 0 0"></origin>
		</collision>
		<collision>
			<geometry>
				<sphere radius="0.05884"></sphere>
			</geometry>
			<origin xyz="0.019333728741637798 -0.033092140552517794 -0.35772648898670195" rpy="0 0 0"></origin>
		</collision>
		<collision>
			<geometry>
				<sphere radius="0.042042"></sphere>
			</geometry>
			<origin xyz="-0.0346822712583622 -0.041564140552517795 -0.340178488986702" rpy="0 0 0"></origin>
		</collision>
		<collision>
			<geometry>
				<sphere radius="0.033433"></sphere>
			</geometry>
			<origin xyz="-0.0646552712583622 -0.005997140552517796 -0.331521488986702" rpy="0 0 0"></origin>
		</collision>
		<collision>
			<geometry>
				<sphere radius="0.039454"></sphere>
			</geometry>
			<origin xyz="-0.0469092712583622 0.0412628594474822 -0.33794748898670196" rpy="0 0 0"></origin>
		</collision>
	</link>
	<link name="head_pan_link">
		<inertial>
			<origin rpy="0 0 0" xyz="0.0321 0.0161 0.0390"></origin>
			<mass value="2.2556"></mass>
			<inertia ixx="0.0129" ixy="0.0002" ixz="0.0007" iyy="0.0095" iyz="-0.0" izz="0.0184"></inertia>
		</inertial>
		<visual>
			<origin rpy="0 0 0" xyz="0 0 0"></origin>
			<geometry>
				<mesh filename="package://meshes/head_pan_link.dae"></mesh>
			</geometry>
			<material name="">
				<color rgba="0.356 0.361 0.376 1"></color>
			</material>
		</visual>
		<collision>
			<geometry>
				<sphere radius="0.069663"></sphere>
			</geometry>
			<origin xyz="0.06321750602192902 -0.07658237139562502 0.004734311192088499" rpy="0 0 0"></origin>
		</collision>
		<collision>
			<geometry>
				<sphere radius="0.075663"></sphere>
			</geometry>
			<origin xyz="-0.027952493978070987 -0.07333537139562502 0.0020633111920884996" rpy="0 0 0"></origin>
		</collision>
		<collision>
			<geometry>
				<sphere radius="0.071032"></sphere>
			</geometry>
			<origin xyz="0.056141506021929015 -0.0008513713956250146 0.0030953111920885" rpy="0 0 0"></origin>
		</collision>
		<collision>
			<geometry>
				<sphere radius="0.072189"></sphere>
			</geometry>
			<origin xyz="0.06120450602192901 0.07447962860437499 0.0038783111920885" rpy="0 0 0"></origin>
		</collision>
		<collision>
			<geometry>
				<sphere radius="0.074008"></sphere>
			</geometry>
			<origin xyz="-0.024169493978070986 0.073102628604375 0.0019853111920884996" rpy="0 0 0"></origin>
		</collision>
		<collision>
			<geometry>
				<sphere radius="0.062736"></sphere>
			</geometry>
			<origin xyz="-0.09575949397807099 0.03836962860437498 -0.0106496888079115" rpy="0 0 0"></origin>
		</collision>
		<collision>
			<geometry>
				<sphere radius="0.062999"></sphere>
			</geometry>
			<origin xyz="-0.10585949397807098 -0.03338837139562501 -0.0133526888079115" rpy="0 0 0"></origin>
		</collision>
		<collision>
			<geometry>
				<sphere radius="0.057197"></sphere>
			</geometry>
			<origin xyz="-0.023542493978070983 -0.005501371395625014 0.0014783111920884998" rpy="0 0 0"></origin>
		</collision>
	</link>
	<link name="head_tilt_link">
		<inertial>
			<origin rpy="0 0 0" xyz="0.0081 0.0025 0.0113"></origin>
			<mass value="0.9087"></mass>
			<inertia ixx="0.0061" ixy="-0.0" ixz="0.0002" iyy="0.0014" iyz="-0.0001" izz="0.0061"></inertia>
		</inertial>
		<visual>
			<origin rpy="0 0 0" xyz="0 0 0"></origin>
			<geometry>
				<mesh filename="package://meshes/head_tilt_link.dae"></mesh>
			</geometry>
			<material name="">
				<color rgba="0.086 0.506 0.767 1"></color>
			</material>
		</visual>
		<collision>
			<geometry>
				<sphere radius="0.062253"></sphere>
			</geometry>
			<origin xyz="-0.005009322531696219 -0.04678028952917898 -0.001391428211611731" rpy="0 0 0"></origin>
		</collision>
		<collision>
			<geometry>
				<sphere radius="0.060026"></sphere>
			</geometry>
			<origin xyz="0.001219677468303781 0.022923710470821018 0.001508571788388269" rpy="0 0 0"></origin>
		</collision>
		<collision>
			<geometry>
				<sphere radius="0.039413"></sphere>
			</geometry>
			<origin xyz="0.01984567746830378 -0.014386289529178984 0.02044557178838827" rpy="0 0 0"></origin>
		</collision>
		<collision>
			<geometry>
				<sphere radius="0.041709"></sphere>
			</geometry>
			<origin xyz="0.01838167746830378 -0.064502289529179 0.01913357178838827" rpy="0 0 0"></origin>
		</collision>
		<collision>
			<geometry>
				<sphere radius="0.043307"></sphere>
			</geometry>
			<origin xyz="0.01783967746830378 0.06358571047082101 0.01775657178838827" rpy="0 0 0"></origin>
		</collision>
		<collision>
			<geometry>
				<sphere radius="0.05409"></sphere>
			</geometry>
			<origin xyz="0.0014016774683037808 0.05359371047082102 -0.01096142821161173" rpy="0 0 0"></origin>
		</collision>
		<collision>
			<geometry>
				<sphere radius="0.048172"></sphere>
			</geometry>
			<origin xyz="-0.01629332253169622 0.05800171047082102 0.005139571788388269" rpy="0 0 0"></origin>
		</collision>
		<collision>
			<geometry>
				<sphere radius="0.055982"></sphere>
			</geometry>
			<origin xyz="0.0019336774683037811 -0.052037289529178986 -0.008118428211611732" rpy="0 0 0"></origin>
		</collision>
	</link>
	<link name="shoulder_pan_link">
		<inertial>
			<origin rpy="0 0 0" xyz="0.0927 -0.0056 0.0564"></origin>
			<mass value="2.5587"></mass>
			<inertia ixx="0.0043" ixy="-0.0001" ixz="0.001" iyy="0.0087" iyz="-0.0001" izz="0.0087"></inertia>
		</inertial>
		<visual>
			<origin rpy="0 0 0" xyz="0 0 0"></origin>
			<geometry>
				<mesh filename="package://meshes/shoulder_pan_link.dae"></mesh>
			</geometry>
			<material name="">
				<color rgba="1 1 1 1"></color>
			</material>
		</visual>
		<collision>
			<geometry>
				<sphere radius="0.05225"></sphere>
			</geometry>
			<origin xyz="0.060757666795426206 -0.012083929498554278 0.012144048801112554" rpy="0 0 0"></origin>
		</collision>
		<collision>
			<geometry>
				<sphere radius="0.054616"></sphere>
			</geometry>
			<origin xyz="0.05667466679542621 -0.010518929498554278 0.033895048801112555" rpy="0 0 0"></origin>
		</collision>
		<collision>
			<geometry>
				<sphere radius="0.054425"></sphere>
			</geometry>
			<origin xyz="0.008815666795426209 -0.008025929498554277 0.028245048801112553" rpy="0 0 0"></origin>
		</collision>
		<collision>
			<geometry>
				<sphere radius="0.057707"></sphere>
			</geometry>
			<origin xyz="0.014889666795426209 -0.0034359294985542767 -0.005219951198887446" rpy="0 0 0"></origin>
		</collision>
		<collision>
			<geometry>
				<sphere radius="0.062897"></sphere>
			</geometry>
			<origin xyz="-0.03200533320457379 0.009762070501445723 -0.022837951198887447" rpy="0 0 0"></origin>
		</collision>
		<collision>
			<geometry>
				<sphere radius="0.054527"></sphere>
			</geometry>
			<origin xyz="-0.03550833320457379 0.0032070705014457237 0.008910048801112555" rpy="0 0 0"></origin>
		</collision>
		<collision>
			<geometry>
				<sphere radius="0.056507"></sphere>
			</geometry>
			<origin xyz="-0.053675333204573794 0.011895070501445722 -0.030564951198887448" rpy="0 0 0"></origin>
		</collision>
		<collision>
			<geometry>
				<sphere radius="0.041094"></sphere>
			</geometry>
			<origin xyz="-0.05319933320457379 0.03273107050144572 -0.043620951198887446" rpy="0 0 0"></origin>
		</collision>
	</link>
	<link name="shoulder_lift_link">
		<inertial>
			<origin rpy="0 0 0" xyz="0.1432 0.0072 -0.0001"></origin>
			<mass value="2.6615"></mass>
			<inertia ixx="0.0028" ixy="-0.0021" ixz="-0.0" iyy="0.0111" iyz="-0.0" izz="0.0112"></inertia>
		</inertial>
		<visual>
			<origin rpy="0 0 0" xyz="0 0 0"></origin>
			<geometry>
				<mesh filename="package://meshes/shoulder_lift_link.dae"></mesh>
			</geometry>
			<material name="">
				<color rgba="0.086 0.506 0.767 1"></color>
			</material>
		</visual>
		<collision>
			<geometry>
				<sphere radius="0.058709"></sphere>
			</geometry>
			<origin xyz="0.05038062828371096 -0.0071019304291654655 0.0026320402952215295" rpy="0 0 0"></origin>
		</collision>
		<collision>
			<geometry>
				<sphere radius="0.058634"></sphere>
			</geometry>
			<origin xyz="-0.0009603717162890413 -0.0005059304291654652 0.0004340402952215296" rpy="0 0 0"></origin>
		</collision>
		<collision>
			<geometry>
				<sphere radius="0.050463"></sphere>
			</geometry>
			<origin xyz="-0.04688437171628904 0.009880069570834534 0.01510804029522153" rpy="0 0 0"></origin>
		</collision>
		<collision>
			<geometry>
				<sphere radius="0.046071"></sphere>
			</geometry>
			<origin xyz="-0.06858937171628904 0.011356069570834536 0.00932604029522153" rpy="0 0 0"></origin>
		</collision>
		<collision>
			<geometry>
				<sphere radius="0.052379"></sphere>
			</geometry>
			<origin xyz="-0.04656837171628904 0.008073069570834535 -0.01331695970477847" rpy="0 0 0"></origin>
		</collision>
		<collision>
			<geometry>
				<sphere radius="0.043129"></sphere>
			</geometry>
			<origin xyz="-0.06800637171628904 0.013268069570834536 -0.01195595970477847" rpy="0 0 0"></origin>
		</collision>
		<collision>
			<geometry>
				<sphere radius="0.052976"></sphere>
			</geometry>
			<origin xyz="0.05670662828371096 -0.020023930429165466 0.00348704029522153" rpy="0 0 0"></origin>
		</collision>
		<collision>
			<geometry>
				<sphere radius="0.050977"></sphere>
			</geometry>
			<origin xyz="0.05816562828371096 -0.017295930429165465 -0.00940895970477847" rpy="0 0 0"></origin>
		</collision>
	</link>
	<link name="upperarm_roll_link">
		<inertial>
			<origin rpy="0 0 0" xyz="0.1165 0.0014 0.0000"></origin>
			<mass value="2.3311"></mass>
			<inertia ixx="0.0019" ixy="-0.0001" ixz="0.0" iyy="0.0045" iyz="0.0" izz="0.0047"></inertia>
		</inertial>
		<visual>
			<origin rpy="0 0 0" xyz="0 0 0"></origin>
			<geometry>
				<mesh filename="package://meshes/upperarm_roll_link.dae"></mesh>
			</geometry>
			<material name="">
				<color rgba="1 1 1 1"></color>
			</material>
		</visual>
		<collision>
			<geometry>
				<sphere radius="0.05066"></sphere>
			</geometry>
			<origin xyz="0.06687218341219686 -0.010250072595099757 0.005860481263865982" rpy="0 0 0"></origin>
		</collision>
		<collision>
			<geometry>
				<sphere radius="0.049859"></sphere>
			</geometry>
			<origin xyz="0.06168518341219687 -0.011317072595099755 -0.008427518736134018" rpy="0 0 0"></origin>
		</collision>
		<collision>
			<geometry>
				<sphere radius="0.05583"></sphere>
			</geometry>
			<origin xyz="0.02397018341219687 -0.0035770725950997548 0.002233481263865982" rpy="0 0 0"></origin>
		</collision>
		<collision>
			<geometry>
				<sphere radius="0.053398"></sphere>
			</geometry>
			<origin xyz="-0.01437681658780313 0.004027927404900244 -3.151873613401823e-05" rpy="0 0 0"></origin>
		</collision>
		<collision>
			<geometry>
				<sphere radius="0.05029"></sphere>
			</geometry>
			<origin xyz="-0.056796816587803126 0.0009279274049002447 0.0031834812638659817" rpy="0 0 0"></origin>
		</collision>
		<collision>
			<geometry>
				<sphere radius="0.038535"></sphere>
			</geometry>
			<origin xyz="-0.06792181658780314 0.011877927404900245 -0.019941518736134017" rpy="0 0 0"></origin>
		</collision>
		<collision>
			<geometry>
				<sphere radius="0.043973"></sphere>
			</geometry>
			<origin xyz="-0.06351081658780312 0.028596927404900243 -0.0012225187361340182" rpy="0 0 0"></origin>
		</collision>
		<collision>
			<geometry>
				<sphere radius="0.048967"></sphere>
			</geometry>
			<origin xyz="-0.05843781658780313 0.017311927404900243 0.009639481263865981" rpy="0 0 0"></origin>
		</collision>
	</link>
	<link name="elbow_flex_link">
		<inertial>
			<origin rpy="0 0 0" xyz="0.1279 0.0073 0.0000"></origin>
			<mass value="2.1299"></mass>
			<inertia ixx="0.0024" ixy="-0.0016" ixz="0.0" iyy="0.0082" iyz="-0.0" izz="0.0084"></inertia>
		</inertial>
		<visual>
			<origin rpy="0 0 0" xyz="0 0 0"></origin>
			<geometry>
				<mesh filename="package://meshes/elbow_flex_link.dae"></mesh>
			</geometry>
			<material name="">
				<color rgba="0.086 0.506 0.767 1"></color>
			</material>
		</visual>
		<collision>
			<geometry>
				<sphere radius="0.049798"></sphere>
			</geometry>
			<origin xyz="-0.061874360824088745 0.010521414571115661 0.006054263651654349" rpy="0 0 0"></origin>
		</collision>
		<collision>
			<geometry>
				<sphere radius="0.049267"></sphere>
			</geometry>
			<origin xyz="-0.058932360824088745 0.010488414571115663 -0.007471736348345651" rpy="0 0 0"></origin>
		</collision>
		<collision>
			<geometry>
				<sphere radius="0.056237"></sphere>
			</geometry>
			<origin xyz="-0.025883360824088746 0.004383414571115662 0.0020542636516543496" rpy="0 0 0"></origin>
		</collision>
		<collision>
			<geometry>
				<sphere radius="0.05027"></sphere>
			</geometry>
			<origin xyz="0.005307639175911252 -0.0012505854288843371 -5.973634834565053e-05" rpy="0 0 0"></origin>
		</collision>
		<collision>
			<geometry>
				<sphere radius="0.058497"></sphere>
			</geometry>
			<origin xyz="0.04196563917591125 -0.006699585428884337 -0.00019473634834565052" rpy="0 0 0"></origin>
		</collision>
		<collision>
			<geometry>
				<sphere radius="0.023624"></sphere>
			</geometry>
			<origin xyz="0.07097563917591125 -0.013036585428884338 0.02918426365165435" rpy="0 0 0"></origin>
		</collision>
		<collision>
			<geometry>
				<sphere radius="0.04463"></sphere>
			</geometry>
			<origin xyz="0.05534163917591125 -0.021488585428884335 -0.01302673634834565" rpy="0 0 0"></origin>
		</collision>
		<collision>
			<geometry>
				<sphere radius="0.047495"></sphere>
			</geometry>
			<origin xyz="0.052718639175911255 -0.02360158542888434 0.004989263651654349" rpy="0 0 0"></origin>
		</collision>
	</link>
	<link name="forearm_roll_link">
		<inertial>
			<origin rpy="0 0 0" xyz="0.1097 -0.0266 0.0000"></origin>
			<mass value="1.6563"></mass>
			<inertia ixx="0.0016" ixy="-0.0003" ixz="0.0" iyy="0.003" iyz="-0.0" izz="0.0035"></inertia>
		</inertial>
		<visual>
			<origin rpy="0 0 0" xyz="0 0 0"></origin>
			<geometry>
				<mesh filename="package://meshes/forearm_roll_link.dae"></mesh>
			</geometry>
			<material name="">
				<color rgba="1 1 1 1"></color>
			</material>
		</visual>
		<collision>
			<geometry>
				<sphere radius="0.058439"></sphere>
			</geometry>
			<origin xyz="-0.029939664166950583 0.00932488582073533 -0.0008448444287301242" rpy="0 0 0"></origin>
		</collision>
		<collision>
			<geometry>
				<sphere radius="0.050793"></sphere>
			</geometry>
			<origin xyz="0.019576335833049414 -0.01137011417926467 -0.002021844428730124" rpy="0 0 0"></origin>
		</collision>
		<collision>
			<geometry>
				<sphere radius="0.046275"></sphere>
			</geometry>
			<origin xyz="-0.04201866416695058 0.02723988582073533 0.012062155571269877" rpy="0 0 0"></origin>
		</collision>
		<collision>
			<geometry>
				<sphere radius="0.042256"></sphere>
			</geometry>
			<origin xyz="-0.04560666416695058 0.02923788582073533 -0.016208844428730124" rpy="0 0 0"></origin>
		</collision>
		<collision>
			<geometry>
				<sphere radius="0.039656"></sphere>
			</geometry>
			<origin xyz="-0.04843266416695058 0.04420688582073533 0.00014315557126987584" rpy="0 0 0"></origin>
		</collision>
		<collision>
			<geometry>
				<sphere radius="0.036325"></sphere>
			</geometry>
			<origin xyz="0.06540233583304941 -0.02682111417926467 -0.020134844428730123" rpy="0 0 0"></origin>
		</collision>
		<collision>
			<geometry>
				<sphere radius="0.034973"></sphere>
			</geometry>
			<origin xyz="0.05652833583304941 -0.024424114179264673 0.019697155571269876" rpy="0 0 0"></origin>
		</collision>
		<collision>
			<geometry>
				<sphere radius="0.03138"></sphere>
			</geometry>
			<origin xyz="0.08362233583304941 -0.029898114179264672 0.006854155571269876" rpy="0 0 0"></origin>
		</collision>
	</link>
	<link name="wrist_flex_link">
		<inertial>
			<origin rpy="0 0 0" xyz="0.0882 0.0009 -0.0001"></origin>
			<mass value="1.725"></mass>
			<inertia ixx="0.0018" ixy="-0.0001" ixz="-0.0" iyy="0.0042" iyz="0.0" izz="0.0042"></inertia>
		</inertial>
		<visual>
			<origin rpy="0 0 0" xyz="0 0 0"></origin>
			<geometry>
				<mesh filename="package://meshes/wrist_flex_link.dae"></mesh>
			</geometry>
			<material name="">
				<color rgba="0.086 0.506 0.767 1"></color>
			</material>
		</visual>
		<collision>
			<geometry>
				<sphere radius="0.059878"></sphere>
			</geometry>
			<origin xyz="-0.026314248472254657 0.00908400191514551 -9.191774894356707e-05" rpy="0 0 0"></origin>
		</collision>
		<collision>
			<geometry>
				<sphere radius="0.060287"></sphere>
			</geometry>
			<origin xyz="0.027252751527745343 0.00308200191514551 0.00011208225105643294" rpy="0 0 0"></origin>
		</collision>
		<collision>
			<geometry>
				<sphere radius="0.054938"></sphere>
			</geometry>
			<origin xyz="0.032350751527745344 -0.01007099808485449 -0.004895917748943567" rpy="0 0 0"></origin>
		</collision>
		<collision>
			<geometry>
				<sphere radius="0.046768"></sphere>
			</geometry>
			<origin xyz="-0.026606248472254658 -0.01789899808485449 -0.012277917748943568" rpy="0 0 0"></origin>
		</collision>
		<collision>
			<geometry>
				<sphere radius="0.037029"></sphere>
			</geometry>
			<origin xyz="0.045303751527745344 -0.01608499808485449 0.018155082251056432" rpy="0 0 0"></origin>
		</collision>
		<collision>
			<geometry>
				<sphere radius="0.043566"></sphere>
			</geometry>
			<origin xyz="-0.04272024847225466 -0.02068699808485449 -0.002245917748943567" rpy="0 0 0"></origin>
		</collision>
		<collision>
			<geometry>
				<sphere radius="0.050543"></sphere>
			</geometry>
			<origin xyz="-0.028693248472254657 -0.01507399808485449 0.009228082251056433" rpy="0 0 0"></origin>
		</collision>
		<collision>
			<geometry>
				<sphere radius="0.060019"></sphere>
			</geometry>
			<origin xyz="0.002289751527745342 -0.0011679980848544897 -2.9177489435670634e-06" rpy="0 0 0"></origin>
		</collision>
	</link>
	<link name="wrist_roll_link">
		<inertial>
			<origin rpy="0 0 0" xyz="0.0095 0.0004 -0.0002"></origin>
			<mass value="0.1354"></mass>
			<inertia ixx="0.0001" ixy="0.0" ixz="0.0" iyy="0.0001" iyz="0.0" izz="0.0001"></inertia>
		</inertial>
		<visual>
			<origin rpy="0 0 0" xyz="0 0 0"></origin>
			<geometry>
				<mesh filename="package://meshes/wrist_roll_link.dae"></mesh>
			</geometry>
			<material name="">
				<color rgba="1 1 1 1"></color>
			</material>
		</visual>
		<collision>
			<geometry>
				<sphere radius="0.025863"></sphere>
			</geometry>
			<origin xyz="-0.0008019773953908313 0.004891117385728573 0.0280785332604151" rpy="0 0 0"></origin>
		</collision>
		<collision>
			<geometry>
				<sphere radius="0.027048"></sphere>
			</geometry>
			<origin xyz="-4.997739539083128e-05 -0.019300882614271427 0.020029533260415098" rpy="0 0 0"></origin>
		</collision>
		<collision>
			<geometry>
				<sphere radius="0.025555"></sphere>
			</geometry>
			<origin xyz="-0.0010529773953908313 -0.027911882614271428 -0.0036434667395849017" rpy="0 0 0"></origin>
		</collision>
		<collision>
			<geometry>
				<sphere radius="0.026156"></sphere>
			</geometry>
			<origin xyz="-0.0004709773953908312 0.024496117385728572 0.012906533260415099" rpy="0 0 0"></origin>
		</collision>
		<collision>
			<geometry>
				<sphere radius="0.025095"></sphere>
			</geometry>
			<origin xyz="-0.0012189773953908312 0.026843117385728574 -0.009933466739584902" rpy="0 0 0"></origin>
		</collision>
		<collision>
			<geometry>
				<sphere radius="0.024466"></sphere>
			</geometry>
			<origin xyz="0.0016320226046091686 -0.0013718826142714272 -0.0014894667395849016" rpy="0 0 0"></origin>
		</collision>
		<collision>
			<geometry>
				<sphere radius="0.026779"></sphere>
			</geometry>
			<origin xyz="-0.00022797739539083127 -0.013636882614271427 -0.024927466739584903" rpy="0 0 0"></origin>
		</collision>
		<collision>
			<geometry>
				<sphere radius="0.026141"></sphere>
			</geometry>
			<origin xyz="-0.00040097739539083146 0.011795117385728573 -0.0260574667395849" rpy="0 0 0"></origin>
		</collision>
	</link>
	<link name="gripper_link">
		<inertial>
			<origin rpy="0 0 0" xyz="-0.0900 -0.0001 -0.0017"></origin>
			<mass value="1.5175"></mass>
			<inertia ixx="0.0013" ixy="-0.0" ixz="0.0" iyy="0.0019" iyz="-0.0" izz="0.0024"></inertia>
		</inertial>
		<visual>
			<origin rpy="0 0 0" xyz="0 0 0"></origin>
			<geometry>
				<mesh filename="package://meshes/gripper_link.dae"></mesh>
			</geometry>
		</visual>
		<collision>
			<geometry>
				<sphere radius="0.043819"></sphere>
			</geometry>
			<origin xyz="-0.02134147104764939 0.023699519766029343 -0.0001561028390709171" rpy="0 0 0"></origin>
		</collision>
		<collision>
			<geometry>
				<sphere radius="0.044235"></sphere>
			</geometry>
			<origin xyz="0.02168052895235061 0.022730519766029345 0.001162897160929083" rpy="0 0 0"></origin>
		</collision>
		<collision>
			<geometry>
				<sphere radius="0.044911"></sphere>
			</geometry>
			<origin xyz="0.02157852895235061 -0.022636480233970656 -0.0005511028390709171" rpy="0 0 0"></origin>
		</collision>
		<collision>
			<geometry>
				<sphere radius="0.046087"></sphere>
			</geometry>
			<origin xyz="-0.01922247104764939 -0.021586480233970657 0.00022989716092908295" rpy="0 0 0"></origin>
		</collision>
		<collision>
			<geometry>
				<sphere radius="0.047125"></sphere>
			</geometry>
			<origin xyz="-0.01800747104764939 0.002195519766029344 -0.000936102839070917" rpy="0 0 0"></origin>
		</collision>
		<collision>
			<geometry>
				<sphere radius="0.007533"></sphere>
			</geometry>
			<origin xyz="0.04484252895235061 0.04377751976602934 -0.021284102839070916" rpy="0 0 0"></origin>
		</collision>
		<collision>
			<geometry>
				<sphere radius="0.040849"></sphere>
			</geometry>
			<origin xyz="0.02469452895235061 -0.022219480233970655 0.004523897160929083" rpy="0 0 0"></origin>
		</collision>
		<collision>
			<geometry>
				<sphere radius="0.003493"></sphere>
			</geometry>
			<origin xyz="-0.047010471047649396 -0.04513348023397065 -0.022887102839070916" rpy="0 0 0"></origin>
		</collision>
	</link>
	<link name="r_gripper_finger_link">
		<inertial>
			<origin rpy="0 0 0" xyz="-0.01 0 0"></origin>
			<mass value="0.0798"></mass>
			<inertia ixx="0.002" ixy="0" ixz="0" iyy="0" iyz="0" izz="0"></inertia>
		</inertial>
		<visual>
			<origin rpy="0 0 0" xyz="0 0.101425 0"></origin>
			<geometry>
				<mesh filename="package://meshes/r_gripper_finger_link.STL"></mesh>
			</geometry>
			<material name="">
				<color rgba="0.356 0.361 0.376 1"></color>
			</material>
		</visual>
		<collision>
			<geometry>
				<sphere radius="0.009203"></sphere>
			</geometry>
			<origin xyz="0.020205728055709082 0.10141806265184446 -0.005424662224501495" rpy="0 0 0"></origin>
		</collision>
		<collision>
			<geometry>
				<sphere radius="0.009709"></sphere>
			</geometry>
			<origin xyz="0.019710728055709083 0.10142106265184446 0.005031337775498505" rpy="0 0 0"></origin>
		</collision>
		<collision>
			<geometry>
				<sphere radius="0.009871"></sphere>
			</geometry>
			<origin xyz="0.008451728055709082 0.10142506265184445 -0.005049662224501495" rpy="0 0 0"></origin>
		</collision>
		<collision>
			<geometry>
				<sphere radius="0.00982"></sphere>
			</geometry>
			<origin xyz="0.006896728055709082 0.10142906265184445 0.005016337775498505" rpy="0 0 0"></origin>
		</collision>
		<collision>
			<geometry>
				<sphere radius="0.010254"></sphere>
			</geometry>
			<origin xyz="-0.0045092719442909185 0.10142106265184446 -0.005094662224501495" rpy="0 0 0"></origin>
		</collision>
		<collision>
			<geometry>
				<sphere radius="0.010434"></sphere>
			</geometry>
			<origin xyz="-0.01840427194429092 0.10141706265184446 -0.005120662224501495" rpy="0 0 0"></origin>
		</collision>
		<collision>
			<geometry>
				<sphere radius="0.010262"></sphere>
			</geometry>
			<origin xyz="-0.01877427194429092 0.10143606265184446 0.005049337775498505" rpy="0 0 0"></origin>
		</collision>
		<collision>
			<geometry>
				<sphere radius="0.009957"></sphere>
			</geometry>
			<origin xyz="-0.005617271944290918 0.10143506265184446 0.005047337775498505" rpy="0 0 0"></origin>
		</collision>
	</link>
	<link name="l_gripper_finger_link">
		<inertial>
			<origin rpy="0 0 0" xyz="-0.01 0 0"></origin>
			<mass value="0.0798"></mass>
			<inertia ixx="0.002" ixy="0" ixz="0" iyy="0" iyz="0" izz="0"></inertia>
		</inertial>
		<visual>
			<origin rpy="0 0 0" xyz="0 -0.101425 0"></origin>
			<geometry>
				<mesh filename="package://meshes/l_gripper_finger_link.STL"></mesh>
			</geometry>
			<material name="">
				<color rgba="0.356 0.361 0.376 1"></color>
			</material>
		</visual>
		<collision>
			<geometry>
				<sphere radius="0.009809"></sphere>
			</geometry>
			<origin xyz="0.019608201049087188 -0.10144464513312751 -0.004929845501590784" rpy="0 0 0"></origin>
		</collision>
		<collision>
			<geometry>
				<sphere radius="0.009664"></sphere>
			</geometry>
			<origin xyz="0.01968520104908719 -0.10137864513312751 0.005100154498409216" rpy="0 0 0"></origin>
		</collision>
		<collision>
			<geometry>
				<sphere radius="0.009762"></sphere>
			</geometry>
			<origin xyz="0.007211201049087188 -0.1012306451331275 -0.005162845501590784" rpy="0 0 0"></origin>
		</collision>
		<collision>
			<geometry>
				<sphere radius="0.009531"></sphere>
			</geometry>
			<origin xyz="0.007256201049087188 -0.1014126451331275 0.0049941544984092165" rpy="0 0 0"></origin>
		</collision>
		<collision>
			<geometry>
				<sphere radius="0.010147"></sphere>
			</geometry>
			<origin xyz="-0.018820798950912813 -0.10142164513312751 -0.005116845501590784" rpy="0 0 0"></origin>
		</collision>
		<collision>
			<geometry>
				<sphere radius="0.010063"></sphere>
			</geometry>
			<origin xyz="-0.0054747989509128115 -0.1014376451331275 -0.005038845501590784" rpy="0 0 0"></origin>
		</collision>
		<collision>
			<geometry>
				<sphere radius="0.010269"></sphere>
			</geometry>
			<origin xyz="-0.01875579895091281 -0.1014246451331275 0.005054154498409216" rpy="0 0 0"></origin>
		</collision>
		<collision>
			<geometry>
				<sphere radius="0.01016"></sphere>
			</geometry>
			<origin xyz="-0.005421798950912812 -0.10141964513312751 0.005064154498409216" rpy="0 0 0"></origin>
		</collision>
	</link>
	<link name="torso_fixed_link">
		<inertial>
			<origin rpy="0 0 0" xyz="-0.0722 0.0057 0.2656"></origin>
			<mass value="13.2775"></mass>
			<inertia ixx="0.3861" ixy="0.0015" ixz="-0.0102" iyy="0.3388" iyz="0.0117" izz="0.1018"></inertia>
		</inertial>
		<visual>
			<origin rpy="0 0 0" xyz="0 0 0"></origin>
			<geometry>
				<mesh filename="package://meshes/torso_fixed_link.dae"></mesh>
			</geometry>
			<material name="">
				<color rgba="0.086 0.506 0.767 1"></color>
			</material>
		</visual>
		<collision>
			<geometry>
				<sphere radius="0.109413"></sphere>
			</geometry>
			<origin xyz="0.0015156185728036177 -0.07826257720651422 0.13427291318262757" rpy="0 0 0"></origin>
		</collision>
		<collision>
			<geometry>
				<sphere radius="0.11015"></sphere>
			</geometry>
			<origin xyz="0.00024961857280361797 0.07337542279348579 0.1391149131826276" rpy="0 0 0"></origin>
		</collision>
		<collision>
			<geometry>
				<sphere radius="0.10859"></sphere>
			</geometry>
			<origin xyz="0.005465618572803617 0.08424442279348578 -0.13164008681737244" rpy="0 0 0"></origin>
		</collision>
		<collision>
			<geometry>
				<sphere radius="0.111204"></sphere>
			</geometry>
			<origin xyz="-0.0001183814271963823 -0.07626257720651422 -0.14104908681737244" rpy="0 0 0"></origin>
		</collision>
		<collision>
			<geometry>
				<sphere radius="0.115435"></sphere>
			</geometry>
			<origin xyz="-0.001965381427196382 0.06689442279348579 0.009583913182627574" rpy="0 0 0"></origin>
		</collision>
		<collision>
			<geometry>
				<sphere radius="0.113608"></sphere>
			</geometry>
			<origin xyz="-0.003407381427196382 0.02428442279348578 -0.13059808681737245" rpy="0 0 0"></origin>
		</collision>
		<collision>
			<geometry>
				<sphere radius="0.113426"></sphere>
			</geometry>
			<origin xyz="-0.00035838142719638207 -0.07518357720651422 -0.0033970868173724255" rpy="0 0 0"></origin>
		</collision>
		<collision>
			<geometry>
				<sphere radius="0.109908"></sphere>
			</geometry>
			<origin xyz="-0.002939381427196382 0.0025274227934857824 0.1331059131826276" rpy="0 0 0"></origin>
		</collision>
	</link>
	<link name="head_camera_link"></link>
	<link name="head_camera_rgb_frame"></link>
	<link name="head_camera_rgb_optical_frame"></link>
	<link name="head_camera_depth_frame"></link>
	<link name="head_camera_depth_optical_frame"></link>
	<joint name="torso_lift_joint" type="prismatic">
		<origin rpy="-6.123E-17 0 0" xyz="-0.086875 0 0.37743"></origin>
		<parent link="base_link"></parent>
		<child link="torso_lift_link"></child>
		<axis xyz="0 0 1"></axis>
		<limit effort="450.0" lower="0" upper="0.38615" velocity="0.1"></limit>
		<dynamics damping="100.0"></dynamics>
	</joint>
	<joint name="head_pan_joint" type="fixed">
		<origin rpy="0 0 0" xyz="0.053125 0 0.603001417713939"></origin>
		<parent link="torso_lift_link"></parent>
		<child link="head_pan_link"></child>
		<axis xyz="0 0 1"></axis>
	</joint>
	<joint name="head_tilt_joint" type="fixed">
		<origin rpy="0 0 0" xyz="0.14253 0 0.057999"></origin>
		<parent link="head_pan_link"></parent>
		<child link="head_tilt_link"></child>
		<axis xyz="0 1 0"></axis>
	</joint>
	<joint name="shoulder_pan_joint" type="revolute">
		<origin rpy="0 0 0" xyz="0.119525 0 0.34858"></origin>
		<parent link="torso_lift_link"></parent>
		<child link="shoulder_pan_link"></child>
		<axis xyz="0 0 1"></axis>
		<dynamics damping="1.0"></dynamics>
		<limit effort="33.82" lower="-1.6056" upper="1.6056" velocity="1.256"></limit>
	</joint>
	<joint name="shoulder_lift_joint" type="revolute">
		<origin rpy="0 0 0" xyz="0.117 0 0.0599999999999999"></origin>
		<parent link="shoulder_pan_link"></parent>
		<child link="shoulder_lift_link"></child>
		<axis xyz="0 1 0"></axis>
		<dynamics damping="1.0"></dynamics>
		<limit effort="131.76" lower="-1.221" upper="1.518" velocity="1.454"></limit>
	</joint>
	<joint name="upperarm_roll_joint" type="revolute">
		<origin rpy="0 0 0" xyz="0.219 0 0"></origin>
		<parent link="shoulder_lift_link"></parent>
		<child link="upperarm_roll_link"></child>
		<axis xyz="1 0 0"></axis>
		<dynamics damping="5.0"></dynamics>
		<limit effort="76.94" velocity="1.571" lower="-3.14159" upper="3.14159"></limit>
	</joint>
	<joint name="elbow_flex_joint" type="revolute">
		<origin rpy="0 0 0" xyz="0.133 0 0"></origin>
		<parent link="upperarm_roll_link"></parent>
		<child link="elbow_flex_link"></child>
		<axis xyz="0 1 0"></axis>
		<dynamics damping="1.0"></dynamics>
		<limit effort="66.18" lower="-2.251" upper="2.251" velocity="1.521"></limit>
	</joint>
	<joint name="forearm_roll_joint" type="revolute">
		<origin rpy="0 0 0" xyz="0.197 0 0"></origin>
		<parent link="elbow_flex_link"></parent>
		<child link="forearm_roll_link"></child>
		<axis xyz="1 0 0"></axis>
		<dynamics damping="5.0"></dynamics>
		<limit effort="29.35" velocity="1.571" lower="-3.14159" upper="3.14159"></limit>
	</joint>
	<joint name="wrist_flex_joint" type="revolute">
		<origin rpy="0 0 0" xyz="0.1245 0 0"></origin>
		<parent link="forearm_roll_link"></parent>
		<child link="wrist_flex_link"></child>
		<axis xyz="0 1 0"></axis>
		<dynamics damping="1.0"></dynamics>
		<limit effort="25.7" lower="-2.16" upper="2.16" velocity="2.268"></limit>
	</joint>
	<joint name="wrist_roll_joint" type="revolute">
		<origin rpy="0 0 0" xyz="0.1385 0 0"></origin>
		<parent link="wrist_flex_link"></parent>
		<child link="wrist_roll_link"></child>
		<axis xyz="1 0 0"></axis>
		<limit effort="7.36" velocity="2.268" lower="-3.14159" upper="3.14159"></limit>
		<dynamics damping="5.0"></dynamics>
	</joint>
	<joint name="gripper_axis" type="fixed">
		<origin rpy="0 0 0" xyz="0.16645 0 0"></origin>
		<parent link="wrist_roll_link"></parent>
		<child link="gripper_link"></child>
		<axis xyz="0 1 0"></axis>
	</joint>
	<joint name="r_gripper_finger_joint" type="fixed">
		<origin rpy="0 0 0" xyz="0 0.065425 0"></origin>
		<parent link="gripper_link"></parent>
		<child link="r_gripper_finger_link"></child>
		<axis xyz="0 1 0"></axis>
	</joint>
	<joint name="l_gripper_finger_joint" type="fixed">
		<origin rpy="0 0 0" xyz="0 -0.065425 0"></origin>
		<parent link="gripper_link"></parent>
		<child link="l_gripper_finger_link"></child>
		<axis xyz="0 -1 0"></axis>
	</joint>
	<joint name="torso_fixed_joint" type="fixed">
		<origin rpy="-6.12303176911189E-17 0 0" xyz="-0.086875 0 0.377425"></origin>
		<parent link="base_link"></parent>
		<child link="torso_fixed_link"></child>
		<axis xyz="0 1 0"></axis>
	</joint>
	<joint name="head_camera_joint" type="fixed">
		<origin rpy="0 0 0" xyz="0.055 0 0.0225"></origin>
		<parent link="head_tilt_link"></parent>
		<child link="head_camera_link"></child>
	</joint>
	<joint name="head_camera_rgb_joint" type="fixed">
		<origin rpy="0 0 0" xyz="0 0.02 0"></origin>
		<parent link="head_camera_link"></parent>
		<child link="head_camera_rgb_frame"></child>
	</joint>
	<joint name="head_camera_rgb_optical_joint" type="fixed">
		<origin rpy="-1.57079632679 0 -1.57079632679" xyz="0 0 0"></origin>
		<parent link="head_camera_rgb_frame"></parent>
		<child link="head_camera_rgb_optical_frame"></child>
	</joint>
	<joint name="head_camera_depth_joint" type="fixed">
		<origin rpy="0 0 0" xyz="0 0.045 0"></origin>
		<parent link="head_camera_link"></parent>
		<child link="head_camera_depth_frame"></child>
	</joint>
	<joint name="head_camera_depth_optical_joint" type="fixed">
		<origin rpy="-1.57079632679 0 -1.57079632679" xyz="0 0 0"></origin>
		<parent link="head_camera_depth_frame"></parent>
		<child link="head_camera_depth_optical_frame"></child>
	</joint>
</robot>