<?xml version="1.0" encoding="utf-8"?>
<robot name="panda" xmlns:xacro="http://www.ros.org/wiki/xacro" path="../assets/panda/panda.urdf">
	<link name="panda_link0">
		<inertial>
			<origin rpy="0 0 0" xyz="0 0 0.05"></origin>
			<mass value="2.9"></mass>
			<inertia ixx="0.1" ixy="0" ixz="0" iyy="0.1" iyz="0" izz="0.1"></inertia>
		</inertial>
		<visual>
			<geometry>
				<mesh filename="meshes/collision/link0.obj"></mesh>
			</geometry>
			<material name="panda_white">
				<color rgba="1. 1. 1. 1."></color>
			</material>
		</visual>
		<collision>
			<geometry>
				<sphere radius="0.118439"></sphere>
			</geometry>
			<origin xyz="-0.013295999999999995 -1.964999999999663e-05 0.06998025359999999" rpy="0 0 0"></origin>
		</collision>
		<collision>
			<geometry>
				<sphere radius="0.09403"></sphere>
			</geometry>
			<origin xyz="-0.08526999999999998 -9.64999999999663e-06 0.04343325359999999" rpy="0 0 0"></origin>
		</collision>
	</link>
	<link name="panda_link1">
		<inertial>
			<origin rpy="0 0 0" xyz="0 -0.04 -0.05"></origin>
			<mass value="2.7"></mass>
			<inertia ixx="0.1" ixy="0" ixz="0" iyy="0.1" iyz="0" izz="0.1"></inertia>
		</inertial>
		<visual>
			<geometry>
				<mesh filename="meshes/visual/link1.obj"></mesh>
			</geometry>
			<material name="panda_white"></material>
		</visual>
		<collision>
			<geometry>
				<sphere radius="0.090276"></sphere>
			</geometry>
			<origin xyz="7.309999999999968e-05 -0.011496349999999995 -0.13115545" rpy="0 0 0"></origin>
		</collision>
		<collision>
			<geometry>
				<sphere radius="0.089788"></sphere>
			</geometry>
			<origin xyz="6.099999999999674e-06 -0.04662034999999999 -0.019059450000000006" rpy="0 0 0"></origin>
		</collision>
	</link>
	<link name="panda_link2">
		<inertial>
			<origin rpy="0 0 0" xyz="0 -0.04 0.06"></origin>
			<mass value="2.73"></mass>
			<inertia ixx="0.1" ixy="0" ixz="0" iyy="0.1" iyz="0" izz="0.1"></inertia>
		</inertial>
		<visual>
			<geometry>
				<mesh filename="meshes/visual/link2.obj"></mesh>
			</geometry>
			<material name="panda_white"></material>
		</visual>
		<collision>
			<geometry>
				<sphere radius="0.079119"></sphere>
			</geometry>
			<origin xyz="-4.324999999999752e-05 -0.13904899999999998 0.0017281999999999922" rpy="0 0 0"></origin>
		</collision>
		<collision>
			<geometry>
				<sphere radius="0.079388"></sphere>
			</geometry>
			<origin xyz="-2.0249999999997524e-05 -0.067742 0.03258719999999999" rpy="0 0 0"></origin>
		</collision>
		<collision>
			<geometry>
				<sphere radius="0.079507"></sphere>
			</geometry>
			<origin xyz="2.175000000000248e-05 -0.004886999999999989 0.05060419999999999" rpy="0 0 0"></origin>
		</collision>
	</link>
	<link name="panda_link3">
		<inertial>
			<origin rpy="0 0 0" xyz="0.01 0.01 -0.05"></origin>
			<mass value="2.04"></mass>
			<inertia ixx="0.1" ixy="0" ixz="0" iyy="0.1" iyz="0" izz="0.1"></inertia>
		</inertial>
		<visual>
			<geometry>
				<mesh filename="meshes/visual/link3.obj"></mesh>
			</geometry>
			<material name="panda_red">
				<color rgba="1. 1. 1. 1."></color>
			</material>
		</visual>
		<collision>
			<geometry>
				<sphere radius="0.082938"></sphere>
			</geometry>
			<origin xyz="0.006546599999999993 0.0037228999999999977 -0.0668178" rpy="0 0 0"></origin>
		</collision>
		<collision>
			<geometry>
				<sphere radius="0.082975"></sphere>
			</geometry>
			<origin xyz="0.07212459999999998 0.0382329 -0.012539799999999997" rpy="0 0 0"></origin>
		</collision>
	</link>
	<link name="panda_link4">
		<inertial>
			<origin rpy="0 0 0" xyz="-0.03 0.03 0.02"></origin>
			<mass value="2.08"></mass>
			<inertia ixx="0.1" ixy="0" ixz="0" iyy="0.1" iyz="0" izz="0.1"></inertia>
		</inertial>
		<visual>
			<geometry>
				<mesh filename="meshes/visual/link4.obj"></mesh>
			</geometry>
			<material name="panda_white"></material>
		</visual>
		<collision>
			<geometry>
				<sphere radius="0.085236"></sphere>
			</geometry>
			<origin xyz="-0.013521750000000006 0.011411649999999992 0.036622699999999994" rpy="0 0 0"></origin>
		</collision>
		<collision>
			<geometry>
				<sphere radius="0.082745"></sphere>
			</geometry>
			<origin xyz="-0.07617575000000001 0.06957964999999999 0.0034766999999999992" rpy="0 0 0"></origin>
		</collision>
	</link>
	<link name="panda_link5">
		<inertial>
			<origin rpy="0 0 0" xyz="0 0.04 -0.12"></origin>
			<mass value="3"></mass>
			<inertia ixx="0.1" ixy="0" ixz="0" iyy="0.1" iyz="0" izz="0.1"></inertia>
		</inertial>
		<visual>
			<geometry>
				<mesh filename="meshes/visual/link5.obj"></mesh>
			</geometry>
			<material name="panda_white"></material>
		</visual>
		<collision>
			<geometry>
				<sphere radius="0.077746"></sphere>
			</geometry>
			<origin xyz="5.449999999997371e-06 0.003668049999999999 -0.20817785" rpy="0 0 0"></origin>
		</collision>
		<collision>
			<geometry>
				<sphere radius="0.078297"></sphere>
			</geometry>
			<origin xyz="3.644999999999737e-05 0.03168405 -0.14633485000000002" rpy="0 0 0"></origin>
		</collision>
		<collision>
			<geometry>
				<sphere radius="0.076108"></sphere>
			</geometry>
			<origin xyz="5.244999999999737e-05 0.05056805 -0.06929185" rpy="0 0 0"></origin>
		</collision>
		<collision>
			<geometry>
				<sphere radius="0.07267"></sphere>
			</geometry>
			<origin xyz="5.9449999999997366e-05 0.06092805 -0.0037818500000000033" rpy="0 0 0"></origin>
		</collision>
	</link>
	<link name="panda_link6">
		<inertial>
			<origin rpy="0 0 0" xyz="0.04 0 0"></origin>
			<mass value="1.3"></mass>
			<inertia ixx="0.1" ixy="0" ixz="0" iyy="0.1" iyz="0" izz="0.1"></inertia>
		</inertial>
		<visual>
			<geometry>
				<mesh filename="meshes/visual/link6.obj"></mesh>
			</geometry>
			<material name="panda_white"></material>
		</visual>
		<collision>
			<geometry>
				<sphere radius="0.083466"></sphere>
			</geometry>
			<origin xyz="0.08817188245061751 0.011466045654191473 0.0005011563488579703" rpy="0 0 0"></origin>
		</collision>
		<collision>
			<geometry>
				<sphere radius="0.076491"></sphere>
			</geometry>
			<origin xyz="0.011219882450617509 0.011244045654191473 0.019311156348857973" rpy="0 0 0"></origin>
		</collision>
	</link>
	<link name="panda_link7">
		<inertial>
			<origin rpy="0 0 0" xyz="0 0 0.08"></origin>
			<mass value=".2"></mass>
			<inertia ixx="0.1" ixy="0" ixz="0" iyy="0.1" iyz="0" izz="0.1"></inertia>
		</inertial>
		<visual>
			<geometry>
				<mesh filename="meshes/collision/link7.obj"></mesh>
			</geometry>
			<material name="panda_white"></material>
		</visual>
		<collision>
			<geometry>
				<sphere radius="0.049095"></sphere>
			</geometry>
			<origin xyz="0.03311775 0.03319985 0.08059375" rpy="0 0 0"></origin>
		</collision>
		<collision>
			<geometry>
				<sphere radius="0.053568"></sphere>
			</geometry>
			<origin xyz="-0.0005112499999999978 -0.001039149999999999 0.07940175000000001" rpy="0 0 0"></origin>
		</collision>
	</link>
	<link name="panda_link8">
		<inertial>
			<origin rpy="0 0 0" xyz="0 0 0"></origin>
			<mass value="0.0"></mass>
			<inertia ixx="0.1" ixy="0" ixz="0" iyy="0.1" iyz="0" izz="0.1"></inertia>
		</inertial>
	</link>
	<link name="panda_hand">
		<inertial>
			<origin rpy="0 0 0" xyz="0 0 0.04"></origin>
			<mass value=".81"></mass>
			<inertia ixx="0.1" ixy="0" ixz="0" iyy="0.1" iyz="0" izz="0.1"></inertia>
		</inertial>
		<visual>
			<geometry>
				<mesh filename="meshes/visual/hand.obj"></mesh>
			</geometry>
			<material name="panda_white"></material>
		</visual>
		<collision>
			<geometry>
				<sphere radius="0.044936"></sphere>
			</geometry>
			<origin xyz="8.894999999999896e-05 0.07400000000000001 0.0270927" rpy="0 0 0"></origin>
		</collision>
		<collision>
			<geometry>
				<sphere radius="0.048492"></sphere>
			</geometry>
			<origin xyz="3.9499999999989695e-06 0.032743 0.0256367" rpy="0 0 0"></origin>
		</collision>
		<collision>
			<geometry>
				<sphere radius="0.050176"></sphere>
			</geometry>
			<origin xyz="4.94999999999897e-06 -0.012592999999999998 0.0213827" rpy="0 0 0"></origin>
		</collision>
		<collision>
			<geometry>
				<sphere radius="0.041818"></sphere>
			</geometry>
			<origin xyz="6.694999999999897e-05 -0.06476000000000001 0.0410127" rpy="0 0 0"></origin>
		</collision>
		<collision>
			<geometry>
				<sphere radius="0.041564"></sphere>
			</geometry>
			<origin xyz="2.6949999999998968e-05 -0.065001 0.005509700000000001" rpy="0 0 0"></origin>
		</collision>
	</link>
	<link name="panda_leftfinger">
		<contact>
			<friction_anchor></friction_anchor>
			<stiffness value="30000.0"></stiffness>
			<damping value="1000.0"></damping>
			<spinning_friction value="0.1"></spinning_friction>
			<lateral_friction value="1.0"></lateral_friction>
		</contact>
		<inertial>
			<origin rpy="0 0 0" xyz="0 0.01 0.02"></origin>
			<mass value="0.1"></mass>
			<inertia ixx="0.1" ixy="0" ixz="0" iyy="0.1" iyz="0" izz="0.1"></inertia>
		</inertial>
		<visual>
			<geometry>
				<mesh filename="meshes/visual/finger.obj"></mesh>
			</geometry>
			<material name="panda_white"></material>
		</visual>
		<collision>
			<geometry>
				<sphere radius="0.018946"></sphere>
			</geometry>
			<origin xyz="-5.349999999999461e-06 0.0144523785 0.010577348" rpy="0 0 0"></origin>
		</collision>
		<collision>
			<geometry>
				<sphere radius="0.015906"></sphere>
			</geometry>
			<origin xyz="1.2650000000000538e-05 0.0116253785 0.026573348" rpy="0 0 0"></origin>
		</collision>
		<collision>
			<geometry>
				<sphere radius="0.015169"></sphere>
			</geometry>
			<origin xyz="-3.2349999999999465e-05 0.0088483785 0.042930348" rpy="0 0 0"></origin>
		</collision>
	</link>
	<link name="panda_rightfinger">
		<contact>
			<friction_anchor></friction_anchor>
			<stiffness value="30000.0"></stiffness>
			<damping value="1000.0"></damping>
			<spinning_friction value="0.1"></spinning_friction>
			<lateral_friction value="1.0"></lateral_friction>
		</contact>
		<inertial>
			<origin rpy="0 0 0" xyz="0 -0.01 0.02"></origin>
			<mass value="0.1"></mass>
			<inertia ixx="0.1" ixy="0" ixz="0" iyy="0.1" iyz="0" izz="0.1"></inertia>
		</inertial>
		<visual>
			<origin rpy="0 0 3.14159265359" xyz="0 0 0"></origin>
			<geometry>
				<mesh filename="meshes/visual/finger.obj"></mesh>
			</geometry>
			<material name="panda_white"></material>
		</visual>
		<collision>
			<geometry>
				<sphere radius="0.015671"></sphere>
			</geometry>
			<origin xyz="0.0002036500000005114 0.01732337849999803 0.042391348" rpy="0 0 0"></origin>
		</collision>
		<collision>
			<geometry>
				<sphere radius="0.018946"></sphere>
			</geometry>
			<origin xyz="2.0650000000511412e-05 0.01181837849999803 0.010577348" rpy="0 0 0"></origin>
		</collision>
		<collision>
			<geometry>
				<sphere radius="0.015661"></sphere>
			</geometry>
			<origin xyz="2.650000000511414e-06 0.014348378499998031 0.025998348" rpy="0 0 0"></origin>
		</collision>
	</link>
	<link name="panda_grasptarget">
		<inertial>
			<origin rpy="0 0 0" xyz="0 0 0"></origin>
			<mass value="0.0"></mass>
			<inertia ixx="0.1" ixy="0" ixz="0" iyy="0.1" iyz="0" izz="0.1"></inertia>
		</inertial>
	</link>
	<joint name="panda_joint1" type="revolute">
		<safety_controller k_position="100.0" k_velocity="40.0" soft_lower_limit="-2.8973" soft_upper_limit="2.8973"></safety_controller>
		<origin rpy="0 0 0" xyz="0 0 0.333"></origin>
		<parent link="panda_link0"></parent>
		<child link="panda_link1"></child>
		<axis xyz="0 0 1"></axis>
		<limit effort="87" lower="-2.9671" upper="2.9671" velocity="2.3925"></limit>
	</joint>
	<joint name="panda_joint2" type="revolute">
		<safety_controller k_position="100.0" k_velocity="40.0" soft_lower_limit="-1.7628" soft_upper_limit="1.7628"></safety_controller>
		<origin rpy="-1.57079632679 0 0" xyz="0 0 0"></origin>
		<parent link="panda_link1"></parent>
		<child link="panda_link2"></child>
		<axis xyz="0 0 1"></axis>
		<limit effort="87" lower="-1.8326" upper="1.8326" velocity="2.3925"></limit>
	</joint>
	<joint name="panda_joint3" type="revolute">
		<safety_controller k_position="100.0" k_velocity="40.0" soft_lower_limit="-2.8973" soft_upper_limit="2.8973"></safety_controller>
		<origin rpy="1.57079632679 0 0" xyz="0 -0.316 0"></origin>
		<parent link="panda_link2"></parent>
		<child link="panda_link3"></child>
		<axis xyz="0 0 1"></axis>
		<limit effort="87" lower="-2.9671" upper="2.9671" velocity="2.3925"></limit>
	</joint>
	<joint name="panda_joint4" type="revolute">
		<safety_controller k_position="100.0" k_velocity="40.0" soft_lower_limit="-3.0718" soft_upper_limit="-0.0698"></safety_controller>
		<origin rpy="1.57079632679 0 0" xyz="0.0825 0 0"></origin>
		<parent link="panda_link3"></parent>
		<child link="panda_link4"></child>
		<axis xyz="0 0 1"></axis>
		<limit effort="87" lower="-3.1416" upper="0.0873" velocity="2.3925"></limit>
	</joint>
	<joint name="panda_joint5" type="revolute">
		<safety_controller k_position="100.0" k_velocity="40.0" soft_lower_limit="-2.8973" soft_upper_limit="2.8973"></safety_controller>
		<origin rpy="-1.57079632679 0 0" xyz="-0.0825 0.384 0"></origin>
		<parent link="panda_link4"></parent>
		<child link="panda_link5"></child>
		<axis xyz="0 0 1"></axis>
		<limit effort="12" lower="-2.9671" upper="2.9671" velocity="2.8710"></limit>
	</joint>
	<joint name="panda_joint6" type="revolute">
		<safety_controller k_position="100.0" k_velocity="40.0" soft_lower_limit="-0.0175" soft_upper_limit="3.7525"></safety_controller>
		<origin rpy="1.57079632679 0 0" xyz="0 0 0"></origin>
		<parent link="panda_link5"></parent>
		<child link="panda_link6"></child>
		<axis xyz="0 0 1"></axis>
		<limit effort="12" lower="-0.0873" upper="3.8223" velocity="2.8710"></limit>
	</joint>
	<joint name="panda_joint7" type="revolute">
		<safety_controller k_position="100.0" k_velocity="40.0" soft_lower_limit="-2.8973" soft_upper_limit="2.8973"></safety_controller>
		<origin rpy="1.57079632679 0 0" xyz="0.088 0 0"></origin>
		<parent link="panda_link6"></parent>
		<child link="panda_link7"></child>
		<axis xyz="0 0 1"></axis>
		<limit effort="12" lower="-2.9671" upper="2.9671" velocity="2.8710"></limit>
	</joint>
	<joint name="panda_joint8" type="fixed">
		<origin rpy="0 0 0" xyz="0 0 0.107"></origin>
		<parent link="panda_link7"></parent>
		<child link="panda_link8"></child>
		<axis xyz="0 0 0"></axis>
	</joint>
	<joint name="panda_hand_joint" type="fixed">
		<parent link="panda_link8"></parent>
		<child link="panda_hand"></child>
		<origin rpy="0 0 -0.785398163397" xyz="0 0 0"></origin>
	</joint>
	<joint name="panda_finger_joint1" type="fixed">
		<parent link="panda_hand"></parent>
		<child link="panda_leftfinger"></child>
		<origin rpy="0 0 0" xyz="0 0.065 0.0584"></origin>
		<axis xyz="0 1 0"></axis>
	</joint>
	<joint name="panda_finger_joint2" type="fixed">
		<parent link="panda_hand"></parent>
		<child link="panda_rightfinger"></child>
		<origin rpy="0 0 0" xyz="0 -0.065 0.0584"></origin>
		<axis xyz="0 -1 0"></axis>
		<mimic joint="panda_finger_joint1"></mimic>
	</joint>
	<joint name="panda_grasptarget_hand" type="fixed">
		<parent link="panda_hand"></parent>
		<child link="panda_grasptarget"></child>
		<origin rpy="0 0 0" xyz="0 0 0.105"></origin>
	</joint>
</robot>