<?xml version="1.0" encoding="utf-8"?>
<robot name="baxter" path="assets/baxter/baxter.urdf">
	<link name="base"></link>
	<link name="torso">
		<visual>
			<origin rpy="0 0 0" xyz="0 0 0"></origin>
			<geometry>
				<mesh filename="meshes/torso/base_link.DAE"></mesh>
			</geometry>
			<material name="darkgray">
				<color rgba=".2 .2 .2 1"></color>
			</material>
		</visual>
		<collision>
			<geometry>
				<sphere radius="0.523785"></sphere>
			</geometry>
			<origin xyz="-0.07619605119409564 0.004945226718584841 0.40337838116045854" rpy="0 0 0"></origin>
		</collision>
		<inertial>
			<origin rpy="0 0 0" xyz="0.000000 0.000000 0.000000"></origin>
			<mass value="35.336455"></mass>
			<inertia ixx="1.849155" ixy="-0.000354" ixz="-0.154188" iyy="1.662671" iyz="0.003292" izz="0.802239"></inertia>
		</inertial>
	</link>
	<link name="left_torso_itb">
		<inertial>
			<origin rpy="0 0 0" xyz="0.000000 0.000000 0.000000"></origin>
			<mass value="0.0001"></mass>
			<inertia ixx="1e-08" ixy="0" ixz="0" iyy="1e-08" iyz="0" izz="1e-08"></inertia>
		</inertial>
	</link>
	<link name="right_torso_itb">
		<inertial>
			<origin rpy="0 0 0" xyz="0.000000 0.000000 0.000000"></origin>
			<mass value="0.0001"></mass>
			<inertia ixx="1e-08" ixy="0" ixz="0" iyy="1e-08" iyz="0" izz="1e-08"></inertia>
		</inertial>
	</link>
	<link name="head">
		<visual>
			<origin rpy="0 0 0" xyz="0 0 .00953"></origin>
			<geometry>
				<mesh filename="meshes/head/H0.DAE"></mesh>
			</geometry>
			<material name="darkgray">
				<color rgba=".2 .2 .2 1"></color>
			</material>
		</visual>
		<collision>
			<origin rpy="0 0 0" xyz="0.0 0 0.0"></origin>
			<geometry>
				<sphere radius="0.001"></sphere>
			</geometry>
		</collision>
		<inertial>
			<origin rpy="0 0 0" xyz="0 0 0"></origin>
			<mass value="0.547767"></mass>
			<inertia ixx="0.004641" ixy="0.000159" ixz="0.000242" iyy="0.003295" iyz="-0.001324" izz="0.003415"></inertia>
		</inertial>
	</link>
	<link name="sonar_ring">
		<visual>
			<origin rpy="0 0 0" xyz="-.0347 0 .00953"></origin>
			<geometry>
				<cylinder length="0.01" radius="0.085"></cylinder>
			</geometry>
			<material name="darkgray">
				<color rgba=".2 .2 .2 1"></color>
			</material>
		</visual>
		<collision>
			<origin rpy="0 0 0" xyz="0.0 0 0.0"></origin>
			<geometry>
				<sphere radius="0.001"></sphere>
			</geometry>
		</collision>
		<inertial>
			<origin rpy="0 0 0" xyz="0 0 0"></origin>
			<mass value="0.0001"></mass>
			<inertia ixx="1e-08" ixy="0" ixz="0" iyy="1e-08" iyz="0" izz="1e-08"></inertia>
		</inertial>
	</link>
	<link name="screen">
		<visual>
			<origin rpy="0 -1.57079632679 0" xyz="0 -.00953 -.0347"></origin>
			<geometry>
				<mesh filename="meshes/head/H1.DAE"></mesh>
			</geometry>
			<material name="darkred">
				<color rgba=".5 .1 .1 1"></color>
			</material>
		</visual>
		<collision>
			<origin rpy="0 0 0" xyz="0.0 0 0.0"></origin>
			<geometry>
				<sphere radius="0.001"></sphere>
			</geometry>
		</collision>
		<inertial>
			<origin rpy="0 0 0" xyz="0 0 0"></origin>
			<mass value="0.440171"></mass>
			<inertia ixx="0.004006" ixy="0.000230" ixz="0.000002" iyy="0.002800" iyz="0.000029" izz="0.001509"></inertia>
		</inertial>
	</link>
	<link name="display">
		<visual>
			<origin rpy="0.2617993877991494 0 0" xyz="0 0 0"></origin>
			<geometry>
				<box size="0.218 0.16 0.001"></box>
			</geometry>
			<material name="black">
				<color rgba="0 0 0 1"></color>
			</material>
		</visual>
		<inertial>
			<origin rpy="0 0 0" xyz="0 0 0"></origin>
			<mass value="0.0001"></mass>
			<inertia ixx="1e-08" ixy="0" ixz="0" iyy="1e-08" iyz="0" izz="1e-08"></inertia>
		</inertial>
	</link>
	<link name="head_camera">
		<inertial>
			<origin rpy="0 0 0" xyz="0 0 0"></origin>
			<mass value="0.0001"></mass>
			<inertia ixx="1e-08" ixy="0" ixz="0" iyy="1e-08" iyz="0" izz="1e-08"></inertia>
		</inertial>
	</link>
	<link name="dummyhead1">
		<inertial>
			<origin rpy="0 0 0" xyz="0 0 0"></origin>
			<mass value="0.0001"></mass>
			<inertia ixx="1e-08" ixy="0" ixz="0" iyy="1e-08" iyz="0" izz="1e-08"></inertia>
		</inertial>
	</link>
	<link name="collision_head_link_1">
		<visual>
			<origin rpy="0 0 0" xyz="0 0 0"></origin>
			<geometry>
				<sphere radius="0.001"></sphere>
			</geometry>
			<material name="red">
				<color rgba="0.8 0.3 0.3 0.3"></color>
			</material>
		</visual>
		<collision>
			<origin rpy="0 0 0.0" xyz="-0.07 -0.04 0.0"></origin>
			<geometry>
				<sphere radius="0.22"></sphere>
			</geometry>
		</collision>
		<inertial>
			<origin rpy="0 0 0" xyz="0 0 0"></origin>
			<mass value="0.0001"></mass>
			<inertia ixx="1e-08" ixy="0" ixz="0" iyy="1e-08" iyz="0" izz="1e-08"></inertia>
		</inertial>
	</link>
	<link name="collision_head_link_2">
		<visual>
			<origin rpy="0 0 0" xyz="0 0 0"></origin>
			<geometry>
				<sphere radius="0.001"></sphere>
			</geometry>
			<material name="red">
				<color rgba="0.8 0.3 0.3 0.3"></color>
			</material>
		</visual>
		<collision>
			<origin rpy="0 0 0" xyz="-0.07 0.04 0.00"></origin>
			<geometry>
				<sphere radius="0.22"></sphere>
			</geometry>
		</collision>
		<inertial>
			<origin rpy="0 0 0" xyz="0 0 0"></origin>
			<mass value="0.0001"></mass>
			<inertia ixx="1e-08" ixy="0" ixz="0" iyy="1e-08" iyz="0" izz="1e-08"></inertia>
		</inertial>
	</link>
	<link name="right_arm_mount">
		<inertial>
			<origin rpy="0 0 0" xyz="0 0 0"></origin>
			<mass value="0.0001"></mass>
			<inertia ixx="1e-08" ixy="0" ixz="0" iyy="1e-08" iyz="0" izz="1e-08"></inertia>
		</inertial>
	</link>
	<link name="right_upper_shoulder">
		<visual>
			<origin rpy="0 0 0" xyz="0 0 0"></origin>
			<geometry>
				<mesh filename="meshes/upper_shoulder/S0.DAE"></mesh>
			</geometry>
			<material name="darkred">
				<color rgba=".5 .1 .1 1"></color>
			</material>
		</visual>
		<collision>
			<geometry>
				<sphere radius="0.148744"></sphere>
			</geometry>
			<origin xyz="-5e-06 -2e-06 0.136103" rpy="0 0 0"></origin>
		</collision>
		<inertial>
			<origin rpy="0 0 0" xyz="0.01783 0.00086 0.19127"></origin>
			<mass value="5.70044"></mass>
			<inertia ixx="0.04709102262" ixy="0.00012787556" ixz="0.00614870039" iyy="0.03766976455" iyz="0.00078086899" izz="0.03595988478"></inertia>
		</inertial>
	</link>
	<link name="right_lower_shoulder">
		<visual>
			<origin rpy="0 0 0" xyz="0 0 0"></origin>
			<geometry>
				<mesh filename="meshes/lower_shoulder/S1.DAE"></mesh>
			</geometry>
			<material name="darkred">
				<color rgba=".5 .1 .1 1"></color>
			</material>
		</visual>
		<collision>
			<geometry>
				<sphere radius="0.084853"></sphere>
			</geometry>
			<origin xyz="0.0 0.0 0.0" rpy="0 0 0"></origin>
		</collision>
		<inertial>
			<origin rpy="0 0 0" xyz="0.06845 0.00269 -0.00529"></origin>
			<mass value="3.22698"></mass>
			<inertia ixx="0.01175209419" ixy="-0.00030096398" ixz="0.00207675762" iyy="0.0278859752" iyz="-0.00018821993" izz="0.02078749298"></inertia>
		</inertial>
	</link>
	<link name="right_upper_elbow">
		<visual>
			<origin rpy="0 0 0" xyz="0 0 0"></origin>
			<geometry>
				<mesh filename="meshes/upper_elbow/E0.DAE"></mesh>
			</geometry>
			<material name="darkred">
				<color rgba=".5 .1 .1 1"></color>
			</material>
		</visual>
		<collision>
			<geometry>
				<sphere radius="0.080388"></sphere>
			</geometry>
			<origin xyz="0.0 0.0 -0.0535" rpy="0 0 0"></origin>
		</collision>
		<inertial>
			<origin rpy="0 0 0" xyz="-0.00276 0.00132 0.18086"></origin>
			<mass value="4.31272"></mass>
			<inertia ixx="0.02661733557" ixy="0.00029270634" ixz="0.00392189887" iyy="0.02844355207" iyz="0.0010838933" izz="0.01248008322"></inertia>
		</inertial>
	</link>
	<link name="right_upper_elbow_visual">
		<collision>
			<geometry>
				<sphere radius="0.149111"></sphere>
			</geometry>
			<origin xyz="1e-06 3e-06 0.136495" rpy="0 0 0"></origin>
		</collision>
		<inertial>
			<origin rpy="0 0 0" xyz="0 0 0"></origin>
			<mass value="0.0001"></mass>
			<inertia ixx="1e-08" ixy="0" ixz="0" iyy="1e-08" iyz="0" izz="1e-08"></inertia>
		</inertial>
	</link>
	<link name="right_lower_elbow">
		<visual>
			<origin rpy="0 0 0" xyz="0 0 0"></origin>
			<geometry>
				<mesh filename="meshes/lower_elbow/E1.DAE"></mesh>
			</geometry>
			<material name="darkred">
				<color rgba=".5 .1 .1 1"></color>
			</material>
		</visual>
		<collision>
			<geometry>
				<sphere radius="0.078103"></sphere>
			</geometry>
			<origin xyz="0.0 0.0 0.0" rpy="0 0 0"></origin>
		</collision>
		<inertial>
			<origin rpy="0 0 0" xyz="0.02611 0.00159 -0.01117"></origin>
			<mass value="2.07206"></mass>
			<inertia ixx="0.00711582686" ixy="0.00036036173" ixz="0.0007459496" iyy="0.01318227876" iyz="-0.00019663418" izz="0.00926852064"></inertia>
		</inertial>
	</link>
	<link name="right_upper_forearm">
		<visual>
			<origin rpy="0 0 0" xyz="0 0 0"></origin>
			<geometry>
				<mesh filename="meshes/upper_forearm/W0.DAE"></mesh>
			</geometry>
			<material name="darkred">
				<color rgba=".5 .1 .1 1"></color>
			</material>
		</visual>
		<collision>
			<geometry>
				<sphere radius="0.074405"></sphere>
			</geometry>
			<origin xyz="0.0 0.0 -0.043998999999999996" rpy="0 0 0"></origin>
		</collision>
		<inertial>
			<origin rpy="0 0 0" xyz="-0.00168 0.0046 0.13952"></origin>
			<mass value="2.24665"></mass>
			<inertia ixx="0.01667742825" ixy="0.00018403705" ixz="0.00018657629" iyy="0.01675457264" iyz="-0.00064732352" izz="0.0037463115"></inertia>
		</inertial>
	</link>
	<link name="right_upper_forearm_visual">
		<collision>
			<geometry>
				<sphere radius="0.148651"></sphere>
			</geometry>
			<origin xyz="-2e-06 -5e-06 0.135998" rpy="0 0 0"></origin>
		</collision>
		<inertial>
			<origin rpy="0 0 0" xyz="0 0 0"></origin>
			<mass value="0.0001"></mass>
			<inertia ixx="1e-08" ixy="0" ixz="0" iyy="1e-08" iyz="0" izz="1e-08"></inertia>
		</inertial>
	</link>
	<link name="right_arm_itb">
		<inertial>
			<origin rpy="0 0 0" xyz="0.000000 0.000000 0.000000"></origin>
			<mass value="0.0001"></mass>
			<inertia ixx="1e-08" ixy="0" ixz="0" iyy="1e-08" iyz="0" izz="1e-08"></inertia>
		</inertial>
	</link>
	<link name="right_lower_forearm">
		<visual>
			<origin rpy="0 0 0" xyz="0 0 0"></origin>
			<geometry>
				<mesh filename="meshes/lower_forearm/W1.DAE"></mesh>
			</geometry>
			<material name="darkred">
				<color rgba=".5 .1 .1 1"></color>
			</material>
		</visual>
		<collision>
			<geometry>
				<sphere radius="0.078103"></sphere>
			</geometry>
			<origin xyz="0.0 0.0 0.0" rpy="0 0 0"></origin>
		</collision>
		<inertial>
			<origin rpy="0 0 0" xyz="0.06041 0.00697 0.006"></origin>
			<mass value="1.60979"></mass>
			<inertia ixx="0.00387607152" ixy="-0.00044384784" ixz="-0.00021115038" iyy="0.00700537914" iyz="0.00015348067" izz="0.0055275524"></inertia>
		</inertial>
	</link>
	<link name="right_wrist">
		<visual>
			<origin rpy="0 0 0" xyz="0 0 0"></origin>
			<geometry>
				<mesh filename="meshes/wrist/W2.DAE"></mesh>
			</geometry>
			<material name="lightgrey">
				<color rgba=".1 .1 .1 1"></color>
			</material>
		</visual>
		<collision>
			<geometry>
				<sphere radius="0.102015"></sphere>
			</geometry>
			<origin xyz="-3e-06 -5e-06 1e-06" rpy="0 0 0"></origin>
		</collision>
		<inertial>
			<origin rpy="0 0 0" xyz="0.00198 0.00125 0.01855"></origin>
			<mass value="0.35093"></mass>
			<inertia ixx="0.00025289155" ixy="0.00000575311" ixz="-0.00000159345" iyy="0.0002688601" iyz="-0.00000519818" izz="0.0003074118"></inertia>
		</inertial>
	</link>
	<link name="right_hand">
		<collision>
			<geometry>
				<sphere radius="0.046243"></sphere>
			</geometry>
			<origin xyz="-2e-06 1e-06 -0.0232" rpy="0 0 0"></origin>
		</collision>
		<inertial>
			<origin rpy="0 0 0" xyz="0.01093 0.00042 -0.01532"></origin>
			<mass value="0.19125"></mass>
			<inertia ixx="0.00017588" ixy="0.00000147073" ixz="0.0000243633" iyy="0.00021166377" iyz="0.00000172689" izz="0.00023745397"></inertia>
		</inertial>
	</link>
	<link name="right_hand_camera">
		<visual>
			<origin rpy="0 0 0" xyz="0 0 0"></origin>
			<geometry>
				<cylinder length="0.01" radius="0.02"></cylinder>
			</geometry>
			<material name="blue">
				<color rgba="0 0 1 0.8"></color>
			</material>
		</visual>
		<inertial>
			<origin rpy="0 0 0" xyz="0 0 0"></origin>
			<mass value="0.0001"></mass>
			<inertia ixx="1e-08" ixy="0" ixz="0" iyy="1e-08" iyz="0" izz="1e-08"></inertia>
		</inertial>
	</link>
	<link name="right_hand_camera_axis">
		<inertial>
			<origin rpy="0 0 0" xyz="0 0 0"></origin>
			<mass value="0.0001"></mass>
			<inertia ixx="1e-08" ixy="0" ixz="0" iyy="1e-08" iyz="0" izz="1e-08"></inertia>
		</inertial>
	</link>
	<link name="right_hand_range">
		<visual>
			<origin rpy="0 0 0" xyz="0 0 0"></origin>
			<geometry>
				<box size="0.005 .02 .005"></box>
			</geometry>
			<material name="blue">
				<color rgba="0 0 1 0.8"></color>
			</material>
		</visual>
		<inertial>
			<origin rpy="0 0 0" xyz="0 0 0"></origin>
			<mass value="0.0001"></mass>
			<inertia ixx="1e-08" ixy="0" ixz="0" iyy="1e-08" iyz="0" izz="1e-08"></inertia>
		</inertial>
	</link>
	<link name="right_hand_accelerometer">
		<visual>
			<origin rpy="0 0 0" xyz="0 0 0"></origin>
			<geometry>
				<box size="0.01 0.01 0.01"></box>
			</geometry>
			<material name="black">
				<color rgba="0 0 0 1"></color>
			</material>
		</visual>
		<inertial>
			<origin rpy="0 0 0" xyz="0.000000 0.000000 0.000000"></origin>
			<mass value="0.0001"></mass>
			<inertia ixx="1e-08" ixy="0" ixz="0" iyy="1e-08" iyz="0" izz="1e-08"></inertia>
		</inertial>
	</link>
	<link name="left_arm_mount">
		<inertial>
			<origin rpy="0 0 0" xyz="0 0 0"></origin>
			<mass value="0.0001"></mass>
			<inertia ixx="1e-08" ixy="0" ixz="0" iyy="1e-08" iyz="0" izz="1e-08"></inertia>
		</inertial>
	</link>
	<link name="left_upper_shoulder">
		<visual>
			<origin rpy="0 0 0" xyz="0 0 0"></origin>
			<geometry>
				<mesh filename="meshes/upper_shoulder/S0.DAE"></mesh>
			</geometry>
			<material name="darkred">
				<color rgba=".5 .1 .1 1"></color>
			</material>
		</visual>
		<collision>
			<geometry>
				<sphere radius="0.148744"></sphere>
			</geometry>
			<origin xyz="-5e-06 -2e-06 0.136103" rpy="0 0 0"></origin>
		</collision>
		<inertial>
			<origin rpy="0 0 0" xyz="0.01783 0.00086 0.19127"></origin>
			<mass value="5.70044"></mass>
			<inertia ixx="0.04709102262" ixy="0.00012787556" ixz="0.00614870039" iyy="0.03766976455" iyz="0.00078086899" izz="0.03595988478"></inertia>
		</inertial>
	</link>
	<link name="left_lower_shoulder">
		<visual>
			<origin rpy="0 0 0" xyz="0 0 0"></origin>
			<geometry>
				<mesh filename="meshes/lower_shoulder/S1.DAE"></mesh>
			</geometry>
			<material name="darkred">
				<color rgba=".5 .1 .1 1"></color>
			</material>
		</visual>
		<collision>
			<geometry>
				<sphere radius="0.084853"></sphere>
			</geometry>
			<origin xyz="0.0 0.0 0.0" rpy="0 0 0"></origin>
		</collision>
		<inertial>
			<origin rpy="0 0 0" xyz="0.06845 0.00269 -0.00529"></origin>
			<mass value="3.22698"></mass>
			<inertia ixx="0.01175209419" ixy="-0.00030096398" ixz="0.00207675762" iyy="0.0278859752" iyz="-0.00018821993" izz="0.02078749298"></inertia>
		</inertial>
	</link>
	<link name="left_upper_elbow">
		<visual>
			<origin rpy="0 0 0" xyz="0 0 0"></origin>
			<geometry>
				<mesh filename="meshes/upper_elbow/E0.DAE"></mesh>
			</geometry>
			<material name="darkred">
				<color rgba=".5 .1 .1 1"></color>
			</material>
		</visual>
		<collision>
			<geometry>
				<sphere radius="0.080388"></sphere>
			</geometry>
			<origin xyz="0.0 0.0 -0.0535" rpy="0 0 0"></origin>
		</collision>
		<inertial>
			<origin rpy="0 0 0" xyz="-0.00276 0.00132 0.18086"></origin>
			<mass value="4.31272"></mass>
			<inertia ixx="0.02661733557" ixy="0.00029270634" ixz="0.00392189887" iyy="0.02844355207" iyz="0.0010838933" izz="0.01248008322"></inertia>
		</inertial>
	</link>
	<link name="left_upper_elbow_visual">
		<collision>
			<geometry>
				<sphere radius="0.149111"></sphere>
			</geometry>
			<origin xyz="1e-06 3e-06 0.136495" rpy="0 0 0"></origin>
		</collision>
		<inertial>
			<origin rpy="0 0 0" xyz="0 0 0"></origin>
			<mass value="0.0001"></mass>
			<inertia ixx="1e-08" ixy="0" ixz="0" iyy="1e-08" iyz="0" izz="1e-08"></inertia>
		</inertial>
	</link>
	<link name="left_lower_elbow">
		<visual>
			<origin rpy="0 0 0" xyz="0 0 0"></origin>
			<geometry>
				<mesh filename="meshes/lower_elbow/E1.DAE"></mesh>
			</geometry>
			<material name="darkred">
				<color rgba=".5 .1 .1 1"></color>
			</material>
		</visual>
		<collision>
			<geometry>
				<sphere radius="0.078103"></sphere>
			</geometry>
			<origin xyz="0.0 0.0 0.0" rpy="0 0 0"></origin>
		</collision>
		<inertial>
			<origin rpy="0 0 0" xyz="0.02611 0.00159 -0.01117"></origin>
			<mass value="2.07206"></mass>
			<inertia ixx="0.00711582686" ixy="0.00036036173" ixz="0.0007459496" iyy="0.01318227876" iyz="-0.00019663418" izz="0.00926852064"></inertia>
		</inertial>
	</link>
	<link name="left_upper_forearm">
		<visual>
			<origin rpy="0 0 0" xyz="0 0 0"></origin>
			<geometry>
				<mesh filename="meshes/upper_forearm/W0.DAE"></mesh>
			</geometry>
			<material name="darkred">
				<color rgba=".5 .1 .1 1"></color>
			</material>
		</visual>
		<collision>
			<geometry>
				<sphere radius="0.074405"></sphere>
			</geometry>
			<origin xyz="0.0 0.0 -0.043998999999999996" rpy="0 0 0"></origin>
		</collision>
		<inertial>
			<origin rpy="0 0 0" xyz="-0.00168 0.0046 0.13952"></origin>
			<mass value="2.24665"></mass>
			<inertia ixx="0.01667742825" ixy="0.00018403705" ixz="0.00018657629" iyy="0.01675457264" iyz="-0.00064732352" izz="0.0037463115"></inertia>
		</inertial>
	</link>
	<link name="left_upper_forearm_visual">
		<collision>
			<geometry>
				<sphere radius="0.148651"></sphere>
			</geometry>
			<origin xyz="-2e-06 -5e-06 0.135998" rpy="0 0 0"></origin>
		</collision>
		<inertial>
			<origin rpy="0 0 0" xyz="0 0 0"></origin>
			<mass value="0.0001"></mass>
			<inertia ixx="1e-08" ixy="0" ixz="0" iyy="1e-08" iyz="0" izz="1e-08"></inertia>
		</inertial>
	</link>
	<link name="left_arm_itb">
		<inertial>
			<origin rpy="0 0 0" xyz="0.000000 0.000000 0.000000"></origin>
			<mass value="0.0001"></mass>
			<inertia ixx="1e-08" ixy="0" ixz="0" iyy="1e-08" iyz="0" izz="1e-08"></inertia>
		</inertial>
	</link>
	<link name="left_lower_forearm">
		<visual>
			<origin rpy="0 0 0" xyz="0 0 0"></origin>
			<geometry>
				<mesh filename="meshes/lower_forearm/W1.DAE"></mesh>
			</geometry>
			<material name="darkred">
				<color rgba=".5 .1 .1 1"></color>
			</material>
		</visual>
		<collision>
			<geometry>
				<sphere radius="0.078103"></sphere>
			</geometry>
			<origin xyz="0.0 0.0 0.0" rpy="0 0 0"></origin>
		</collision>
		<inertial>
			<origin rpy="0 0 0" xyz="0.06041 0.00697 0.006"></origin>
			<mass value="1.60979"></mass>
			<inertia ixx="0.00387607152" ixy="-0.00044384784" ixz="-0.00021115038" iyy="0.00700537914" iyz="0.00015348067" izz="0.0055275524"></inertia>
		</inertial>
	</link>
	<link name="left_wrist">
		<visual>
			<origin rpy="0 0 0" xyz="0 0 0"></origin>
			<geometry>
				<mesh filename="meshes/wrist/W2.DAE"></mesh>
			</geometry>
			<material name="lightgrey">
				<color rgba=".1 .1 .1 1"></color>
			</material>
		</visual>
		<collision>
			<geometry>
				<sphere radius="0.102015"></sphere>
			</geometry>
			<origin xyz="-3e-06 -5e-06 1e-06" rpy="0 0 0"></origin>
		</collision>
		<inertial>
			<origin rpy="0 0 0" xyz="0.00198 0.00125 0.01855"></origin>
			<mass value="0.35093"></mass>
			<inertia ixx="0.00025289155" ixy="0.00000575311" ixz="-0.00000159345" iyy="0.0002688601" iyz="-0.00000519818" izz="0.0003074118"></inertia>
		</inertial>
	</link>
	<link name="left_hand">
		<collision>
			<geometry>
				<sphere radius="0.046243"></sphere>
			</geometry>
			<origin xyz="-2e-06 1e-06 -0.0232" rpy="0 0 0"></origin>
		</collision>
		<inertial>
			<origin rpy="0 0 0" xyz="0.01093 0.00042 -0.01532"></origin>
			<mass value="0.19125"></mass>
			<inertia ixx="0.00017588" ixy="0.00000147073" ixz="0.0000243633" iyy="0.00021166377" iyz="0.00000172689" izz="0.00023745397"></inertia>
		</inertial>
	</link>
	<link name="left_hand_camera">
		<visual>
			<origin rpy="0 0 0" xyz="0 0 0"></origin>
			<geometry>
				<cylinder length="0.01" radius="0.02"></cylinder>
			</geometry>
			<material name="blue">
				<color rgba="0 0 1 0.8"></color>
			</material>
		</visual>
		<inertial>
			<origin rpy="0 0 0" xyz="0 0 0"></origin>
			<mass value="0.0001"></mass>
			<inertia ixx="1e-08" ixy="0" ixz="0" iyy="1e-08" iyz="0" izz="1e-08"></inertia>
		</inertial>
	</link>
	<link name="left_hand_camera_axis">
		<inertial>
			<origin rpy="0 0 0" xyz="0 0 0"></origin>
			<mass value="0.0001"></mass>
			<inertia ixx="1e-08" ixy="0" ixz="0" iyy="1e-08" iyz="0" izz="1e-08"></inertia>
		</inertial>
	</link>
	<link name="left_hand_range">
		<visual>
			<origin rpy="0 0 0" xyz="0 0 0"></origin>
			<geometry>
				<box size="0.005 .02 .005"></box>
			</geometry>
			<material name="blue">
				<color rgba="0 0 1 0.8"></color>
			</material>
		</visual>
		<inertial>
			<origin rpy="0 0 0" xyz="0 0 0"></origin>
			<mass value="0.0001"></mass>
			<inertia ixx="1e-08" ixy="0" ixz="0" iyy="1e-08" iyz="0" izz="1e-08"></inertia>
		</inertial>
	</link>
	<link name="left_hand_accelerometer">
		<visual>
			<origin rpy="0 0 0" xyz="0 0 0"></origin>
			<geometry>
				<box size="0.01 0.01 0.01"></box>
			</geometry>
			<material name="black">
				<color rgba="0 0 0 1"></color>
			</material>
		</visual>
		<inertial>
			<origin rpy="0 0 0" xyz="0.000000 0.000000 0.000000"></origin>
			<mass value="0.0001"></mass>
			<inertia ixx="1e-08" ixy="0" ixz="0" iyy="1e-08" iyz="0" izz="1e-08"></inertia>
		</inertial>
	</link>
	<link name="pedestal">
		<visual>
			<origin rpy="0 0 0" xyz="0 0 0"></origin>
			<geometry>
				<mesh filename="meshes/base/PEDESTAL.DAE"></mesh>
			</geometry>
			<material name="darkgray">
				<color rgba=".2 .2 .2 1"></color>
			</material>
		</visual>
		<collision>
			<geometry>
				<sphere radius="0.714337"></sphere>
			</geometry>
			<origin xyz="-0.03737104364291968 0.0032565654099008324 -0.5335471291821219" rpy="0 0 0"></origin>
		</collision>
		<inertial>
			<origin rpy="0 0 0" xyz="0 0 0"></origin>
			<mass value="60.86397744"></mass>
			<inertia ixx="5.0635929" ixy="0.00103417" ixz="0.80199628" iyy="6.08689388" iyz="0.00105311" izz="4.96191932"></inertia>
		</inertial>
	</link>
	<link name="left_gripper_base">
		<visual>
			<origin rpy="-1.5707963267948966 3.141592653589793 0" xyz="0 0 0"></origin>
			<geometry>
				<mesh filename="meshes/electric_gripper/electric_gripper_base.DAE"></mesh>
			</geometry>
		</visual>
		<collision>
			<geometry>
				<sphere radius="0.057803"></sphere>
			</geometry>
			<origin xyz="2e-06 1e-06 0.0" rpy="0 0 0"></origin>
		</collision>
		<inertial>
			<origin rpy="-1.5707963267948966 3.141592653589793 0" xyz="0.0 0.0 0.0"></origin>
			<mass value="0.3"></mass>
			<inertia ixx="2e-08" ixy="0" ixz="0" iyy="3e-08" iyz="0" izz="2e-08"></inertia>
		</inertial>
	</link>
	<link name="l_gripper_l_finger_2">
		<collision>
			<geometry>
				<sphere radius="0.026876"></sphere>
			</geometry>
			<origin xyz="-0.005 -0.002999999999999999 0.008303000000000001" rpy="0 0 0"></origin>
		</collision>
	</link>
	<link name="l_gripper_l_finger">
		<visual>
			<origin rpy="0 0 -3.141592653589793" xyz="0 0 0"></origin>
			<geometry>
				<mesh filename="meshes/electric_gripper/fingers/extended_narrow.DAE"></mesh>
			</geometry>
		</visual>
		<collision>
			<geometry>
				<sphere radius="0.056975"></sphere>
			</geometry>
			<origin xyz="0.0 0.017249 0.061498" rpy="0 0 0"></origin>
		</collision>
		<inertial>
			<origin rpy="0 0 -3.141592653589793" xyz="0 0 0"></origin>
			<mass value="0.02"></mass>
			<inertia ixx="0.01" ixy="0" ixz="0" iyy="0.01" iyz="0" izz="0.01"></inertia>
		</inertial>
	</link>
	<link name="l_gripper_l_finger_tip">
		<visual>
			<origin rpy="0 0 3.141592653589793" xyz="0 0 0"></origin>
			<geometry>
				<mesh filename="meshes/electric_gripper/fingers/paddle_tip.DAE"></mesh>
			</geometry>
		</visual>
		<collision>
			<geometry>
				<sphere radius="0.028175"></sphere>
			</geometry>
			<origin xyz="0.0 -0.0044989999999999995 -0.015000000000000001" rpy="0 0 0"></origin>
		</collision>
		<inertial>
			<origin rpy="0 0 3.141592653589793" xyz="0 0 0"></origin>
			<mass value="0.01"></mass>
			<inertia ixx="0.01" ixy="0" ixz="0" iyy="0.01" iyz="0" izz="0.01"></inertia>
		</inertial>
	</link>
	<link name="l_gripper_r_finger_2">
		<collision>
			<geometry>
				<sphere radius="0.026876"></sphere>
			</geometry>
			<origin xyz="0.004999 0.002999999999999999 0.008297000000000002" rpy="0 0 0"></origin>
		</collision>
	</link>
	<link name="l_gripper_r_finger">
		<visual>
			<origin rpy="0 0 -0.0" xyz="0 0 0"></origin>
			<geometry>
				<mesh filename="meshes/electric_gripper/fingers/extended_narrow.DAE"></mesh>
			</geometry>
		</visual>
		<collision>
			<geometry>
				<sphere radius="0.056975"></sphere>
			</geometry>
			<origin xyz="0.0 -0.017239 0.061501" rpy="0 0 0"></origin>
		</collision>
		<inertial>
			<origin rpy="0 0 -0.0" xyz="0 0 0"></origin>
			<mass value="0.02"></mass>
			<inertia ixx="0.01" ixy="0" ixz="0" iyy="0.01" iyz="0" izz="0.01"></inertia>
		</inertial>
	</link>
	<link name="l_gripper_r_finger_tip">
		<visual>
			<origin rpy="0 0 0.0" xyz="0 0 0"></origin>
			<geometry>
				<mesh filename="meshes/electric_gripper/fingers/paddle_tip.DAE"></mesh>
			</geometry>
		</visual>
		<collision>
			<geometry>
				<sphere radius="0.028175"></sphere>
			</geometry>
			<origin xyz="0.0 0.0045 -0.014999000000000002" rpy="0 0 0"></origin>
		</collision>
		<inertial>
			<origin rpy="0 0 0.0" xyz="0 0 0"></origin>
			<mass value="0.01"></mass>
			<inertia ixx="0.01" ixy="0" ixz="0" iyy="0.01" iyz="0" izz="0.01"></inertia>
		</inertial>
	</link>
	<link name="left_gripper">
		<inertial>
			<origin rpy="0 0 0" xyz="0 0 0"></origin>
			<mass value="0.0001"></mass>
			<inertia ixx="0" ixy="0" ixz="0" iyy="0" iyz="0" izz="0.0"></inertia>
		</inertial>
	</link>
	<link name="right_gripper_base">
		<visual>
			<origin rpy="-1.5707963267948966 3.141592653589793 0" xyz="0 0 0"></origin>
			<geometry>
				<mesh filename="meshes/electric_gripper/electric_gripper_base.DAE"></mesh>
			</geometry>
		</visual>
		<collision>
			<geometry>
				<sphere radius="0.057803"></sphere>
			</geometry>
			<origin xyz="2e-06 1e-06 0.0" rpy="0 0 0"></origin>
		</collision>
		<inertial>
			<origin rpy="-1.5707963267948966 3.141592653589793 0" xyz="0.0 0.0 0.0"></origin>
			<mass value="0.3"></mass>
			<inertia ixx="2e-08" ixy="0" ixz="0" iyy="3e-08" iyz="0" izz="2e-08"></inertia>
		</inertial>
	</link>
	<link name="r_gripper_l_finger_2">
		<collision>
			<geometry>
				<sphere radius="0.026876"></sphere>
			</geometry>
			<origin xyz="-0.005 -0.002999999999999999 0.008303000000000001" rpy="0 0 0"></origin>
		</collision>
	</link>
	<link name="r_gripper_l_finger">
		<visual>
			<origin rpy="0 0 -3.141592653589793" xyz="0 0 0"></origin>
			<geometry>
				<mesh filename="meshes/electric_gripper/fingers/extended_narrow.DAE"></mesh>
			</geometry>
		</visual>
		<collision>
			<geometry>
				<sphere radius="0.056975"></sphere>
			</geometry>
			<origin xyz="0.0 0.017249 0.061498" rpy="0 0 0"></origin>
		</collision>
		<inertial>
			<origin rpy="0 0 -3.141592653589793" xyz="0 0 0"></origin>
			<mass value="0.02"></mass>
			<inertia ixx="0.01" ixy="0" ixz="0" iyy="0.01" iyz="0" izz="0.01"></inertia>
		</inertial>
	</link>
	<link name="r_gripper_l_finger_tip">
		<visual>
			<origin rpy="0 0 3.141592653589793" xyz="0 0 0"></origin>
			<geometry>
				<mesh filename="meshes/electric_gripper/fingers/half_round_tip.DAE"></mesh>
			</geometry>
		</visual>
		<collision>
			<geometry>
				<sphere radius="0.020156"></sphere>
			</geometry>
			<origin xyz="0.0 -0.0045000000000000005 -0.015000000000000001" rpy="0 0 0"></origin>
		</collision>
		<inertial>
			<origin rpy="0 0 3.141592653589793" xyz="0 0 0"></origin>
			<mass value="0.01"></mass>
			<inertia ixx="0.01" ixy="0" ixz="0" iyy="0.01" iyz="0" izz="0.01"></inertia>
		</inertial>
	</link>
	<link name="r_gripper_r_finger_2">
		<collision>
			<geometry>
				<sphere radius="0.026876"></sphere>
			</geometry>
			<origin xyz="0.004999 0.002999999999999999 0.008297000000000002" rpy="0 0 0"></origin>
		</collision>
	</link>
	<link name="r_gripper_r_finger">
		<visual>
			<origin rpy="0 0 -0.0" xyz="0 0 0"></origin>
			<geometry>
				<mesh filename="meshes/electric_gripper/fingers/extended_narrow.DAE"></mesh>
			</geometry>
		</visual>
		<collision>
			<geometry>
				<sphere radius="0.056975"></sphere>
			</geometry>
			<origin xyz="0.0 -0.017239 0.061501" rpy="0 0 0"></origin>
		</collision>
		<inertial>
			<origin rpy="0 0 -0.0" xyz="0 0 0"></origin>
			<mass value="0.02"></mass>
			<inertia ixx="0.01" ixy="0" ixz="0" iyy="0.01" iyz="0" izz="0.01"></inertia>
		</inertial>
	</link>
	<link name="r_gripper_r_finger_tip">
		<visual>
			<origin rpy="0 0 0.0" xyz="0 0 0"></origin>
			<geometry>
				<mesh filename="meshes/electric_gripper/fingers/half_round_tip.DAE"></mesh>
			</geometry>
		</visual>
		<collision>
			<geometry>
				<sphere radius="0.020157"></sphere>
			</geometry>
			<origin xyz="0.0 0.004499 -0.015001" rpy="0 0 0"></origin>
		</collision>
		<inertial>
			<origin rpy="0 0 0.0" xyz="0 0 0"></origin>
			<mass value="0.01"></mass>
			<inertia ixx="0.01" ixy="0" ixz="0" iyy="0.01" iyz="0" izz="0.01"></inertia>
		</inertial>
	</link>
	<link name="right_gripper">
		<inertial>
			<origin rpy="0 0 0" xyz="0 0 0"></origin>
			<mass value="0.0001"></mass>
			<inertia ixx="0" ixy="0" ixz="0" iyy="0" iyz="0" izz="0.0"></inertia>
		</inertial>
	</link>
	<joint name="collision_head_1" type="fixed">
		<origin rpy="0 0 0" xyz="0.11 0 0.75"></origin>
		<parent link="base"></parent>
		<child link="collision_head_link_1"></child>
	</joint>
	<joint name="collision_head_2" type="fixed">
		<origin rpy="0 0 0" xyz="0.11 0 0.75"></origin>
		<parent link="base"></parent>
		<child link="collision_head_link_2"></child>
	</joint>
	<joint name="dummy" type="fixed">
		<origin rpy="0 0 0" xyz="0 0 0"></origin>
		<parent link="head"></parent>
		<child link="dummyhead1"></child>
	</joint>
	<joint name="torso_t0" type="fixed">
		<origin rpy="0 0 0" xyz="0 0 0"></origin>
		<parent link="base"></parent>
		<child link="torso"></child>
		<limit effort="50000" lower="-3.01" upper="3.01" velocity="10000"></limit>
	</joint>
	<joint name="left_torso_itb_fixed" type="fixed">
		<origin rpy="-1.57079632679 3.1415 0" xyz="-0.08897 0.15593 0.389125"></origin>
		<parent link="torso"></parent>
		<child link="left_torso_itb"></child>
	</joint>
	<joint name="right_torso_itb_fixed" type="fixed">
		<origin rpy="1.57079632679 0 0" xyz="-0.08897 -0.15593 0.389125"></origin>
		<parent link="torso"></parent>
		<child link="right_torso_itb"></child>
	</joint>
	<joint name="head_pan" type="fixed">
		<origin rpy="0 0 0" xyz="0.06 0 0.686"></origin>
		<axis xyz="0 0 1"></axis>
		<parent link="torso"></parent>
		<child link="head"></child>
	</joint>
	<joint name="head_nod" type="fixed">
		<origin rpy="1.75057 0 1.57079632679" xyz=".1227 0 0"></origin>
		<parent link="head"></parent>
		<child link="screen"></child>
	</joint>
	<joint name="head_camera" type="fixed">
		<origin rpy="1.75057 0 1.57079632679" xyz="0.12839 0 0.06368"></origin>
		<parent link="head"></parent>
		<child link="head_camera"></child>
	</joint>
	<joint name="display_joint" type="fixed">
		<origin rpy="0 0 0" xyz="0.0 -0.016 0.0"></origin>
		<parent link="screen"></parent>
		<child link="display"></child>
	</joint>
	<joint name="sonar_s0" type="fixed">
		<origin rpy="0 0 0" xyz="0.0947 0 .817"></origin>
		<axis xyz="0 0 1"></axis>
		<parent link="torso"></parent>
		<child link="sonar_ring"></child>
	</joint>
	<joint name="right_torso_arm_mount" type="fixed">
		<origin rpy="0 0 -0.7854" xyz="0.024645 -0.219645 0.118588"></origin>
		<parent link="torso"></parent>
		<child link="right_arm_mount"></child>
	</joint>
	<joint name="right_s0" type="revolute">
		<origin rpy="0 0 0" xyz="0.055695 0 0.011038"></origin>
		<axis xyz="0 0 1"></axis>
		<parent link="right_arm_mount"></parent>
		<child link="right_upper_shoulder"></child>
		<limit effort="50.0" lower="-1.70167993878" upper="1.70167993878" velocity="1.5"></limit>
		<dynamics damping="0.7" friction="0.0"></dynamics>
	</joint>
	<joint name="right_s1" type="revolute">
		<origin rpy="-1.57079632679 0 0" xyz="0.069 0 0.27035"></origin>
		<axis xyz="0 0 1"></axis>
		<parent link="right_upper_shoulder"></parent>
		<child link="right_lower_shoulder"></child>
		<limit effort="50.0" lower="-2.147" upper="1.047" velocity="1.5"></limit>
		<dynamics damping="0.7" friction="0.0"></dynamics>
	</joint>
	<joint name="right_e0" type="revolute">
		<origin rpy="1.57079632679 0 1.57079632679" xyz="0.102 0 0"></origin>
		<axis xyz="0 0 1"></axis>
		<parent link="right_lower_shoulder"></parent>
		<child link="right_upper_elbow"></child>
		<limit effort="50.0" lower="-3.05417993878" upper="3.05417993878" velocity="1.5"></limit>
		<dynamics damping="0.7" friction="0.0"></dynamics>
	</joint>
	<joint name="right_e0_fixed" type="fixed">
		<origin rpy="1.57079632679 0 1.57079632679" xyz="0.107 0 0"></origin>
		<axis xyz="0 0 1"></axis>
		<parent link="right_lower_shoulder"></parent>
		<child link="right_upper_elbow_visual"></child>
	</joint>
	<joint name="right_e1" type="revolute">
		<origin rpy="-1.57079632679 -1.57079632679 0" xyz="0.069 0 0.26242"></origin>
		<axis xyz="0 0 1"></axis>
		<parent link="right_upper_elbow"></parent>
		<child link="right_lower_elbow"></child>
		<limit effort="50.0" lower="-0.05" upper="2.618" velocity="1.5"></limit>
		<dynamics damping="0.7" friction="0.0"></dynamics>
	</joint>
	<joint name="right_w0" type="revolute">
		<origin rpy="1.57079632679 0 1.57079632679" xyz="0.10359 0 0"></origin>
		<axis xyz="0 0 1"></axis>
		<parent link="right_lower_elbow"></parent>
		<child link="right_upper_forearm"></child>
		<limit effort="15.0" lower="-3.059" upper="3.059" velocity="4.0"></limit>
		<dynamics damping="0.7" friction="0.0"></dynamics>
	</joint>
	<joint name="right_w0_fixed" type="fixed">
		<origin rpy="1.57079632679 0 1.57079632679" xyz="0.088 0 0"></origin>
		<axis xyz="0 0 1"></axis>
		<parent link="right_lower_elbow"></parent>
		<child link="right_upper_forearm_visual"></child>
	</joint>
	<joint name="right_w0_to_itb_fixed" type="fixed">
		<origin rpy="-1.57079632679 0 1.57079632679" xyz="-0.0565 0 0.12"></origin>
		<axis xyz="0 0 1"></axis>
		<parent link="right_upper_forearm"></parent>
		<child link="right_arm_itb"></child>
	</joint>
	<joint name="right_w1" type="revolute">
		<origin rpy="-1.57079632679 -1.57079632679 0" xyz="0.01 0 0.2707"></origin>
		<axis xyz="0 0 1"></axis>
		<parent link="right_upper_forearm"></parent>
		<child link="right_lower_forearm"></child>
		<limit effort="15.0" lower="-1.57079632679" upper="2.094" velocity="4.0"></limit>
		<dynamics damping="0.7" friction="0.0"></dynamics>
	</joint>
	<joint name="right_w2" type="revolute">
		<origin rpy="1.57079632679 0 1.57079632679" xyz="0.115975 0 0"></origin>
		<axis xyz="0 0 1"></axis>
		<parent link="right_lower_forearm"></parent>
		<child link="right_wrist"></child>
		<limit effort="15.0" lower="-3.059" upper="3.059" velocity="4.0"></limit>
		<dynamics damping="0.7" friction="0.0"></dynamics>
	</joint>
	<joint name="right_hand" type="fixed">
		<origin rpy="0 0 0" xyz="0 0 0.11355"></origin>
		<axis xyz="0 0 1"></axis>
		<parent link="right_wrist"></parent>
		<child link="right_hand"></child>
	</joint>
	<joint name="right_hand_camera" type="fixed">
		<origin rpy="0 0 -1.57079633" xyz="0.03825 0.012 0.015355"></origin>
		<parent link="right_hand"></parent>
		<child link="right_hand_camera"></child>
	</joint>
	<joint name="right_hand_camera_axis" type="fixed">
		<origin rpy="0 0 0" xyz="0.03825 0.012 0.015355"></origin>
		<parent link="right_hand"></parent>
		<child link="right_hand_camera_axis"></child>
	</joint>
	<joint name="right_hand_range" type="fixed">
		<origin rpy="0 -1.57079632679 -1.57079632679" xyz="0.032 -0.020245 0.0288"></origin>
		<parent link="right_hand"></parent>
		<child link="right_hand_range"></child>
	</joint>
	<joint name="right_hand_accelerometer" type="fixed">
		<origin rpy="0 0 0" xyz="0.00198 0.000133 -0.0146"></origin>
		<parent link="right_hand"></parent>
		<child link="right_hand_accelerometer"></child>
	</joint>
	<joint name="left_torso_arm_mount" type="fixed">
		<origin rpy="0 0 0.7854" xyz="0.024645 0.219645 0.118588"></origin>
		<parent link="torso"></parent>
		<child link="left_arm_mount"></child>
	</joint>
	<joint name="left_s0" type="revolute">
		<origin rpy="0 0 0" xyz="0.055695 0 0.011038"></origin>
		<axis xyz="0 0 1"></axis>
		<parent link="left_arm_mount"></parent>
		<child link="left_upper_shoulder"></child>
		<limit effort="50.0" lower="-1.70167993878" upper="1.70167993878" velocity="1.5"></limit>
		<dynamics damping="0.7" friction="0.0"></dynamics>
	</joint>
	<joint name="left_s1" type="revolute">
		<origin rpy="-1.57079632679 0 0" xyz="0.069 0 0.27035"></origin>
		<axis xyz="0 0 1"></axis>
		<parent link="left_upper_shoulder"></parent>
		<child link="left_lower_shoulder"></child>
		<limit effort="50.0" lower="-2.147" upper="1.047" velocity="1.5"></limit>
		<dynamics damping="0.7" friction="0.0"></dynamics>
	</joint>
	<joint name="left_e0" type="revolute">
		<origin rpy="1.57079632679 0 1.57079632679" xyz="0.102 0 0"></origin>
		<axis xyz="0 0 1"></axis>
		<parent link="left_lower_shoulder"></parent>
		<child link="left_upper_elbow"></child>
		<limit effort="50.0" lower="-3.05417993878" upper="3.05417993878" velocity="1.5"></limit>
		<dynamics damping="0.7" friction="0.0"></dynamics>
	</joint>
	<joint name="left_e0_fixed" type="fixed">
		<origin rpy="1.57079632679 0 1.57079632679" xyz="0.107 0 0"></origin>
		<axis xyz="0 0 1"></axis>
		<parent link="left_lower_shoulder"></parent>
		<child link="left_upper_elbow_visual"></child>
	</joint>
	<joint name="left_e1" type="revolute">
		<origin rpy="-1.57079632679 -1.57079632679 0" xyz="0.069 0 0.26242"></origin>
		<axis xyz="0 0 1"></axis>
		<parent link="left_upper_elbow"></parent>
		<child link="left_lower_elbow"></child>
		<limit effort="50.0" lower="-0.05" upper="2.618" velocity="1.5"></limit>
		<dynamics damping="0.7" friction="0.0"></dynamics>
	</joint>
	<joint name="left_w0" type="revolute">
		<origin rpy="1.57079632679 0 1.57079632679" xyz="0.10359 0 0"></origin>
		<axis xyz="0 0 1"></axis>
		<parent link="left_lower_elbow"></parent>
		<child link="left_upper_forearm"></child>
		<limit effort="15.0" lower="-3.059" upper="3.059" velocity="4.0"></limit>
		<dynamics damping="0.7" friction="0.0"></dynamics>
	</joint>
	<joint name="left_w0_fixed" type="fixed">
		<origin rpy="1.57079632679 0 1.57079632679" xyz="0.088 0 0"></origin>
		<axis xyz="0 0 1"></axis>
		<parent link="left_lower_elbow"></parent>
		<child link="left_upper_forearm_visual"></child>
	</joint>
	<joint name="left_w0_to_itb_fixed" type="fixed">
		<origin rpy="-1.57079632679 0 1.57079632679" xyz="-0.0565 0 0.12"></origin>
		<axis xyz="0 0 1"></axis>
		<parent link="left_upper_forearm"></parent>
		<child link="left_arm_itb"></child>
	</joint>
	<joint name="left_w1" type="revolute">
		<origin rpy="-1.57079632679 -1.57079632679 0" xyz="0.01 0 0.2707"></origin>
		<axis xyz="0 0 1"></axis>
		<parent link="left_upper_forearm"></parent>
		<child link="left_lower_forearm"></child>
		<limit effort="15.0" lower="-1.57079632679" upper="2.094" velocity="4.0"></limit>
		<dynamics damping="0.7" friction="0.0"></dynamics>
	</joint>
	<joint name="left_w2" type="revolute">
		<origin rpy="1.57079632679 0 1.57079632679" xyz="0.115975 0 0"></origin>
		<axis xyz="0 0 1"></axis>
		<parent link="left_lower_forearm"></parent>
		<child link="left_wrist"></child>
		<limit effort="15.0" lower="-3.059" upper="3.059" velocity="4.0"></limit>
		<dynamics damping="0.7" friction="0.0"></dynamics>
	</joint>
	<joint name="left_hand" type="fixed">
		<origin rpy="0 0 0" xyz="0 0 0.11355"></origin>
		<axis xyz="0 0 1"></axis>
		<parent link="left_wrist"></parent>
		<child link="left_hand"></child>
	</joint>
	<joint name="left_hand_camera" type="fixed">
		<origin rpy="0 0 -1.57079633" xyz="0.03825 0.012 0.015355"></origin>
		<parent link="left_hand"></parent>
		<child link="left_hand_camera"></child>
	</joint>
	<joint name="left_hand_camera_axis" type="fixed">
		<origin rpy="0 0 0" xyz="0.03825 0.012 0.015355"></origin>
		<parent link="left_hand"></parent>
		<child link="left_hand_camera_axis"></child>
	</joint>
	<joint name="left_hand_range" type="fixed">
		<origin rpy="0 -1.57079632679 -1.57079632679" xyz="0.032 -0.020245 0.0288"></origin>
		<parent link="left_hand"></parent>
		<child link="left_hand_range"></child>
	</joint>
	<joint name="left_hand_accelerometer" type="fixed">
		<origin rpy="0 0 0" xyz="0.00198 0.000133 -0.0146"></origin>
		<parent link="left_hand"></parent>
		<child link="left_hand_accelerometer"></child>
	</joint>
	<joint name="pedestal_fixed" type="fixed">
		<origin rpy="0 0 0" xyz="0.0 0.0 0.0"></origin>
		<parent link="torso"></parent>
		<child link="pedestal"></child>
	</joint>
	<joint name="l_gripper_l_finger_tip_joint" type="fixed">
		<origin rpy="0 0 0" xyz="0.0 0.01725 0.1127"></origin>
		<parent link="l_gripper_l_finger"></parent>
		<child link="l_gripper_l_finger_tip"></child>
	</joint>
	<joint name="l_gripper_r_finger_tip_joint" type="fixed">
		<origin rpy="0 0 0" xyz="0.0 -0.01725 0.1127"></origin>
		<parent link="l_gripper_r_finger"></parent>
		<child link="l_gripper_r_finger_tip"></child>
	</joint>
	<joint name="left_gripper_base" type="fixed">
		<origin rpy="0 0 0" xyz="0 0 0.025"></origin>
		<parent link="left_hand"></parent>
		<child link="left_gripper_base"></child>
	</joint>
	<joint name="left_endpoint" type="fixed">
		<origin rpy="0 0 0" xyz="0 0 0.13269999999999998"></origin>
		<parent link="left_gripper_base"></parent>
		<child link="left_gripper"></child>
	</joint>
	<joint name="l_gripper_l_finger_joint_2" type="fixed">
		<origin rpy="0 0 0" xyz="0.0 0.019333 0.02"></origin>
		<axis xyz="0 1 0"></axis>
		<parent link="left_gripper_base"></parent>
		<child link="l_gripper_l_finger_2"></child>
	</joint>
	<joint name="l_gripper_l_finger_joint" type="fixed">
		<origin rpy="0 0 0" xyz="0.0 0.019333 0.02"></origin>
		<axis xyz="0 1 0"></axis>
		<parent link="left_gripper_base"></parent>
		<child link="l_gripper_l_finger"></child>
	</joint>
	<joint name="l_gripper_r_finger_joint_2" type="fixed">
		<origin rpy="0 0 0" xyz="0.0 -0.019333 0.02"></origin>
		<axis xyz="0 1 0"></axis>
		<parent link="left_gripper_base"></parent>
		<child link="l_gripper_r_finger_2"></child>
	</joint>
	<joint name="l_gripper_r_finger_joint" type="fixed">
		<origin rpy="0 0 0" xyz="0.0 -0.019333 0.02"></origin>
		<axis xyz="0 1 0"></axis>
		<parent link="left_gripper_base"></parent>
		<child link="l_gripper_r_finger"></child>
	</joint>
	<joint name="r_gripper_l_finger_tip_joint" type="fixed">
		<origin rpy="0 0 0" xyz="0.0 0.01725 0.1127"></origin>
		<parent link="r_gripper_l_finger"></parent>
		<child link="r_gripper_l_finger_tip"></child>
	</joint>
	<joint name="r_gripper_r_finger_tip_joint" type="fixed">
		<origin rpy="0 0 0" xyz="0.0 -0.01725 0.1127"></origin>
		<parent link="r_gripper_r_finger"></parent>
		<child link="r_gripper_r_finger_tip"></child>
	</joint>
	<joint name="right_gripper_base" type="fixed">
		<origin rpy="0 0 0" xyz="0 0 0.025"></origin>
		<parent link="right_hand"></parent>
		<child link="right_gripper_base"></child>
	</joint>
	<joint name="right_endpoint" type="fixed">
		<origin rpy="0 0 0" xyz="0 0 0.13269999999999998"></origin>
		<parent link="right_gripper_base"></parent>
		<child link="right_gripper"></child>
	</joint>
	<joint name="r_gripper_l_finger_joint_2" type="fixed">
		<origin rpy="0 0 0" xyz="0.0 0.019333 0.02"></origin>
		<axis xyz="0 1 0"></axis>
		<parent link="right_gripper_base"></parent>
		<child link="r_gripper_l_finger_2"></child>
	</joint>
	<joint name="r_gripper_l_finger_joint" type="fixed">
		<origin rpy="0 0 0" xyz="0.0 0.019333 0.02"></origin>
		<axis xyz="0 1 0"></axis>
		<parent link="right_gripper_base"></parent>
		<child link="r_gripper_l_finger"></child>
	</joint>
	<joint name="r_gripper_r_finger_joint_2" type="fixed">
		<origin rpy="0 0 0" xyz="0.0 -0.019333 0.02"></origin>
		<axis xyz="0 1 0"></axis>
		<parent link="right_gripper_base"></parent>
		<child link="r_gripper_r_finger_2"></child>
	</joint>
	<joint name="r_gripper_r_finger_joint" type="fixed">
		<origin rpy="0 0 0" xyz="0.0 -0.019333 0.02"></origin>
		<axis xyz="0 1 0"></axis>
		<parent link="right_gripper_base"></parent>
		<child link="r_gripper_r_finger"></child>
	</joint>
	<gazebo reference="l_gripper_l_finger">
		<mu1>1000</mu1>
		<mu2>1000</mu2>
		<fdir1>0.0 0.0 1.0</fdir1>
		<kp>1e5</kp>
		<kd>1.0</kd>
	</gazebo>
	<gazebo reference="l_gripper_r_finger">
		<mu1>1000</mu1>
		<mu2>1000</mu2>
		<fdir1>0.0 0.0 1.0</fdir1>
		<kp>1e5</kp>
		<kd>1.0</kd>
	</gazebo>
	<gazebo reference="l_gripper_r_finger_joint">
		<implicitSpringDamper>1</implicitSpringDamper>
	</gazebo>
	<gazebo reference="l_gripper_l_finger_joint">
		<implicitSpringDamper>1</implicitSpringDamper>
	</gazebo>
	<gazebo reference="r_gripper_l_finger">
		<mu1>1000</mu1>
		<mu2>1000</mu2>
		<fdir1>0.0 0.0 1.0</fdir1>
		<kp>1e5</kp>
		<kd>1.0</kd>
	</gazebo>
	<gazebo reference="r_gripper_r_finger">
		<mu1>1000</mu1>
		<mu2>1000</mu2>
		<fdir1>0.0 0.0 1.0</fdir1>
		<kp>1e5</kp>
		<kd>1.0</kd>
	</gazebo>
	<gazebo reference="r_gripper_r_finger_joint">
		<implicitSpringDamper>1</implicitSpringDamper>
	</gazebo>
	<gazebo reference="r_gripper_l_finger_joint">
		<implicitSpringDamper>1</implicitSpringDamper>
	</gazebo>
	<transmission name="gripper_left1">
		<type>transmission_interface/SimpleTransmission</type>
		<joint name="l_gripper_r_finger_joint">
			<hardwareInterface>EffortJointInterface</hardwareInterface>
		</joint>
		<actuator name="gripper_l1_motor1">
			<hardwareInterface>EffortJointInterface</hardwareInterface>
			<mechanicalReduction>1</mechanicalReduction>
		</actuator>
	</transmission>
	<transmission name="gripper_left2">
		<type>transmission_interface/SimpleTransmission</type>
		<joint name="l_gripper_l_finger_joint">
			<hardwareInterface>EffortJointInterface</hardwareInterface>
		</joint>
		<actuator name="gripper_l1_motor2">
			<hardwareInterface>EffortJointInterface</hardwareInterface>
			<mechanicalReduction>1</mechanicalReduction>
		</actuator>
	</transmission>
	<transmission name="gripper_right1">
		<type>transmission_interface/SimpleTransmission</type>
		<joint name="r_gripper_r_finger_joint">
			<hardwareInterface>EffortJointInterface</hardwareInterface>
		</joint>
		<actuator name="gripper_r1_motor1">
			<hardwareInterface>EffortJointInterface</hardwareInterface>
			<mechanicalReduction>1</mechanicalReduction>
		</actuator>
	</transmission>
	<transmission name="gripper_right2">
		<type>transmission_interface/SimpleTransmission</type>
		<joint name="r_gripper_l_finger_joint">
			<hardwareInterface>EffortJointInterface</hardwareInterface>
		</joint>
		<actuator name="gripper_r1_motor2">
			<hardwareInterface>EffortJointInterface</hardwareInterface>
			<mechanicalReduction>1</mechanicalReduction>
		</actuator>
	</transmission>
</robot>