<?xml version="1.0" encoding="utf-8"?>
<robot name="baxter" path="assets/baxter/baxter.urdf">
	<link name="base"></link>
	<link name="torso">
		<visual>
			<origin rpy="0 0 0" xyz="0 0 0"></origin>
			<geometry>
				<mesh filename="meshes/torso/base_link.DAE"></mesh>
			</geometry>
			<material name="darkgray">
				<color rgba=".2 .2 .2 1"></color>
			</material>
		</visual>
		<collision>
			<geometry>
				<sphere radius="0.164839"></sphere>
			</geometry>
			<origin xyz="0.014699948805904355 0.0022552267185848417 0.7632673811604586" rpy="0 0 0"></origin>
		</collision>
		<collision>
			<geometry>
				<sphere radius="0.208855"></sphere>
			</geometry>
			<origin xyz="-0.10168805119409564 0.011328226718584841 0.5238983811604585" rpy="0 0 0"></origin>
		</collision>
		<collision>
			<geometry>
				<sphere radius="0.24947"></sphere>
			</geometry>
			<origin xyz="-0.07715305119409564 0.004001226718584842 0.3937833811604585" rpy="0 0 0"></origin>
		</collision>
		<collision>
			<geometry>
				<sphere radius="0.254673"></sphere>
			</geometry>
			<origin xyz="-0.061031051194095645 -0.024468773281415158 0.25398338116045854" rpy="0 0 0"></origin>
		</collision>
		<collision>
			<geometry>
				<sphere radius="0.273482"></sphere>
			</geometry>
			<origin xyz="-0.019392051194095646 -0.009287773281415158 0.12408438116045856" rpy="0 0 0"></origin>
		</collision>
		<collision>
			<geometry>
				<sphere radius="0.125661"></sphere>
			</geometry>
			<origin xyz="0.057654948805904355 -0.23470777328141515 0.12400338116045856" rpy="0 0 0"></origin>
		</collision>
		<collision>
			<geometry>
				<sphere radius="0.224009"></sphere>
			</geometry>
			<origin xyz="0.01622294880590435 0.14096122671858485 0.11018638116045854" rpy="0 0 0"></origin>
		</collision>
		<collision>
			<geometry>
				<sphere radius="0.16144"></sphere>
			</geometry>
			<origin xyz="-0.12666805119409563 0.12954622671858484 0.2684543811604585" rpy="0 0 0"></origin>
		</collision>
		<inertial>
			<origin rpy="0 0 0" xyz="0.000000 0.000000 0.000000"></origin>
			<mass value="35.336455"></mass>
			<inertia ixx="1.849155" ixy="-0.000354" ixz="-0.154188" iyy="1.662671" iyz="0.003292" izz="0.802239"></inertia>
		</inertial>
	</link>
	<link name="left_torso_itb">
		<inertial>
			<origin rpy="0 0 0" xyz="0.000000 0.000000 0.000000"></origin>
			<mass value="0.0001"></mass>
			<inertia ixx="1e-08" ixy="0" ixz="0" iyy="1e-08" iyz="0" izz="1e-08"></inertia>
		</inertial>
	</link>
	<link name="right_torso_itb">
		<inertial>
			<origin rpy="0 0 0" xyz="0.000000 0.000000 0.000000"></origin>
			<mass value="0.0001"></mass>
			<inertia ixx="1e-08" ixy="0" ixz="0" iyy="1e-08" iyz="0" izz="1e-08"></inertia>
		</inertial>
	</link>
	<link name="head">
		<visual>
			<origin rpy="0 0 0" xyz="0 0 .00953"></origin>
			<geometry>
				<mesh filename="meshes/head/H0.DAE"></mesh>
			</geometry>
			<material name="darkgray">
				<color rgba=".2 .2 .2 1"></color>
			</material>
		</visual>
		<collision>
			<origin rpy="0 0 0" xyz="0.0 0 0.0"></origin>
			<geometry>
				<sphere radius="0.001"></sphere>
			</geometry>
		</collision>
		<inertial>
			<origin rpy="0 0 0" xyz="0 0 0"></origin>
			<mass value="0.547767"></mass>
			<inertia ixx="0.004641" ixy="0.000159" ixz="0.000242" iyy="0.003295" iyz="-0.001324" izz="0.003415"></inertia>
		</inertial>
	</link>
	<link name="sonar_ring">
		<visual>
			<origin rpy="0 0 0" xyz="-.0347 0 .00953"></origin>
			<geometry>
				<cylinder length="0.01" radius="0.085"></cylinder>
			</geometry>
			<material name="darkgray">
				<color rgba=".2 .2 .2 1"></color>
			</material>
		</visual>
		<collision>
			<origin rpy="0 0 0" xyz="0.0 0 0.0"></origin>
			<geometry>
				<sphere radius="0.001"></sphere>
			</geometry>
		</collision>
		<inertial>
			<origin rpy="0 0 0" xyz="0 0 0"></origin>
			<mass value="0.0001"></mass>
			<inertia ixx="1e-08" ixy="0" ixz="0" iyy="1e-08" iyz="0" izz="1e-08"></inertia>
		</inertial>
	</link>
	<link name="screen">
		<visual>
			<origin rpy="0 -1.57079632679 0" xyz="0 -.00953 -.0347"></origin>
			<geometry>
				<mesh filename="meshes/head/H1.DAE"></mesh>
			</geometry>
			<material name="darkred">
				<color rgba=".5 .1 .1 1"></color>
			</material>
		</visual>
		<collision>
			<origin rpy="0 0 0" xyz="0.0 0 0.0"></origin>
			<geometry>
				<sphere radius="0.001"></sphere>
			</geometry>
		</collision>
		<inertial>
			<origin rpy="0 0 0" xyz="0 0 0"></origin>
			<mass value="0.440171"></mass>
			<inertia ixx="0.004006" ixy="0.000230" ixz="0.000002" iyy="0.002800" iyz="0.000029" izz="0.001509"></inertia>
		</inertial>
	</link>
	<link name="display">
		<visual>
			<origin rpy="0.2617993877991494 0 0" xyz="0 0 0"></origin>
			<geometry>
				<box size="0.218 0.16 0.001"></box>
			</geometry>
			<material name="black">
				<color rgba="0 0 0 1"></color>
			</material>
		</visual>
		<inertial>
			<origin rpy="0 0 0" xyz="0 0 0"></origin>
			<mass value="0.0001"></mass>
			<inertia ixx="1e-08" ixy="0" ixz="0" iyy="1e-08" iyz="0" izz="1e-08"></inertia>
		</inertial>
	</link>
	<link name="head_camera">
		<inertial>
			<origin rpy="0 0 0" xyz="0 0 0"></origin>
			<mass value="0.0001"></mass>
			<inertia ixx="1e-08" ixy="0" ixz="0" iyy="1e-08" iyz="0" izz="1e-08"></inertia>
		</inertial>
	</link>
	<link name="dummyhead1">
		<inertial>
			<origin rpy="0 0 0" xyz="0 0 0"></origin>
			<mass value="0.0001"></mass>
			<inertia ixx="1e-08" ixy="0" ixz="0" iyy="1e-08" iyz="0" izz="1e-08"></inertia>
		</inertial>
	</link>
	<link name="collision_head_link_1">
		<visual>
			<origin rpy="0 0 0" xyz="0 0 0"></origin>
			<geometry>
				<sphere radius="0.001"></sphere>
			</geometry>
			<material name="red">
				<color rgba="0.8 0.3 0.3 0.3"></color>
			</material>
		</visual>
		<collision>
			<origin rpy="0 0 0.0" xyz="-0.07 -0.04 0.0"></origin>
			<geometry>
				<sphere radius="0.22"></sphere>
			</geometry>
		</collision>
		<inertial>
			<origin rpy="0 0 0" xyz="0 0 0"></origin>
			<mass value="0.0001"></mass>
			<inertia ixx="1e-08" ixy="0" ixz="0" iyy="1e-08" iyz="0" izz="1e-08"></inertia>
		</inertial>
	</link>
	<link name="collision_head_link_2">
		<visual>
			<origin rpy="0 0 0" xyz="0 0 0"></origin>
			<geometry>
				<sphere radius="0.001"></sphere>
			</geometry>
			<material name="red">
				<color rgba="0.8 0.3 0.3 0.3"></color>
			</material>
		</visual>
		<collision>
			<origin rpy="0 0 0" xyz="-0.07 0.04 0.00"></origin>
			<geometry>
				<sphere radius="0.22"></sphere>
			</geometry>
		</collision>
		<inertial>
			<origin rpy="0 0 0" xyz="0 0 0"></origin>
			<mass value="0.0001"></mass>
			<inertia ixx="1e-08" ixy="0" ixz="0" iyy="1e-08" iyz="0" izz="1e-08"></inertia>
		</inertial>
	</link>
	<link name="right_arm_mount">
		<inertial>
			<origin rpy="0 0 0" xyz="0 0 0"></origin>
			<mass value="0.0001"></mass>
			<inertia ixx="1e-08" ixy="0" ixz="0" iyy="1e-08" iyz="0" izz="1e-08"></inertia>
		</inertial>
	</link>
	<link name="right_upper_shoulder">
		<visual>
			<origin rpy="0 0 0" xyz="0 0 0"></origin>
			<geometry>
				<mesh filename="meshes/upper_shoulder/S0.DAE"></mesh>
			</geometry>
			<material name="darkred">
				<color rgba=".5 .1 .1 1"></color>
			</material>
		</visual>
		<collision>
			<geometry>
				<sphere radius="0.043303"></sphere>
			</geometry>
			<origin xyz="0.01103 -0.029885 0.243103" rpy="0 0 0"></origin>
		</collision>
		<collision>
			<geometry>
				<sphere radius="0.062721"></sphere>
			</geometry>
			<origin xyz="2e-06 -0.000133 0.136805" rpy="0 0 0"></origin>
		</collision>
		<collision>
			<geometry>
				<sphere radius="0.084766"></sphere>
			</geometry>
			<origin xyz="2e-06 0.0 0.059875" rpy="0 0 0"></origin>
		</collision>
		<collision>
			<geometry>
				<sphere radius="0.055178"></sphere>
			</geometry>
			<origin xyz="-0.024348 0.000152 0.236549" rpy="0 0 0"></origin>
		</collision>
		<collision>
			<geometry>
				<sphere radius="0.084092"></sphere>
			</geometry>
			<origin xyz="0.000316 0.000763 0.21296500000000002" rpy="0 0 0"></origin>
		</collision>
		<collision>
			<geometry>
				<sphere radius="0.03722"></sphere>
			</geometry>
			<origin xyz="-0.016893 -0.032329 0.247072" rpy="0 0 0"></origin>
		</collision>
		<inertial>
			<origin rpy="0 0 0" xyz="0.01783 0.00086 0.19127"></origin>
			<mass value="5.70044"></mass>
			<inertia ixx="0.04709102262" ixy="0.00012787556" ixz="0.00614870039" iyy="0.03766976455" iyz="0.00078086899" izz="0.03595988478"></inertia>
		</inertial>
	</link>
	<link name="right_lower_shoulder">
		<visual>
			<origin rpy="0 0 0" xyz="0 0 0"></origin>
			<geometry>
				<mesh filename="meshes/lower_shoulder/S1.DAE"></mesh>
			</geometry>
			<material name="darkred">
				<color rgba=".5 .1 .1 1"></color>
			</material>
		</visual>
		<collision>
			<geometry>
				<sphere radius="0.068728"></sphere>
			</geometry>
			<origin xyz="-0.010536 0.010523 -0.014568" rpy="0 0 0"></origin>
		</collision>
		<collision>
			<geometry>
				<sphere radius="0.060101"></sphere>
			</geometry>
			<origin xyz="0.014261 0.014854 -0.0202" rpy="0 0 0"></origin>
		</collision>
		<collision>
			<geometry>
				<sphere radius="0.058701"></sphere>
			</geometry>
			<origin xyz="0.017285 -0.01473 -0.022527" rpy="0 0 0"></origin>
		</collision>
		<collision>
			<geometry>
				<sphere radius="0.061789"></sphere>
			</geometry>
			<origin xyz="-0.012972 -0.015236 -0.019432" rpy="0 0 0"></origin>
		</collision>
		<collision>
			<geometry>
				<sphere radius="0.060643"></sphere>
			</geometry>
			<origin xyz="0.018474 0.010395 0.021362" rpy="0 0 0"></origin>
		</collision>
		<collision>
			<geometry>
				<sphere radius="0.051186"></sphere>
			</geometry>
			<origin xyz="-0.010619 0.027017 0.02797" rpy="0 0 0"></origin>
		</collision>
		<collision>
			<geometry>
				<sphere radius="0.058315"></sphere>
			</geometry>
			<origin xyz="0.012425 -0.021046 0.022725" rpy="0 0 0"></origin>
		</collision>
		<collision>
			<geometry>
				<sphere radius="0.067072"></sphere>
			</geometry>
			<origin xyz="-0.014317 -0.005947 0.015587" rpy="0 0 0"></origin>
		</collision>
		<inertial>
			<origin rpy="0 0 0" xyz="0.06845 0.00269 -0.00529"></origin>
			<mass value="3.22698"></mass>
			<inertia ixx="0.01175209419" ixy="-0.00030096398" ixz="0.00207675762" iyy="0.0278859752" iyz="-0.00018821993" izz="0.02078749298"></inertia>
		</inertial>
	</link>
	<link name="right_upper_elbow">
		<visual>
			<origin rpy="0 0 0" xyz="0 0 0"></origin>
			<geometry>
				<mesh filename="meshes/upper_elbow/E0.DAE"></mesh>
			</geometry>
			<material name="darkred">
				<color rgba=".5 .1 .1 1"></color>
			</material>
		</visual>
		<collision>
			<geometry>
				<sphere radius="0.060888"></sphere>
			</geometry>
			<origin xyz="-0.020397 0.000515 -0.067403" rpy="0 0 0"></origin>
		</collision>
		<collision>
			<geometry>
				<sphere radius="0.07648"></sphere>
			</geometry>
			<origin xyz="-0.001295 -0.006457 -0.0535" rpy="0 0 0"></origin>
		</collision>
		<collision>
			<geometry>
				<sphere radius="0.076373"></sphere>
			</geometry>
			<origin xyz="0.005584 -0.003051 -0.053498" rpy="0 0 0"></origin>
		</collision>
		<collision>
			<geometry>
				<sphere radius="0.076124"></sphere>
			</geometry>
			<origin xyz="0.005319 0.003548 -0.053496999999999996" rpy="0 0 0"></origin>
		</collision>
		<collision>
			<geometry>
				<sphere radius="0.059516"></sphere>
			</geometry>
			<origin xyz="-0.00401 0.020116 -0.067416" rpy="0 0 0"></origin>
		</collision>
		<collision>
			<geometry>
				<sphere radius="0.067106"></sphere>
			</geometry>
			<origin xyz="-0.013078 -0.00344 -0.04668" rpy="0 0 0"></origin>
		</collision>
		<collision>
			<geometry>
				<sphere radius="0.067471"></sphere>
			</geometry>
			<origin xyz="-0.005768 0.014634 -0.044903" rpy="0 0 0"></origin>
		</collision>
		<inertial>
			<origin rpy="0 0 0" xyz="-0.00276 0.00132 0.18086"></origin>
			<mass value="4.31272"></mass>
			<inertia ixx="0.02661733557" ixy="0.00029270634" ixz="0.00392189887" iyy="0.02844355207" iyz="0.0010838933" izz="0.01248008322"></inertia>
		</inertial>
	</link>
	<link name="right_upper_elbow_visual">
		<collision>
			<geometry>
				<sphere radius="0.084453"></sphere>
			</geometry>
			<origin xyz="-8.1e-05 0.000408 0.05959300000000001" rpy="0 0 0"></origin>
		</collision>
		<collision>
			<geometry>
				<sphere radius="0.069876"></sphere>
			</geometry>
			<origin xyz="-1e-06 -2e-06 0.15583000000000002" rpy="0 0 0"></origin>
		</collision>
		<collision>
			<geometry>
				<sphere radius="0.064251"></sphere>
			</geometry>
			<origin xyz="0.017053 0.005156 0.230634" rpy="0 0 0"></origin>
		</collision>
		<collision>
			<geometry>
				<sphere radius="0.069072"></sphere>
			</geometry>
			<origin xyz="-0.010615 -0.009514 0.04592800000000001" rpy="0 0 0"></origin>
		</collision>
		<collision>
			<geometry>
				<sphere radius="0.074818"></sphere>
			</geometry>
			<origin xyz="0.007854 -0.004198 0.05095300000000001" rpy="0 0 0"></origin>
		</collision>
		<collision>
			<geometry>
				<sphere radius="0.066208"></sphere>
			</geometry>
			<origin xyz="-0.006123 0.015893 0.229387" rpy="0 0 0"></origin>
		</collision>
		<collision>
			<geometry>
				<sphere radius="0.070661"></sphere>
			</geometry>
			<origin xyz="-0.010126 -0.006766 0.225271" rpy="0 0 0"></origin>
		</collision>
		<collision>
			<geometry>
				<sphere radius="0.049148"></sphere>
			</geometry>
			<origin xyz="0.014514 -0.026563 0.24106" rpy="0 0 0"></origin>
		</collision>
		<inertial>
			<origin rpy="0 0 0" xyz="0 0 0"></origin>
			<mass value="0.0001"></mass>
			<inertia ixx="1e-08" ixy="0" ixz="0" iyy="1e-08" iyz="0" izz="1e-08"></inertia>
		</inertial>
	</link>
	<link name="right_lower_elbow">
		<visual>
			<origin rpy="0 0 0" xyz="0 0 0"></origin>
			<geometry>
				<mesh filename="meshes/lower_elbow/E1.DAE"></mesh>
			</geometry>
			<material name="darkred">
				<color rgba=".5 .1 .1 1"></color>
			</material>
		</visual>
		<collision>
			<geometry>
				<sphere radius="0.071372"></sphere>
			</geometry>
			<origin xyz="-0.001758 0.009929 -1e-06" rpy="0 0 0"></origin>
		</collision>
		<collision>
			<geometry>
				<sphere radius="0.0717"></sphere>
			</geometry>
			<origin xyz="0.007732 0.006416 2e-06" rpy="0 0 0"></origin>
		</collision>
		<collision>
			<geometry>
				<sphere radius="0.065188"></sphere>
			</geometry>
			<origin xyz="0.013338 -0.008417 -0.005892" rpy="0 0 0"></origin>
		</collision>
		<collision>
			<geometry>
				<sphere radius="0.066661"></sphere>
			</geometry>
			<origin xyz="-0.01472 0.003978 -0.005016" rpy="0 0 0"></origin>
		</collision>
		<collision>
			<geometry>
				<sphere radius="0.054374"></sphere>
			</geometry>
			<origin xyz="-0.011057 -0.024192 -0.015187" rpy="0 0 0"></origin>
		</collision>
		<collision>
			<geometry>
				<sphere radius="0.066192"></sphere>
			</geometry>
			<origin xyz="-0.014692 0.003283 0.004913" rpy="0 0 0"></origin>
		</collision>
		<collision>
			<geometry>
				<sphere radius="0.056334"></sphere>
			</geometry>
			<origin xyz="-0.008327 -0.02275 0.013475" rpy="0 0 0"></origin>
		</collision>
		<collision>
			<geometry>
				<sphere radius="0.064955"></sphere>
			</geometry>
			<origin xyz="0.014034 -0.008438 0.006516" rpy="0 0 0"></origin>
		</collision>
		<inertial>
			<origin rpy="0 0 0" xyz="0.02611 0.00159 -0.01117"></origin>
			<mass value="2.07206"></mass>
			<inertia ixx="0.00711582686" ixy="0.00036036173" ixz="0.0007459496" iyy="0.01318227876" iyz="-0.00019663418" izz="0.00926852064"></inertia>
		</inertial>
	</link>
	<link name="right_upper_forearm">
		<visual>
			<origin rpy="0 0 0" xyz="0 0 0"></origin>
			<geometry>
				<mesh filename="meshes/upper_forearm/W0.DAE"></mesh>
			</geometry>
			<material name="darkred">
				<color rgba=".5 .1 .1 1"></color>
			</material>
		</visual>
		<collision>
			<geometry>
				<sphere radius="0.063096"></sphere>
			</geometry>
			<origin xyz="0.011033 0.012755 -0.044347" rpy="0 0 0"></origin>
		</collision>
		<collision>
			<geometry>
				<sphere radius="0.063411"></sphere>
			</geometry>
			<origin xyz="-0.002953 0.015813 -0.043996999999999994" rpy="0 0 0"></origin>
		</collision>
		<collision>
			<geometry>
				<sphere radius="0.06259"></sphere>
			</geometry>
			<origin xyz="-0.013505 0.009013 -0.044323999999999995" rpy="0 0 0"></origin>
		</collision>
		<collision>
			<geometry>
				<sphere radius="0.063329"></sphere>
			</geometry>
			<origin xyz="0.0161 -0.0002 -0.043898" rpy="0 0 0"></origin>
		</collision>
		<collision>
			<geometry>
				<sphere radius="0.062721"></sphere>
			</geometry>
			<origin xyz="0.010307 -0.013343 -0.043837999999999995" rpy="0 0 0"></origin>
		</collision>
		<collision>
			<geometry>
				<sphere radius="0.054021"></sphere>
			</geometry>
			<origin xyz="-0.010275 -0.024201 -0.05312" rpy="0 0 0"></origin>
		</collision>
		<collision>
			<geometry>
				<sphere radius="0.063331"></sphere>
			</geometry>
			<origin xyz="-0.015784 -0.003139 -0.044" rpy="0 0 0"></origin>
		</collision>
		<collision>
			<geometry>
				<sphere radius="0.050984"></sphere>
			</geometry>
			<origin xyz="-0.007853 -0.025787 -0.033523" rpy="0 0 0"></origin>
		</collision>
		<inertial>
			<origin rpy="0 0 0" xyz="-0.00168 0.0046 0.13952"></origin>
			<mass value="2.24665"></mass>
			<inertia ixx="0.01667742825" ixy="0.00018403705" ixz="0.00018657629" iyy="0.01675457264" iyz="-0.00064732352" izz="0.0037463115"></inertia>
		</inertial>
	</link>
	<link name="right_upper_forearm_visual">
		<collision>
			<geometry>
				<sphere radius="0.084761"></sphere>
			</geometry>
			<origin xyz="1e-06 0.0 0.059869000000000006" rpy="0 0 0"></origin>
		</collision>
		<collision>
			<geometry>
				<sphere radius="0.069259"></sphere>
			</geometry>
			<origin xyz="-2e-06 -4e-06 0.151459" rpy="0 0 0"></origin>
		</collision>
		<collision>
			<geometry>
				<sphere radius="0.060316"></sphere>
			</geometry>
			<origin xyz="0.007559 0.020802 0.233441" rpy="0 0 0"></origin>
		</collision>
		<collision>
			<geometry>
				<sphere radius="0.065908"></sphere>
			</geometry>
			<origin xyz="0.014648 -0.002233 0.22677200000000003" rpy="0 0 0"></origin>
		</collision>
		<inertial>
			<origin rpy="0 0 0" xyz="0 0 0"></origin>
			<mass value="0.0001"></mass>
			<inertia ixx="1e-08" ixy="0" ixz="0" iyy="1e-08" iyz="0" izz="1e-08"></inertia>
		</inertial>
	</link>
	<link name="right_arm_itb">
		<inertial>
			<origin rpy="0 0 0" xyz="0.000000 0.000000 0.000000"></origin>
			<mass value="0.0001"></mass>
			<inertia ixx="1e-08" ixy="0" ixz="0" iyy="1e-08" iyz="0" izz="1e-08"></inertia>
		</inertial>
	</link>
	<link name="right_lower_forearm">
		<visual>
			<origin rpy="0 0 0" xyz="0 0 0"></origin>
			<geometry>
				<mesh filename="meshes/lower_forearm/W1.DAE"></mesh>
			</geometry>
			<material name="darkred">
				<color rgba=".5 .1 .1 1"></color>
			</material>
		</visual>
		<collision>
			<geometry>
				<sphere radius="0.071372"></sphere>
			</geometry>
			<origin xyz="-0.001758 0.009929 -1e-06" rpy="0 0 0"></origin>
		</collision>
		<collision>
			<geometry>
				<sphere radius="0.0717"></sphere>
			</geometry>
			<origin xyz="0.007732 0.006416 2e-06" rpy="0 0 0"></origin>
		</collision>
		<collision>
			<geometry>
				<sphere radius="0.065188"></sphere>
			</geometry>
			<origin xyz="0.013338 -0.008417 -0.005892" rpy="0 0 0"></origin>
		</collision>
		<collision>
			<geometry>
				<sphere radius="0.066661"></sphere>
			</geometry>
			<origin xyz="-0.01472 0.003978 -0.005016" rpy="0 0 0"></origin>
		</collision>
		<collision>
			<geometry>
				<sphere radius="0.054374"></sphere>
			</geometry>
			<origin xyz="-0.011057 -0.024192 -0.015187" rpy="0 0 0"></origin>
		</collision>
		<collision>
			<geometry>
				<sphere radius="0.066192"></sphere>
			</geometry>
			<origin xyz="-0.014692 0.003283 0.004913" rpy="0 0 0"></origin>
		</collision>
		<collision>
			<geometry>
				<sphere radius="0.056334"></sphere>
			</geometry>
			<origin xyz="-0.008327 -0.02275 0.013475" rpy="0 0 0"></origin>
		</collision>
		<collision>
			<geometry>
				<sphere radius="0.064955"></sphere>
			</geometry>
			<origin xyz="0.014034 -0.008438 0.006516" rpy="0 0 0"></origin>
		</collision>
		<inertial>
			<origin rpy="0 0 0" xyz="0.06041 0.00697 0.006"></origin>
			<mass value="1.60979"></mass>
			<inertia ixx="0.00387607152" ixy="-0.00044384784" ixz="-0.00021115038" iyy="0.00700537914" iyz="0.00015348067" izz="0.0055275524"></inertia>
		</inertial>
	</link>
	<link name="right_wrist">
		<visual>
			<origin rpy="0 0 0" xyz="0 0 0"></origin>
			<geometry>
				<mesh filename="meshes/wrist/W2.DAE"></mesh>
			</geometry>
			<material name="lightgrey">
				<color rgba=".1 .1 .1 1"></color>
			</material>
		</visual>
		<collision>
			<geometry>
				<sphere radius="0.067962"></sphere>
			</geometry>
			<origin xyz="-0.007806 0.014583 -0.037739" rpy="0 0 0"></origin>
		</collision>
		<collision>
			<geometry>
				<sphere radius="0.064893"></sphere>
			</geometry>
			<origin xyz="0.003465 0.017357 0.040089" rpy="0 0 0"></origin>
		</collision>
		<collision>
			<geometry>
				<sphere radius="0.058402"></sphere>
			</geometry>
			<origin xyz="0.022534 -0.004507 0.045374" rpy="0 0 0"></origin>
		</collision>
		<collision>
			<geometry>
				<sphere radius="0.064593"></sphere>
			</geometry>
			<origin xyz="-0.003848 -0.017787 0.040557" rpy="0 0 0"></origin>
		</collision>
		<collision>
			<geometry>
				<sphere radius="0.061956"></sphere>
			</geometry>
			<origin xyz="-0.018066 0.003592 0.040824" rpy="0 0 0"></origin>
		</collision>
		<collision>
			<geometry>
				<sphere radius="0.063813"></sphere>
			</geometry>
			<origin xyz="0.017678 0.004456 -0.040514" rpy="0 0 0"></origin>
		</collision>
		<collision>
			<geometry>
				<sphere radius="0.063075"></sphere>
			</geometry>
			<origin xyz="0.006842 -0.016509 -0.039582" rpy="0 0 0"></origin>
		</collision>
		<collision>
			<geometry>
				<sphere radius="0.057802"></sphere>
			</geometry>
			<origin xyz="-0.019502 -0.013061 -0.046032" rpy="0 0 0"></origin>
		</collision>
		<inertial>
			<origin rpy="0 0 0" xyz="0.00198 0.00125 0.01855"></origin>
			<mass value="0.35093"></mass>
			<inertia ixx="0.00025289155" ixy="0.00000575311" ixz="-0.00000159345" iyy="0.0002688601" iyz="-0.00000519818" izz="0.0003074118"></inertia>
		</inertial>
	</link>
	<link name="right_hand">
		<collision>
			<geometry>
				<sphere radius="0.034365"></sphere>
			</geometry>
			<origin xyz="0.013925 -0.009318 -0.0232" rpy="0 0 0"></origin>
		</collision>
		<collision>
			<geometry>
				<sphere radius="0.033912"></sphere>
			</geometry>
			<origin xyz="0.016625 0.004155 -0.023017" rpy="0 0 0"></origin>
		</collision>
		<collision>
			<geometry>
				<sphere radius="0.034363"></sphere>
			</geometry>
			<origin xyz="0.007126 0.016156 -0.023201" rpy="0 0 0"></origin>
		</collision>
		<collision>
			<geometry>
				<sphere radius="0.034244"></sphere>
			</geometry>
			<origin xyz="-0.009633 0.01534 -0.022934" rpy="0 0 0"></origin>
		</collision>
		<collision>
			<geometry>
				<sphere radius="0.034662"></sphere>
			</geometry>
			<origin xyz="-0.01678 -0.000689 -0.023198999999999997" rpy="0 0 0"></origin>
		</collision>
		<collision>
			<geometry>
				<sphere radius="0.034174"></sphere>
			</geometry>
			<origin xyz="-0.009349 -0.015621 -0.023427999999999997" rpy="0 0 0"></origin>
		</collision>
		<collision>
			<geometry>
				<sphere radius="0.033363"></sphere>
			</geometry>
			<origin xyz="0.004362 -0.016426 -0.023198999999999997" rpy="0 0 0"></origin>
		</collision>
		<collision>
			<geometry>
				<sphere radius="0.002744"></sphere>
			</geometry>
			<origin xyz="-0.033918 0.018085 -0.045026" rpy="0 0 0"></origin>
		</collision>
		<inertial>
			<origin rpy="0 0 0" xyz="0.01093 0.00042 -0.01532"></origin>
			<mass value="0.19125"></mass>
			<inertia ixx="0.00017588" ixy="0.00000147073" ixz="0.0000243633" iyy="0.00021166377" iyz="0.00000172689" izz="0.00023745397"></inertia>
		</inertial>
	</link>
	<link name="right_hand_camera">
		<visual>
			<origin rpy="0 0 0" xyz="0 0 0"></origin>
			<geometry>
				<cylinder length="0.01" radius="0.02"></cylinder>
			</geometry>
			<material name="blue">
				<color rgba="0 0 1 0.8"></color>
			</material>
		</visual>
		<inertial>
			<origin rpy="0 0 0" xyz="0 0 0"></origin>
			<mass value="0.0001"></mass>
			<inertia ixx="1e-08" ixy="0" ixz="0" iyy="1e-08" iyz="0" izz="1e-08"></inertia>
		</inertial>
	</link>
	<link name="right_hand_camera_axis">
		<inertial>
			<origin rpy="0 0 0" xyz="0 0 0"></origin>
			<mass value="0.0001"></mass>
			<inertia ixx="1e-08" ixy="0" ixz="0" iyy="1e-08" iyz="0" izz="1e-08"></inertia>
		</inertial>
	</link>
	<link name="right_hand_range">
		<visual>
			<origin rpy="0 0 0" xyz="0 0 0"></origin>
			<geometry>
				<box size="0.005 .02 .005"></box>
			</geometry>
			<material name="blue">
				<color rgba="0 0 1 0.8"></color>
			</material>
		</visual>
		<inertial>
			<origin rpy="0 0 0" xyz="0 0 0"></origin>
			<mass value="0.0001"></mass>
			<inertia ixx="1e-08" ixy="0" ixz="0" iyy="1e-08" iyz="0" izz="1e-08"></inertia>
		</inertial>
	</link>
	<link name="right_hand_accelerometer">
		<visual>
			<origin rpy="0 0 0" xyz="0 0 0"></origin>
			<geometry>
				<box size="0.01 0.01 0.01"></box>
			</geometry>
			<material name="black">
				<color rgba="0 0 0 1"></color>
			</material>
		</visual>
		<inertial>
			<origin rpy="0 0 0" xyz="0.000000 0.000000 0.000000"></origin>
			<mass value="0.0001"></mass>
			<inertia ixx="1e-08" ixy="0" ixz="0" iyy="1e-08" iyz="0" izz="1e-08"></inertia>
		</inertial>
	</link>
	<link name="left_arm_mount">
		<inertial>
			<origin rpy="0 0 0" xyz="0 0 0"></origin>
			<mass value="0.0001"></mass>
			<inertia ixx="1e-08" ixy="0" ixz="0" iyy="1e-08" iyz="0" izz="1e-08"></inertia>
		</inertial>
	</link>
	<link name="left_upper_shoulder">
		<visual>
			<origin rpy="0 0 0" xyz="0 0 0"></origin>
			<geometry>
				<mesh filename="meshes/upper_shoulder/S0.DAE"></mesh>
			</geometry>
			<material name="darkred">
				<color rgba=".5 .1 .1 1"></color>
			</material>
		</visual>
		<collision>
			<geometry>
				<sphere radius="0.043303"></sphere>
			</geometry>
			<origin xyz="0.01103 -0.029885 0.243103" rpy="0 0 0"></origin>
		</collision>
		<collision>
			<geometry>
				<sphere radius="0.062721"></sphere>
			</geometry>
			<origin xyz="2e-06 -0.000133 0.136805" rpy="0 0 0"></origin>
		</collision>
		<collision>
			<geometry>
				<sphere radius="0.084766"></sphere>
			</geometry>
			<origin xyz="2e-06 0.0 0.059875" rpy="0 0 0"></origin>
		</collision>
		<collision>
			<geometry>
				<sphere radius="0.055178"></sphere>
			</geometry>
			<origin xyz="-0.024348 0.000152 0.236549" rpy="0 0 0"></origin>
		</collision>
		<collision>
			<geometry>
				<sphere radius="0.084092"></sphere>
			</geometry>
			<origin xyz="0.000316 0.000763 0.21296500000000002" rpy="0 0 0"></origin>
		</collision>
		<collision>
			<geometry>
				<sphere radius="0.03722"></sphere>
			</geometry>
			<origin xyz="-0.016893 -0.032329 0.247072" rpy="0 0 0"></origin>
		</collision>
		<inertial>
			<origin rpy="0 0 0" xyz="0.01783 0.00086 0.19127"></origin>
			<mass value="5.70044"></mass>
			<inertia ixx="0.04709102262" ixy="0.00012787556" ixz="0.00614870039" iyy="0.03766976455" iyz="0.00078086899" izz="0.03595988478"></inertia>
		</inertial>
	</link>
	<link name="left_lower_shoulder">
		<visual>
			<origin rpy="0 0 0" xyz="0 0 0"></origin>
			<geometry>
				<mesh filename="meshes/lower_shoulder/S1.DAE"></mesh>
			</geometry>
			<material name="darkred">
				<color rgba=".5 .1 .1 1"></color>
			</material>
		</visual>
		<collision>
			<geometry>
				<sphere radius="0.068728"></sphere>
			</geometry>
			<origin xyz="-0.010536 0.010523 -0.014568" rpy="0 0 0"></origin>
		</collision>
		<collision>
			<geometry>
				<sphere radius="0.060101"></sphere>
			</geometry>
			<origin xyz="0.014261 0.014854 -0.0202" rpy="0 0 0"></origin>
		</collision>
		<collision>
			<geometry>
				<sphere radius="0.058701"></sphere>
			</geometry>
			<origin xyz="0.017285 -0.01473 -0.022527" rpy="0 0 0"></origin>
		</collision>
		<collision>
			<geometry>
				<sphere radius="0.061789"></sphere>
			</geometry>
			<origin xyz="-0.012972 -0.015236 -0.019432" rpy="0 0 0"></origin>
		</collision>
		<collision>
			<geometry>
				<sphere radius="0.060643"></sphere>
			</geometry>
			<origin xyz="0.018474 0.010395 0.021362" rpy="0 0 0"></origin>
		</collision>
		<collision>
			<geometry>
				<sphere radius="0.051186"></sphere>
			</geometry>
			<origin xyz="-0.010619 0.027017 0.02797" rpy="0 0 0"></origin>
		</collision>
		<collision>
			<geometry>
				<sphere radius="0.058315"></sphere>
			</geometry>
			<origin xyz="0.012425 -0.021046 0.022725" rpy="0 0 0"></origin>
		</collision>
		<collision>
			<geometry>
				<sphere radius="0.067072"></sphere>
			</geometry>
			<origin xyz="-0.014317 -0.005947 0.015587" rpy="0 0 0"></origin>
		</collision>
		<inertial>
			<origin rpy="0 0 0" xyz="0.06845 0.00269 -0.00529"></origin>
			<mass value="3.22698"></mass>
			<inertia ixx="0.01175209419" ixy="-0.00030096398" ixz="0.00207675762" iyy="0.0278859752" iyz="-0.00018821993" izz="0.02078749298"></inertia>
		</inertial>
	</link>
	<link name="left_upper_elbow">
		<visual>
			<origin rpy="0 0 0" xyz="0 0 0"></origin>
			<geometry>
				<mesh filename="meshes/upper_elbow/E0.DAE"></mesh>
			</geometry>
			<material name="darkred">
				<color rgba=".5 .1 .1 1"></color>
			</material>
		</visual>
		<collision>
			<geometry>
				<sphere radius="0.060888"></sphere>
			</geometry>
			<origin xyz="-0.020397 0.000515 -0.067403" rpy="0 0 0"></origin>
		</collision>
		<collision>
			<geometry>
				<sphere radius="0.07648"></sphere>
			</geometry>
			<origin xyz="-0.001295 -0.006457 -0.0535" rpy="0 0 0"></origin>
		</collision>
		<collision>
			<geometry>
				<sphere radius="0.076373"></sphere>
			</geometry>
			<origin xyz="0.005584 -0.003051 -0.053498" rpy="0 0 0"></origin>
		</collision>
		<collision>
			<geometry>
				<sphere radius="0.076124"></sphere>
			</geometry>
			<origin xyz="0.005319 0.003548 -0.053496999999999996" rpy="0 0 0"></origin>
		</collision>
		<collision>
			<geometry>
				<sphere radius="0.059516"></sphere>
			</geometry>
			<origin xyz="-0.00401 0.020116 -0.067416" rpy="0 0 0"></origin>
		</collision>
		<collision>
			<geometry>
				<sphere radius="0.067106"></sphere>
			</geometry>
			<origin xyz="-0.013078 -0.00344 -0.04668" rpy="0 0 0"></origin>
		</collision>
		<collision>
			<geometry>
				<sphere radius="0.067471"></sphere>
			</geometry>
			<origin xyz="-0.005768 0.014634 -0.044903" rpy="0 0 0"></origin>
		</collision>
		<inertial>
			<origin rpy="0 0 0" xyz="-0.00276 0.00132 0.18086"></origin>
			<mass value="4.31272"></mass>
			<inertia ixx="0.02661733557" ixy="0.00029270634" ixz="0.00392189887" iyy="0.02844355207" iyz="0.0010838933" izz="0.01248008322"></inertia>
		</inertial>
	</link>
	<link name="left_upper_elbow_visual">
		<collision>
			<geometry>
				<sphere radius="0.084453"></sphere>
			</geometry>
			<origin xyz="-8.1e-05 0.000408 0.05959300000000001" rpy="0 0 0"></origin>
		</collision>
		<collision>
			<geometry>
				<sphere radius="0.069876"></sphere>
			</geometry>
			<origin xyz="-1e-06 -2e-06 0.15583000000000002" rpy="0 0 0"></origin>
		</collision>
		<collision>
			<geometry>
				<sphere radius="0.064251"></sphere>
			</geometry>
			<origin xyz="0.017053 0.005156 0.230634" rpy="0 0 0"></origin>
		</collision>
		<collision>
			<geometry>
				<sphere radius="0.069072"></sphere>
			</geometry>
			<origin xyz="-0.010615 -0.009514 0.04592800000000001" rpy="0 0 0"></origin>
		</collision>
		<collision>
			<geometry>
				<sphere radius="0.074818"></sphere>
			</geometry>
			<origin xyz="0.007854 -0.004198 0.05095300000000001" rpy="0 0 0"></origin>
		</collision>
		<collision>
			<geometry>
				<sphere radius="0.066208"></sphere>
			</geometry>
			<origin xyz="-0.006123 0.015893 0.229387" rpy="0 0 0"></origin>
		</collision>
		<collision>
			<geometry>
				<sphere radius="0.070661"></sphere>
			</geometry>
			<origin xyz="-0.010126 -0.006766 0.225271" rpy="0 0 0"></origin>
		</collision>
		<collision>
			<geometry>
				<sphere radius="0.049148"></sphere>
			</geometry>
			<origin xyz="0.014514 -0.026563 0.24106" rpy="0 0 0"></origin>
		</collision>
		<inertial>
			<origin rpy="0 0 0" xyz="0 0 0"></origin>
			<mass value="0.0001"></mass>
			<inertia ixx="1e-08" ixy="0" ixz="0" iyy="1e-08" iyz="0" izz="1e-08"></inertia>
		</inertial>
	</link>
	<link name="left_lower_elbow">
		<visual>
			<origin rpy="0 0 0" xyz="0 0 0"></origin>
			<geometry>
				<mesh filename="meshes/lower_elbow/E1.DAE"></mesh>
			</geometry>
			<material name="darkred">
				<color rgba=".5 .1 .1 1"></color>
			</material>
		</visual>
		<collision>
			<geometry>
				<sphere radius="0.071372"></sphere>
			</geometry>
			<origin xyz="-0.001758 0.009929 -1e-06" rpy="0 0 0"></origin>
		</collision>
		<collision>
			<geometry>
				<sphere radius="0.0717"></sphere>
			</geometry>
			<origin xyz="0.007732 0.006416 2e-06" rpy="0 0 0"></origin>
		</collision>
		<collision>
			<geometry>
				<sphere radius="0.065188"></sphere>
			</geometry>
			<origin xyz="0.013338 -0.008417 -0.005892" rpy="0 0 0"></origin>
		</collision>
		<collision>
			<geometry>
				<sphere radius="0.066661"></sphere>
			</geometry>
			<origin xyz="-0.01472 0.003978 -0.005016" rpy="0 0 0"></origin>
		</collision>
		<collision>
			<geometry>
				<sphere radius="0.054374"></sphere>
			</geometry>
			<origin xyz="-0.011057 -0.024192 -0.015187" rpy="0 0 0"></origin>
		</collision>
		<collision>
			<geometry>
				<sphere radius="0.066192"></sphere>
			</geometry>
			<origin xyz="-0.014692 0.003283 0.004913" rpy="0 0 0"></origin>
		</collision>
		<collision>
			<geometry>
				<sphere radius="0.056334"></sphere>
			</geometry>
			<origin xyz="-0.008327 -0.02275 0.013475" rpy="0 0 0"></origin>
		</collision>
		<collision>
			<geometry>
				<sphere radius="0.064955"></sphere>
			</geometry>
			<origin xyz="0.014034 -0.008438 0.006516" rpy="0 0 0"></origin>
		</collision>
		<inertial>
			<origin rpy="0 0 0" xyz="0.02611 0.00159 -0.01117"></origin>
			<mass value="2.07206"></mass>
			<inertia ixx="0.00711582686" ixy="0.00036036173" ixz="0.0007459496" iyy="0.01318227876" iyz="-0.00019663418" izz="0.00926852064"></inertia>
		</inertial>
	</link>
	<link name="left_upper_forearm">
		<visual>
			<origin rpy="0 0 0" xyz="0 0 0"></origin>
			<geometry>
				<mesh filename="meshes/upper_forearm/W0.DAE"></mesh>
			</geometry>
			<material name="darkred">
				<color rgba=".5 .1 .1 1"></color>
			</material>
		</visual>
		<collision>
			<geometry>
				<sphere radius="0.063096"></sphere>
			</geometry>
			<origin xyz="0.011033 0.012755 -0.044347" rpy="0 0 0"></origin>
		</collision>
		<collision>
			<geometry>
				<sphere radius="0.063411"></sphere>
			</geometry>
			<origin xyz="-0.002953 0.015813 -0.043996999999999994" rpy="0 0 0"></origin>
		</collision>
		<collision>
			<geometry>
				<sphere radius="0.06259"></sphere>
			</geometry>
			<origin xyz="-0.013505 0.009013 -0.044323999999999995" rpy="0 0 0"></origin>
		</collision>
		<collision>
			<geometry>
				<sphere radius="0.063329"></sphere>
			</geometry>
			<origin xyz="0.0161 -0.0002 -0.043898" rpy="0 0 0"></origin>
		</collision>
		<collision>
			<geometry>
				<sphere radius="0.062721"></sphere>
			</geometry>
			<origin xyz="0.010307 -0.013343 -0.043837999999999995" rpy="0 0 0"></origin>
		</collision>
		<collision>
			<geometry>
				<sphere radius="0.054021"></sphere>
			</geometry>
			<origin xyz="-0.010275 -0.024201 -0.05312" rpy="0 0 0"></origin>
		</collision>
		<collision>
			<geometry>
				<sphere radius="0.063331"></sphere>
			</geometry>
			<origin xyz="-0.015784 -0.003139 -0.044" rpy="0 0 0"></origin>
		</collision>
		<collision>
			<geometry>
				<sphere radius="0.050984"></sphere>
			</geometry>
			<origin xyz="-0.007853 -0.025787 -0.033523" rpy="0 0 0"></origin>
		</collision>
		<inertial>
			<origin rpy="0 0 0" xyz="-0.00168 0.0046 0.13952"></origin>
			<mass value="2.24665"></mass>
			<inertia ixx="0.01667742825" ixy="0.00018403705" ixz="0.00018657629" iyy="0.01675457264" iyz="-0.00064732352" izz="0.0037463115"></inertia>
		</inertial>
	</link>
	<link name="left_upper_forearm_visual">
		<collision>
			<geometry>
				<sphere radius="0.084761"></sphere>
			</geometry>
			<origin xyz="1e-06 0.0 0.059869000000000006" rpy="0 0 0"></origin>
		</collision>
		<collision>
			<geometry>
				<sphere radius="0.069259"></sphere>
			</geometry>
			<origin xyz="-2e-06 -4e-06 0.151459" rpy="0 0 0"></origin>
		</collision>
		<collision>
			<geometry>
				<sphere radius="0.060316"></sphere>
			</geometry>
			<origin xyz="0.007559 0.020802 0.233441" rpy="0 0 0"></origin>
		</collision>
		<collision>
			<geometry>
				<sphere radius="0.065908"></sphere>
			</geometry>
			<origin xyz="0.014648 -0.002233 0.22677200000000003" rpy="0 0 0"></origin>
		</collision>
		<inertial>
			<origin rpy="0 0 0" xyz="0 0 0"></origin>
			<mass value="0.0001"></mass>
			<inertia ixx="1e-08" ixy="0" ixz="0" iyy="1e-08" iyz="0" izz="1e-08"></inertia>
		</inertial>
	</link>
	<link name="left_arm_itb">
		<inertial>
			<origin rpy="0 0 0" xyz="0.000000 0.000000 0.000000"></origin>
			<mass value="0.0001"></mass>
			<inertia ixx="1e-08" ixy="0" ixz="0" iyy="1e-08" iyz="0" izz="1e-08"></inertia>
		</inertial>
	</link>
	<link name="left_lower_forearm">
		<visual>
			<origin rpy="0 0 0" xyz="0 0 0"></origin>
			<geometry>
				<mesh filename="meshes/lower_forearm/W1.DAE"></mesh>
			</geometry>
			<material name="darkred">
				<color rgba=".5 .1 .1 1"></color>
			</material>
		</visual>
		<collision>
			<geometry>
				<sphere radius="0.071372"></sphere>
			</geometry>
			<origin xyz="-0.001758 0.009929 -1e-06" rpy="0 0 0"></origin>
		</collision>
		<collision>
			<geometry>
				<sphere radius="0.0717"></sphere>
			</geometry>
			<origin xyz="0.007732 0.006416 2e-06" rpy="0 0 0"></origin>
		</collision>
		<collision>
			<geometry>
				<sphere radius="0.065188"></sphere>
			</geometry>
			<origin xyz="0.013338 -0.008417 -0.005892" rpy="0 0 0"></origin>
		</collision>
		<collision>
			<geometry>
				<sphere radius="0.066661"></sphere>
			</geometry>
			<origin xyz="-0.01472 0.003978 -0.005016" rpy="0 0 0"></origin>
		</collision>
		<collision>
			<geometry>
				<sphere radius="0.054374"></sphere>
			</geometry>
			<origin xyz="-0.011057 -0.024192 -0.015187" rpy="0 0 0"></origin>
		</collision>
		<collision>
			<geometry>
				<sphere radius="0.066192"></sphere>
			</geometry>
			<origin xyz="-0.014692 0.003283 0.004913" rpy="0 0 0"></origin>
		</collision>
		<collision>
			<geometry>
				<sphere radius="0.056334"></sphere>
			</geometry>
			<origin xyz="-0.008327 -0.02275 0.013475" rpy="0 0 0"></origin>
		</collision>
		<collision>
			<geometry>
				<sphere radius="0.064955"></sphere>
			</geometry>
			<origin xyz="0.014034 -0.008438 0.006516" rpy="0 0 0"></origin>
		</collision>
		<inertial>
			<origin rpy="0 0 0" xyz="0.06041 0.00697 0.006"></origin>
			<mass value="1.60979"></mass>
			<inertia ixx="0.00387607152" ixy="-0.00044384784" ixz="-0.00021115038" iyy="0.00700537914" iyz="0.00015348067" izz="0.0055275524"></inertia>
		</inertial>
	</link>
	<link name="left_wrist">
		<visual>
			<origin rpy="0 0 0" xyz="0 0 0"></origin>
			<geometry>
				<mesh filename="meshes/wrist/W2.DAE"></mesh>
			</geometry>
			<material name="lightgrey">
				<color rgba=".1 .1 .1 1"></color>
			</material>
		</visual>
		<collision>
			<geometry>
				<sphere radius="0.067962"></sphere>
			</geometry>
			<origin xyz="-0.007806 0.014583 -0.037739" rpy="0 0 0"></origin>
		</collision>
		<collision>
			<geometry>
				<sphere radius="0.064893"></sphere>
			</geometry>
			<origin xyz="0.003465 0.017357 0.040089" rpy="0 0 0"></origin>
		</collision>
		<collision>
			<geometry>
				<sphere radius="0.058402"></sphere>
			</geometry>
			<origin xyz="0.022534 -0.004507 0.045374" rpy="0 0 0"></origin>
		</collision>
		<collision>
			<geometry>
				<sphere radius="0.064593"></sphere>
			</geometry>
			<origin xyz="-0.003848 -0.017787 0.040557" rpy="0 0 0"></origin>
		</collision>
		<collision>
			<geometry>
				<sphere radius="0.061956"></sphere>
			</geometry>
			<origin xyz="-0.018066 0.003592 0.040824" rpy="0 0 0"></origin>
		</collision>
		<collision>
			<geometry>
				<sphere radius="0.063813"></sphere>
			</geometry>
			<origin xyz="0.017678 0.004456 -0.040514" rpy="0 0 0"></origin>
		</collision>
		<collision>
			<geometry>
				<sphere radius="0.063075"></sphere>
			</geometry>
			<origin xyz="0.006842 -0.016509 -0.039582" rpy="0 0 0"></origin>
		</collision>
		<collision>
			<geometry>
				<sphere radius="0.057802"></sphere>
			</geometry>
			<origin xyz="-0.019502 -0.013061 -0.046032" rpy="0 0 0"></origin>
		</collision>
		<inertial>
			<origin rpy="0 0 0" xyz="0.00198 0.00125 0.01855"></origin>
			<mass value="0.35093"></mass>
			<inertia ixx="0.00025289155" ixy="0.00000575311" ixz="-0.00000159345" iyy="0.0002688601" iyz="-0.00000519818" izz="0.0003074118"></inertia>
		</inertial>
	</link>
	<link name="left_hand">
		<collision>
			<geometry>
				<sphere radius="0.034365"></sphere>
			</geometry>
			<origin xyz="0.013925 -0.009318 -0.0232" rpy="0 0 0"></origin>
		</collision>
		<collision>
			<geometry>
				<sphere radius="0.033912"></sphere>
			</geometry>
			<origin xyz="0.016625 0.004155 -0.023017" rpy="0 0 0"></origin>
		</collision>
		<collision>
			<geometry>
				<sphere radius="0.034363"></sphere>
			</geometry>
			<origin xyz="0.007126 0.016156 -0.023201" rpy="0 0 0"></origin>
		</collision>
		<collision>
			<geometry>
				<sphere radius="0.034244"></sphere>
			</geometry>
			<origin xyz="-0.009633 0.01534 -0.022934" rpy="0 0 0"></origin>
		</collision>
		<collision>
			<geometry>
				<sphere radius="0.034662"></sphere>
			</geometry>
			<origin xyz="-0.01678 -0.000689 -0.023198999999999997" rpy="0 0 0"></origin>
		</collision>
		<collision>
			<geometry>
				<sphere radius="0.034174"></sphere>
			</geometry>
			<origin xyz="-0.009349 -0.015621 -0.023427999999999997" rpy="0 0 0"></origin>
		</collision>
		<collision>
			<geometry>
				<sphere radius="0.033363"></sphere>
			</geometry>
			<origin xyz="0.004362 -0.016426 -0.023198999999999997" rpy="0 0 0"></origin>
		</collision>
		<collision>
			<geometry>
				<sphere radius="0.002744"></sphere>
			</geometry>
			<origin xyz="-0.033918 0.018085 -0.045026" rpy="0 0 0"></origin>
		</collision>
		<inertial>
			<origin rpy="0 0 0" xyz="0.01093 0.00042 -0.01532"></origin>
			<mass value="0.19125"></mass>
			<inertia ixx="0.00017588" ixy="0.00000147073" ixz="0.0000243633" iyy="0.00021166377" iyz="0.00000172689" izz="0.00023745397"></inertia>
		</inertial>
	</link>
	<link name="left_hand_camera">
		<visual>
			<origin rpy="0 0 0" xyz="0 0 0"></origin>
			<geometry>
				<cylinder length="0.01" radius="0.02"></cylinder>
			</geometry>
			<material name="blue">
				<color rgba="0 0 1 0.8"></color>
			</material>
		</visual>
		<inertial>
			<origin rpy="0 0 0" xyz="0 0 0"></origin>
			<mass value="0.0001"></mass>
			<inertia ixx="1e-08" ixy="0" ixz="0" iyy="1e-08" iyz="0" izz="1e-08"></inertia>
		</inertial>
	</link>
	<link name="left_hand_camera_axis">
		<inertial>
			<origin rpy="0 0 0" xyz="0 0 0"></origin>
			<mass value="0.0001"></mass>
			<inertia ixx="1e-08" ixy="0" ixz="0" iyy="1e-08" iyz="0" izz="1e-08"></inertia>
		</inertial>
	</link>
	<link name="left_hand_range">
		<visual>
			<origin rpy="0 0 0" xyz="0 0 0"></origin>
			<geometry>
				<box size="0.005 .02 .005"></box>
			</geometry>
			<material name="blue">
				<color rgba="0 0 1 0.8"></color>
			</material>
		</visual>
		<inertial>
			<origin rpy="0 0 0" xyz="0 0 0"></origin>
			<mass value="0.0001"></mass>
			<inertia ixx="1e-08" ixy="0" ixz="0" iyy="1e-08" iyz="0" izz="1e-08"></inertia>
		</inertial>
	</link>
	<link name="left_hand_accelerometer">
		<visual>
			<origin rpy="0 0 0" xyz="0 0 0"></origin>
			<geometry>
				<box size="0.01 0.01 0.01"></box>
			</geometry>
			<material name="black">
				<color rgba="0 0 0 1"></color>
			</material>
		</visual>
		<inertial>
			<origin rpy="0 0 0" xyz="0.000000 0.000000 0.000000"></origin>
			<mass value="0.0001"></mass>
			<inertia ixx="1e-08" ixy="0" ixz="0" iyy="1e-08" iyz="0" izz="1e-08"></inertia>
		</inertial>
	</link>
	<link name="pedestal">
		<visual>
			<origin rpy="0 0 0" xyz="0 0 0"></origin>
			<geometry>
				<mesh filename="meshes/base/PEDESTAL.DAE"></mesh>
			</geometry>
			<material name="darkgray">
				<color rgba=".2 .2 .2 1"></color>
			</material>
		</visual>
		<collision>
			<geometry>
				<sphere radius="0.227033"></sphere>
			</geometry>
			<origin xyz="0.31577995635708034 0.2960545654099008 -0.7485481291821219" rpy="0 0 0"></origin>
		</collision>
		<collision>
			<geometry>
				<sphere radius="0.203407"></sphere>
			</geometry>
			<origin xyz="-0.4182720436429197 0.2771935654099008 -0.7887991291821219" rpy="0 0 0"></origin>
		</collision>
		<collision>
			<geometry>
				<sphere radius="0.222076"></sphere>
			</geometry>
			<origin xyz="0.31815095635708035 -0.29108843459009914 -0.7546941291821219" rpy="0 0 0"></origin>
		</collision>
		<collision>
			<geometry>
				<sphere radius="0.311326"></sphere>
			</geometry>
			<origin xyz="0.013137956357080316 -0.001972434590099168 -0.5749281291821219" rpy="0 0 0"></origin>
		</collision>
		<collision>
			<geometry>
				<sphere radius="0.243769"></sphere>
			</geometry>
			<origin xyz="-0.0016370436429196805 -0.001215434590099168 -0.20390512918212195" rpy="0 0 0"></origin>
		</collision>
		<collision>
			<geometry>
				<sphere radius="0.201193"></sphere>
			</geometry>
			<origin xyz="-0.24104704364291968 0.13662956540990084 -0.7007821291821219" rpy="0 0 0"></origin>
		</collision>
		<collision>
			<geometry>
				<sphere radius="0.201528"></sphere>
			</geometry>
			<origin xyz="-0.2982870436429197 -0.19986443459009917 -0.7199951291821219" rpy="0 0 0"></origin>
		</collision>
		<collision>
			<geometry>
				<sphere radius="0.191758"></sphere>
			</geometry>
			<origin xyz="-0.4177810436429197 -0.28897543459009917 -0.7897691291821219" rpy="0 0 0"></origin>
		</collision>
		<inertial>
			<origin rpy="0 0 0" xyz="0 0 0"></origin>
			<mass value="60.86397744"></mass>
			<inertia ixx="5.0635929" ixy="0.00103417" ixz="0.80199628" iyy="6.08689388" iyz="0.00105311" izz="4.96191932"></inertia>
		</inertial>
	</link>
	<link name="left_gripper_base">
		<visual>
			<origin rpy="-1.5707963267948966 3.141592653589793 0" xyz="0 0 0"></origin>
			<geometry>
				<mesh filename="meshes/electric_gripper/electric_gripper_base.DAE"></mesh>
			</geometry>
		</visual>
		<collision>
			<geometry>
				<sphere radius="0.037214"></sphere>
			</geometry>
			<origin xyz="-0.002743 -0.02433 -0.002197" rpy="0 0 0"></origin>
		</collision>
		<collision>
			<geometry>
				<sphere radius="0.03779"></sphere>
			</geometry>
			<origin xyz="0.00095 0.023534 0.00229" rpy="0 0 0"></origin>
		</collision>
		<collision>
			<geometry>
				<sphere radius="0.035109"></sphere>
			</geometry>
			<origin xyz="0.005025 -0.026362 -0.003037" rpy="0 0 0"></origin>
		</collision>
		<collision>
			<geometry>
				<sphere radius="0.034411"></sphere>
			</geometry>
			<origin xyz="-0.002217 -0.026827 0.00534" rpy="0 0 0"></origin>
		</collision>
		<collision>
			<geometry>
				<sphere radius="0.037912"></sphere>
			</geometry>
			<origin xyz="0.002124 -0.023192 0.001243" rpy="0 0 0"></origin>
		</collision>
		<collision>
			<geometry>
				<sphere radius="0.03552"></sphere>
			</geometry>
			<origin xyz="-0.004819 0.025908 0.001467" rpy="0 0 0"></origin>
		</collision>
		<collision>
			<geometry>
				<sphere radius="0.033791"></sphere>
			</geometry>
			<origin xyz="-0.001602 0.026488 -0.005285" rpy="0 0 0"></origin>
		</collision>
		<collision>
			<geometry>
				<sphere radius="0.033432"></sphere>
			</geometry>
			<origin xyz="0.006387 0.027575 -0.002449" rpy="0 0 0"></origin>
		</collision>
		<inertial>
			<origin rpy="-1.5707963267948966 3.141592653589793 0" xyz="0.0 0.0 0.0"></origin>
			<mass value="0.3"></mass>
			<inertia ixx="2e-08" ixy="0" ixz="0" iyy="3e-08" iyz="0" izz="2e-08"></inertia>
		</inertial>
	</link>
	<link name="l_gripper_l_finger_2">
		<collision>
			<geometry>
				<sphere radius="0.00988"></sphere>
			</geometry>
			<origin xyz="-0.005001 -0.0211 0.011801000000000002" rpy="0 0 0"></origin>
		</collision>
		<collision>
			<geometry>
				<sphere radius="0.009587"></sphere>
			</geometry>
			<origin xyz="-0.005 -0.021528 0.004800000000000002" rpy="0 0 0"></origin>
		</collision>
		<collision>
			<geometry>
				<sphere radius="0.009586"></sphere>
			</geometry>
			<origin xyz="-0.005 -0.007057999999999999 0.011801000000000002" rpy="0 0 0"></origin>
		</collision>
		<collision>
			<geometry>
				<sphere radius="0.009336"></sphere>
			</geometry>
			<origin xyz="-0.005 -0.008204 0.004800000000000002" rpy="0 0 0"></origin>
		</collision>
		<collision>
			<geometry>
				<sphere radius="0.008735"></sphere>
			</geometry>
			<origin xyz="-0.005 0.004631000000000001 0.011400000000000002" rpy="0 0 0"></origin>
		</collision>
		<collision>
			<geometry>
				<sphere radius="0.009262"></sphere>
			</geometry>
			<origin xyz="-0.005 0.016018 0.011800000000000001" rpy="0 0 0"></origin>
		</collision>
		<collision>
			<geometry>
				<sphere radius="0.009008"></sphere>
			</geometry>
			<origin xyz="-0.005 0.016419 0.004800000000000002" rpy="0 0 0"></origin>
		</collision>
		<collision>
			<geometry>
				<sphere radius="0.009148"></sphere>
			</geometry>
			<origin xyz="-0.005 0.004458000000000001 0.004800000000000002" rpy="0 0 0"></origin>
		</collision>
	</link>
	<link name="l_gripper_l_finger">
		<visual>
			<origin rpy="0 0 -3.141592653589793" xyz="0 0 0"></origin>
			<geometry>
				<mesh filename="meshes/electric_gripper/fingers/extended_narrow.DAE"></mesh>
			</geometry>
		</visual>
		<collision>
			<geometry>
				<sphere radius="0.011156"></sphere>
			</geometry>
			<origin xyz="0.0 0.017272000000000003 0.012470999999999996" rpy="0 0 0"></origin>
		</collision>
		<collision>
			<geometry>
				<sphere radius="0.010845"></sphere>
			</geometry>
			<origin xyz="0.0 0.016720000000000002 0.027095" rpy="0 0 0"></origin>
		</collision>
		<collision>
			<geometry>
				<sphere radius="0.010842"></sphere>
			</geometry>
			<origin xyz="-1e-06 0.017738 0.041727" rpy="0 0 0"></origin>
		</collision>
		<collision>
			<geometry>
				<sphere radius="0.011156"></sphere>
			</geometry>
			<origin xyz="0.0 0.017246 0.05629" rpy="0 0 0"></origin>
		</collision>
		<collision>
			<geometry>
				<sphere radius="0.010823"></sphere>
			</geometry>
			<origin xyz="0.0 0.016683 0.070884" rpy="0 0 0"></origin>
		</collision>
		<collision>
			<geometry>
				<sphere radius="0.010259"></sphere>
			</geometry>
			<origin xyz="0.0 0.018101000000000003 0.083924" rpy="0 0 0"></origin>
		</collision>
		<collision>
			<geometry>
				<sphere radius="0.011128"></sphere>
			</geometry>
			<origin xyz="0.0 0.01726 0.11055999999999999" rpy="0 0 0"></origin>
		</collision>
		<collision>
			<geometry>
				<sphere radius="0.010523"></sphere>
			</geometry>
			<origin xyz="0.0 0.016764 0.09643199999999999" rpy="0 0 0"></origin>
		</collision>
		<inertial>
			<origin rpy="0 0 -3.141592653589793" xyz="0 0 0"></origin>
			<mass value="0.02"></mass>
			<inertia ixx="0.01" ixy="0" ixz="0" iyy="0.01" iyz="0" izz="0.01"></inertia>
		</inertial>
	</link>
	<link name="l_gripper_l_finger_tip">
		<visual>
			<origin rpy="0 0 3.141592653589793" xyz="0 0 0"></origin>
			<geometry>
				<mesh filename="meshes/electric_gripper/fingers/paddle_tip.DAE"></mesh>
			</geometry>
		</visual>
		<collision>
			<geometry>
				<sphere radius="0.010397"></sphere>
			</geometry>
			<origin xyz="-0.012828 -0.0045 -0.027955" rpy="0 0 0"></origin>
		</collision>
		<collision>
			<geometry>
				<sphere radius="0.010331"></sphere>
			</geometry>
			<origin xyz="-0.014696 -0.0045 -0.014481" rpy="0 0 0"></origin>
		</collision>
		<collision>
			<geometry>
				<sphere radius="0.010733"></sphere>
			</geometry>
			<origin xyz="0.000442 -0.0045 -0.024381" rpy="0 0 0"></origin>
		</collision>
		<collision>
			<geometry>
				<sphere radius="0.010572"></sphere>
			</geometry>
			<origin xyz="0.013286 -0.0045 -0.027079" rpy="0 0 0"></origin>
		</collision>
		<collision>
			<geometry>
				<sphere radius="0.010587"></sphere>
			</geometry>
			<origin xyz="0.012946 -0.0045 -0.013796000000000001" rpy="0 0 0"></origin>
		</collision>
		<collision>
			<geometry>
				<sphere radius="0.01062"></sphere>
			</geometry>
			<origin xyz="-0.002403 -0.0045 -0.004787000000000001" rpy="0 0 0"></origin>
		</collision>
		<collision>
			<geometry>
				<sphere radius="0.010654"></sphere>
			</geometry>
			<origin xyz="0.012386 -0.0045 -0.0018600000000000005" rpy="0 0 0"></origin>
		</collision>
		<collision>
			<geometry>
				<sphere radius="0.008656"></sphere>
			</geometry>
			<origin xyz="-0.014807 -0.0045 -0.0016010000000000017" rpy="0 0 0"></origin>
		</collision>
		<inertial>
			<origin rpy="0 0 3.141592653589793" xyz="0 0 0"></origin>
			<mass value="0.01"></mass>
			<inertia ixx="0.01" ixy="0" ixz="0" iyy="0.01" iyz="0" izz="0.01"></inertia>
		</inertial>
	</link>
	<link name="l_gripper_r_finger_2">
		<collision>
			<geometry>
				<sphere radius="0.009249"></sphere>
			</geometry>
			<origin xyz="0.005 0.022039 0.004800000000000002" rpy="0 0 0"></origin>
		</collision>
		<collision>
			<geometry>
				<sphere radius="0.009498"></sphere>
			</geometry>
			<origin xyz="0.005 0.021657 0.011801000000000002" rpy="0 0 0"></origin>
		</collision>
		<collision>
			<geometry>
				<sphere radius="0.009206"></sphere>
			</geometry>
			<origin xyz="0.00518 0.008937999999999998 0.011980000000000001" rpy="0 0 0"></origin>
		</collision>
		<collision>
			<geometry>
				<sphere radius="0.009334"></sphere>
			</geometry>
			<origin xyz="0.005 0.009222999999999999 0.004799000000000001" rpy="0 0 0"></origin>
		</collision>
		<collision>
			<geometry>
				<sphere radius="0.00935"></sphere>
			</geometry>
			<origin xyz="0.005 -0.0037490000000000006 0.011800000000000001" rpy="0 0 0"></origin>
		</collision>
		<collision>
			<geometry>
				<sphere radius="0.009146"></sphere>
			</geometry>
			<origin xyz="0.005 -0.0162 0.011800000000000001" rpy="0 0 0"></origin>
		</collision>
		<collision>
			<geometry>
				<sphere radius="0.009587"></sphere>
			</geometry>
			<origin xyz="0.005 -0.004104000000000001 0.004800000000000002" rpy="0 0 0"></origin>
		</collision>
		<collision>
			<geometry>
				<sphere radius="0.008855"></sphere>
			</geometry>
			<origin xyz="0.005 -0.016669 0.004799000000000001" rpy="0 0 0"></origin>
		</collision>
	</link>
	<link name="l_gripper_r_finger">
		<visual>
			<origin rpy="0 0 -0.0" xyz="0 0 0"></origin>
			<geometry>
				<mesh filename="meshes/electric_gripper/fingers/extended_narrow.DAE"></mesh>
			</geometry>
		</visual>
		<collision>
			<geometry>
				<sphere radius="0.01082"></sphere>
			</geometry>
			<origin xyz="0.0 -0.017263 0.111043" rpy="0 0 0"></origin>
		</collision>
		<collision>
			<geometry>
				<sphere radius="0.011128"></sphere>
			</geometry>
			<origin xyz="0.0 -0.01725 0.09595200000000001" rpy="0 0 0"></origin>
		</collision>
		<collision>
			<geometry>
				<sphere radius="0.010846"></sphere>
			</geometry>
			<origin xyz="0.0 -0.017779000000000003 0.081315" rpy="0 0 0"></origin>
		</collision>
		<collision>
			<geometry>
				<sphere radius="0.010842"></sphere>
			</geometry>
			<origin xyz="0.0 -0.016763 0.066754" rpy="0 0 0"></origin>
		</collision>
		<collision>
			<geometry>
				<sphere radius="0.010846"></sphere>
			</geometry>
			<origin xyz="0.0 -0.017782000000000003 0.052121" rpy="0 0 0"></origin>
		</collision>
		<collision>
			<geometry>
				<sphere radius="0.010842"></sphere>
			</geometry>
			<origin xyz="0.0 -0.016765000000000002 0.037557999999999994" rpy="0 0 0"></origin>
		</collision>
		<collision>
			<geometry>
				<sphere radius="0.010819"></sphere>
			</geometry>
			<origin xyz="0.0 -0.017774 0.02296" rpy="0 0 0"></origin>
		</collision>
		<collision>
			<geometry>
				<sphere radius="0.009909"></sphere>
			</geometry>
			<origin xyz="0.0 -0.017230000000000002 0.01038" rpy="0 0 0"></origin>
		</collision>
		<inertial>
			<origin rpy="0 0 -0.0" xyz="0 0 0"></origin>
			<mass value="0.02"></mass>
			<inertia ixx="0.01" ixy="0" ixz="0" iyy="0.01" iyz="0" izz="0.01"></inertia>
		</inertial>
	</link>
	<link name="l_gripper_r_finger_tip">
		<visual>
			<origin rpy="0 0 0.0" xyz="0 0 0"></origin>
			<geometry>
				<mesh filename="meshes/electric_gripper/fingers/paddle_tip.DAE"></mesh>
			</geometry>
		</visual>
		<collision>
			<geometry>
				<sphere radius="0.009723"></sphere>
			</geometry>
			<origin xyz="0.012827 0.0045 -0.0006450000000000015" rpy="0 0 0"></origin>
		</collision>
		<collision>
			<geometry>
				<sphere radius="0.008818"></sphere>
			</geometry>
			<origin xyz="0.01706 0.0045 -0.012623" rpy="0 0 0"></origin>
		</collision>
		<collision>
			<geometry>
				<sphere radius="0.009028"></sphere>
			</geometry>
			<origin xyz="-0.002469 0.0045 -0.029756" rpy="0 0 0"></origin>
		</collision>
		<collision>
			<geometry>
				<sphere radius="0.010781"></sphere>
			</geometry>
			<origin xyz="-0.015496 0.0045 -0.005163000000000001" rpy="0 0 0"></origin>
		</collision>
		<collision>
			<geometry>
				<sphere radius="0.011412"></sphere>
			</geometry>
			<origin xyz="-0.015692 0.0045 -0.023934" rpy="0 0 0"></origin>
		</collision>
		<collision>
			<geometry>
				<sphere radius="0.01076"></sphere>
			</geometry>
			<origin xyz="0.01327 0.0045 -0.026758" rpy="0 0 0"></origin>
		</collision>
		<collision>
			<geometry>
				<sphere radius="0.008593"></sphere>
			</geometry>
			<origin xyz="-0.002594 0.0045 -0.0003880000000000012" rpy="0 0 0"></origin>
		</collision>
		<collision>
			<geometry>
				<sphere radius="0.010362"></sphere>
			</geometry>
			<origin xyz="0.000217 0.0044989999999999995 -0.014134" rpy="0 0 0"></origin>
		</collision>
		<inertial>
			<origin rpy="0 0 0.0" xyz="0 0 0"></origin>
			<mass value="0.01"></mass>
			<inertia ixx="0.01" ixy="0" ixz="0" iyy="0.01" iyz="0" izz="0.01"></inertia>
		</inertial>
	</link>
	<link name="left_gripper">
		<inertial>
			<origin rpy="0 0 0" xyz="0 0 0"></origin>
			<mass value="0.0001"></mass>
			<inertia ixx="0" ixy="0" ixz="0" iyy="0" iyz="0" izz="0.0"></inertia>
		</inertial>
	</link>
	<link name="right_gripper_base">
		<visual>
			<origin rpy="-1.5707963267948966 3.141592653589793 0" xyz="0 0 0"></origin>
			<geometry>
				<mesh filename="meshes/electric_gripper/electric_gripper_base.DAE"></mesh>
			</geometry>
		</visual>
		<collision>
			<geometry>
				<sphere radius="0.037214"></sphere>
			</geometry>
			<origin xyz="-0.002743 -0.02433 -0.002197" rpy="0 0 0"></origin>
		</collision>
		<collision>
			<geometry>
				<sphere radius="0.03779"></sphere>
			</geometry>
			<origin xyz="0.00095 0.023534 0.00229" rpy="0 0 0"></origin>
		</collision>
		<collision>
			<geometry>
				<sphere radius="0.035109"></sphere>
			</geometry>
			<origin xyz="0.005025 -0.026362 -0.003037" rpy="0 0 0"></origin>
		</collision>
		<collision>
			<geometry>
				<sphere radius="0.034411"></sphere>
			</geometry>
			<origin xyz="-0.002217 -0.026827 0.00534" rpy="0 0 0"></origin>
		</collision>
		<collision>
			<geometry>
				<sphere radius="0.037912"></sphere>
			</geometry>
			<origin xyz="0.002124 -0.023192 0.001243" rpy="0 0 0"></origin>
		</collision>
		<collision>
			<geometry>
				<sphere radius="0.03552"></sphere>
			</geometry>
			<origin xyz="-0.004819 0.025908 0.001467" rpy="0 0 0"></origin>
		</collision>
		<collision>
			<geometry>
				<sphere radius="0.033791"></sphere>
			</geometry>
			<origin xyz="-0.001602 0.026488 -0.005285" rpy="0 0 0"></origin>
		</collision>
		<collision>
			<geometry>
				<sphere radius="0.033432"></sphere>
			</geometry>
			<origin xyz="0.006387 0.027575 -0.002449" rpy="0 0 0"></origin>
		</collision>
		<inertial>
			<origin rpy="-1.5707963267948966 3.141592653589793 0" xyz="0.0 0.0 0.0"></origin>
			<mass value="0.3"></mass>
			<inertia ixx="2e-08" ixy="0" ixz="0" iyy="3e-08" iyz="0" izz="2e-08"></inertia>
		</inertial>
	</link>
	<link name="r_gripper_l_finger_2">
		<collision>
			<geometry>
				<sphere radius="0.00988"></sphere>
			</geometry>
			<origin xyz="-0.005001 -0.0211 0.011801000000000002" rpy="0 0 0"></origin>
		</collision>
		<collision>
			<geometry>
				<sphere radius="0.009587"></sphere>
			</geometry>
			<origin xyz="-0.005 -0.021528 0.004800000000000002" rpy="0 0 0"></origin>
		</collision>
		<collision>
			<geometry>
				<sphere radius="0.009586"></sphere>
			</geometry>
			<origin xyz="-0.005 -0.007057999999999999 0.011801000000000002" rpy="0 0 0"></origin>
		</collision>
		<collision>
			<geometry>
				<sphere radius="0.009336"></sphere>
			</geometry>
			<origin xyz="-0.005 -0.008204 0.004800000000000002" rpy="0 0 0"></origin>
		</collision>
		<collision>
			<geometry>
				<sphere radius="0.008735"></sphere>
			</geometry>
			<origin xyz="-0.005 0.004631000000000001 0.011400000000000002" rpy="0 0 0"></origin>
		</collision>
		<collision>
			<geometry>
				<sphere radius="0.009262"></sphere>
			</geometry>
			<origin xyz="-0.005 0.016018 0.011800000000000001" rpy="0 0 0"></origin>
		</collision>
		<collision>
			<geometry>
				<sphere radius="0.009008"></sphere>
			</geometry>
			<origin xyz="-0.005 0.016419 0.004800000000000002" rpy="0 0 0"></origin>
		</collision>
		<collision>
			<geometry>
				<sphere radius="0.009148"></sphere>
			</geometry>
			<origin xyz="-0.005 0.004458000000000001 0.004800000000000002" rpy="0 0 0"></origin>
		</collision>
	</link>
	<link name="r_gripper_l_finger">
		<visual>
			<origin rpy="0 0 -3.141592653589793" xyz="0 0 0"></origin>
			<geometry>
				<mesh filename="meshes/electric_gripper/fingers/extended_narrow.DAE"></mesh>
			</geometry>
		</visual>
		<collision>
			<geometry>
				<sphere radius="0.011156"></sphere>
			</geometry>
			<origin xyz="0.0 0.017272000000000003 0.012470999999999996" rpy="0 0 0"></origin>
		</collision>
		<collision>
			<geometry>
				<sphere radius="0.010845"></sphere>
			</geometry>
			<origin xyz="0.0 0.016720000000000002 0.027095" rpy="0 0 0"></origin>
		</collision>
		<collision>
			<geometry>
				<sphere radius="0.010842"></sphere>
			</geometry>
			<origin xyz="-1e-06 0.017738 0.041727" rpy="0 0 0"></origin>
		</collision>
		<collision>
			<geometry>
				<sphere radius="0.011156"></sphere>
			</geometry>
			<origin xyz="0.0 0.017246 0.05629" rpy="0 0 0"></origin>
		</collision>
		<collision>
			<geometry>
				<sphere radius="0.010823"></sphere>
			</geometry>
			<origin xyz="0.0 0.016683 0.070884" rpy="0 0 0"></origin>
		</collision>
		<collision>
			<geometry>
				<sphere radius="0.010259"></sphere>
			</geometry>
			<origin xyz="0.0 0.018101000000000003 0.083924" rpy="0 0 0"></origin>
		</collision>
		<collision>
			<geometry>
				<sphere radius="0.011128"></sphere>
			</geometry>
			<origin xyz="0.0 0.01726 0.11055999999999999" rpy="0 0 0"></origin>
		</collision>
		<collision>
			<geometry>
				<sphere radius="0.010523"></sphere>
			</geometry>
			<origin xyz="0.0 0.016764 0.09643199999999999" rpy="0 0 0"></origin>
		</collision>
		<inertial>
			<origin rpy="0 0 -3.141592653589793" xyz="0 0 0"></origin>
			<mass value="0.02"></mass>
			<inertia ixx="0.01" ixy="0" ixz="0" iyy="0.01" iyz="0" izz="0.01"></inertia>
		</inertial>
	</link>
	<link name="r_gripper_l_finger_tip">
		<visual>
			<origin rpy="0 0 3.141592653589793" xyz="0 0 0"></origin>
			<geometry>
				<mesh filename="meshes/electric_gripper/fingers/half_round_tip.DAE"></mesh>
			</geometry>
		</visual>
		<collision>
			<geometry>
				<sphere radius="0.011238"></sphere>
			</geometry>
			<origin xyz="-4e-05 -0.004560000000000001 -0.025580000000000002" rpy="0 0 0"></origin>
		</collision>
		<collision>
			<geometry>
				<sphere radius="0.008784"></sphere>
			</geometry>
			<origin xyz="0.0 -0.004540000000000001 -0.014319000000000002" rpy="0 0 0"></origin>
		</collision>
		<collision>
			<geometry>
				<sphere radius="0.010767"></sphere>
			</geometry>
			<origin xyz="-0.00016 -0.003973000000000001 -0.003969000000000002" rpy="0 0 0"></origin>
		</collision>
		<collision>
			<geometry>
				<sphere radius="0.009653"></sphere>
			</geometry>
			<origin xyz="0.001441 -0.004535000000000001 -0.026942" rpy="0 0 0"></origin>
		</collision>
		<collision>
			<geometry>
				<sphere radius="0.009261"></sphere>
			</geometry>
			<origin xyz="-0.000557 -0.002666000000000001 -0.027373" rpy="0 0 0"></origin>
		</collision>
		<collision>
			<geometry>
				<sphere radius="0.009399"></sphere>
			</geometry>
			<origin xyz="-0.001143 -0.005893000000000001 -0.0027760000000000007" rpy="0 0 0"></origin>
		</collision>
		<collision>
			<geometry>
				<sphere radius="0.009041"></sphere>
			</geometry>
			<origin xyz="0.001857 -0.004562000000000001 -0.002642000000000002" rpy="0 0 0"></origin>
		</collision>
		<collision>
			<geometry>
				<sphere radius="0.008819"></sphere>
			</geometry>
			<origin xyz="0.00093 -0.0061470000000000006 -0.0027740000000000004" rpy="0 0 0"></origin>
		</collision>
		<inertial>
			<origin rpy="0 0 3.141592653589793" xyz="0 0 0"></origin>
			<mass value="0.01"></mass>
			<inertia ixx="0.01" ixy="0" ixz="0" iyy="0.01" iyz="0" izz="0.01"></inertia>
		</inertial>
	</link>
	<link name="r_gripper_r_finger_2">
		<collision>
			<geometry>
				<sphere radius="0.009249"></sphere>
			</geometry>
			<origin xyz="0.005 0.022039 0.004800000000000002" rpy="0 0 0"></origin>
		</collision>
		<collision>
			<geometry>
				<sphere radius="0.009498"></sphere>
			</geometry>
			<origin xyz="0.005 0.021657 0.011801000000000002" rpy="0 0 0"></origin>
		</collision>
		<collision>
			<geometry>
				<sphere radius="0.009206"></sphere>
			</geometry>
			<origin xyz="0.00518 0.008937999999999998 0.011980000000000001" rpy="0 0 0"></origin>
		</collision>
		<collision>
			<geometry>
				<sphere radius="0.009334"></sphere>
			</geometry>
			<origin xyz="0.005 0.009222999999999999 0.004799000000000001" rpy="0 0 0"></origin>
		</collision>
		<collision>
			<geometry>
				<sphere radius="0.00935"></sphere>
			</geometry>
			<origin xyz="0.005 -0.0037490000000000006 0.011800000000000001" rpy="0 0 0"></origin>
		</collision>
		<collision>
			<geometry>
				<sphere radius="0.009146"></sphere>
			</geometry>
			<origin xyz="0.005 -0.0162 0.011800000000000001" rpy="0 0 0"></origin>
		</collision>
		<collision>
			<geometry>
				<sphere radius="0.009587"></sphere>
			</geometry>
			<origin xyz="0.005 -0.004104000000000001 0.004800000000000002" rpy="0 0 0"></origin>
		</collision>
		<collision>
			<geometry>
				<sphere radius="0.008855"></sphere>
			</geometry>
			<origin xyz="0.005 -0.016669 0.004799000000000001" rpy="0 0 0"></origin>
		</collision>
	</link>
	<link name="r_gripper_r_finger">
		<visual>
			<origin rpy="0 0 -0.0" xyz="0 0 0"></origin>
			<geometry>
				<mesh filename="meshes/electric_gripper/fingers/extended_narrow.DAE"></mesh>
			</geometry>
		</visual>
		<collision>
			<geometry>
				<sphere radius="0.01082"></sphere>
			</geometry>
			<origin xyz="0.0 -0.017263 0.111043" rpy="0 0 0"></origin>
		</collision>
		<collision>
			<geometry>
				<sphere radius="0.011128"></sphere>
			</geometry>
			<origin xyz="0.0 -0.01725 0.09595200000000001" rpy="0 0 0"></origin>
		</collision>
		<collision>
			<geometry>
				<sphere radius="0.010846"></sphere>
			</geometry>
			<origin xyz="0.0 -0.017779000000000003 0.081315" rpy="0 0 0"></origin>
		</collision>
		<collision>
			<geometry>
				<sphere radius="0.010842"></sphere>
			</geometry>
			<origin xyz="0.0 -0.016763 0.066754" rpy="0 0 0"></origin>
		</collision>
		<collision>
			<geometry>
				<sphere radius="0.010846"></sphere>
			</geometry>
			<origin xyz="0.0 -0.017782000000000003 0.052121" rpy="0 0 0"></origin>
		</collision>
		<collision>
			<geometry>
				<sphere radius="0.010842"></sphere>
			</geometry>
			<origin xyz="0.0 -0.016765000000000002 0.037557999999999994" rpy="0 0 0"></origin>
		</collision>
		<collision>
			<geometry>
				<sphere radius="0.010819"></sphere>
			</geometry>
			<origin xyz="0.0 -0.017774 0.02296" rpy="0 0 0"></origin>
		</collision>
		<collision>
			<geometry>
				<sphere radius="0.009909"></sphere>
			</geometry>
			<origin xyz="0.0 -0.017230000000000002 0.01038" rpy="0 0 0"></origin>
		</collision>
		<inertial>
			<origin rpy="0 0 -0.0" xyz="0 0 0"></origin>
			<mass value="0.02"></mass>
			<inertia ixx="0.01" ixy="0" ixz="0" iyy="0.01" iyz="0" izz="0.01"></inertia>
		</inertial>
	</link>
	<link name="r_gripper_r_finger_tip">
		<visual>
			<origin rpy="0 0 0.0" xyz="0 0 0"></origin>
			<geometry>
				<mesh filename="meshes/electric_gripper/fingers/half_round_tip.DAE"></mesh>
			</geometry>
		</visual>
		<collision>
			<geometry>
				<sphere radius="0.011303"></sphere>
			</geometry>
			<origin xyz="0.0 0.0045000000000000005 -0.025516" rpy="0 0 0"></origin>
		</collision>
		<collision>
			<geometry>
				<sphere radius="0.009311"></sphere>
			</geometry>
			<origin xyz="0.0 0.0045000000000000005 -0.013038000000000001" rpy="0 0 0"></origin>
		</collision>
		<collision>
			<geometry>
				<sphere radius="0.010215"></sphere>
			</geometry>
			<origin xyz="-0.000399 0.0034930000000000004 -0.003470000000000001" rpy="0 0 0"></origin>
		</collision>
		<collision>
			<geometry>
				<sphere radius="0.009524"></sphere>
			</geometry>
			<origin xyz="-0.001054 0.005844 -0.002877000000000001" rpy="0 0 0"></origin>
		</collision>
		<inertial>
			<origin rpy="0 0 0.0" xyz="0 0 0"></origin>
			<mass value="0.01"></mass>
			<inertia ixx="0.01" ixy="0" ixz="0" iyy="0.01" iyz="0" izz="0.01"></inertia>
		</inertial>
	</link>
	<link name="right_gripper">
		<inertial>
			<origin rpy="0 0 0" xyz="0 0 0"></origin>
			<mass value="0.0001"></mass>
			<inertia ixx="0" ixy="0" ixz="0" iyy="0" iyz="0" izz="0.0"></inertia>
		</inertial>
	</link>
	<joint name="collision_head_1" type="fixed">
		<origin rpy="0 0 0" xyz="0.11 0 0.75"></origin>
		<parent link="base"></parent>
		<child link="collision_head_link_1"></child>
	</joint>
	<joint name="collision_head_2" type="fixed">
		<origin rpy="0 0 0" xyz="0.11 0 0.75"></origin>
		<parent link="base"></parent>
		<child link="collision_head_link_2"></child>
	</joint>
	<joint name="dummy" type="fixed">
		<origin rpy="0 0 0" xyz="0 0 0"></origin>
		<parent link="head"></parent>
		<child link="dummyhead1"></child>
	</joint>
	<joint name="torso_t0" type="fixed">
		<origin rpy="0 0 0" xyz="0 0 0"></origin>
		<parent link="base"></parent>
		<child link="torso"></child>
		<limit effort="50000" lower="-3.01" upper="3.01" velocity="10000"></limit>
	</joint>
	<joint name="left_torso_itb_fixed" type="fixed">
		<origin rpy="-1.57079632679 3.1415 0" xyz="-0.08897 0.15593 0.389125"></origin>
		<parent link="torso"></parent>
		<child link="left_torso_itb"></child>
	</joint>
	<joint name="right_torso_itb_fixed" type="fixed">
		<origin rpy="1.57079632679 0 0" xyz="-0.08897 -0.15593 0.389125"></origin>
		<parent link="torso"></parent>
		<child link="right_torso_itb"></child>
	</joint>
	<joint name="head_pan" type="fixed">
		<origin rpy="0 0 0" xyz="0.06 0 0.686"></origin>
		<axis xyz="0 0 1"></axis>
		<parent link="torso"></parent>
		<child link="head"></child>
	</joint>
	<joint name="head_nod" type="fixed">
		<origin rpy="1.75057 0 1.57079632679" xyz=".1227 0 0"></origin>
		<parent link="head"></parent>
		<child link="screen"></child>
	</joint>
	<joint name="head_camera" type="fixed">
		<origin rpy="1.75057 0 1.57079632679" xyz="0.12839 0 0.06368"></origin>
		<parent link="head"></parent>
		<child link="head_camera"></child>
	</joint>
	<joint name="display_joint" type="fixed">
		<origin rpy="0 0 0" xyz="0.0 -0.016 0.0"></origin>
		<parent link="screen"></parent>
		<child link="display"></child>
	</joint>
	<joint name="sonar_s0" type="fixed">
		<origin rpy="0 0 0" xyz="0.0947 0 .817"></origin>
		<axis xyz="0 0 1"></axis>
		<parent link="torso"></parent>
		<child link="sonar_ring"></child>
	</joint>
	<joint name="right_torso_arm_mount" type="fixed">
		<origin rpy="0 0 -0.7854" xyz="0.024645 -0.219645 0.118588"></origin>
		<parent link="torso"></parent>
		<child link="right_arm_mount"></child>
	</joint>
	<joint name="right_s0" type="revolute">
		<origin rpy="0 0 0" xyz="0.055695 0 0.011038"></origin>
		<axis xyz="0 0 1"></axis>
		<parent link="right_arm_mount"></parent>
		<child link="right_upper_shoulder"></child>
		<limit effort="50.0" lower="-1.70167993878" upper="1.70167993878" velocity="1.5"></limit>
		<dynamics damping="0.7" friction="0.0"></dynamics>
	</joint>
	<joint name="right_s1" type="revolute">
		<origin rpy="-1.57079632679 0 0" xyz="0.069 0 0.27035"></origin>
		<axis xyz="0 0 1"></axis>
		<parent link="right_upper_shoulder"></parent>
		<child link="right_lower_shoulder"></child>
		<limit effort="50.0" lower="-2.147" upper="1.047" velocity="1.5"></limit>
		<dynamics damping="0.7" friction="0.0"></dynamics>
	</joint>
	<joint name="right_e0" type="revolute">
		<origin rpy="1.57079632679 0 1.57079632679" xyz="0.102 0 0"></origin>
		<axis xyz="0 0 1"></axis>
		<parent link="right_lower_shoulder"></parent>
		<child link="right_upper_elbow"></child>
		<limit effort="50.0" lower="-3.05417993878" upper="3.05417993878" velocity="1.5"></limit>
		<dynamics damping="0.7" friction="0.0"></dynamics>
	</joint>
	<joint name="right_e0_fixed" type="fixed">
		<origin rpy="1.57079632679 0 1.57079632679" xyz="0.107 0 0"></origin>
		<axis xyz="0 0 1"></axis>
		<parent link="right_lower_shoulder"></parent>
		<child link="right_upper_elbow_visual"></child>
	</joint>
	<joint name="right_e1" type="revolute">
		<origin rpy="-1.57079632679 -1.57079632679 0" xyz="0.069 0 0.26242"></origin>
		<axis xyz="0 0 1"></axis>
		<parent link="right_upper_elbow"></parent>
		<child link="right_lower_elbow"></child>
		<limit effort="50.0" lower="-0.05" upper="2.618" velocity="1.5"></limit>
		<dynamics damping="0.7" friction="0.0"></dynamics>
	</joint>
	<joint name="right_w0" type="revolute">
		<origin rpy="1.57079632679 0 1.57079632679" xyz="0.10359 0 0"></origin>
		<axis xyz="0 0 1"></axis>
		<parent link="right_lower_elbow"></parent>
		<child link="right_upper_forearm"></child>
		<limit effort="15.0" lower="-3.059" upper="3.059" velocity="4.0"></limit>
		<dynamics damping="0.7" friction="0.0"></dynamics>
	</joint>
	<joint name="right_w0_fixed" type="fixed">
		<origin rpy="1.57079632679 0 1.57079632679" xyz="0.088 0 0"></origin>
		<axis xyz="0 0 1"></axis>
		<parent link="right_lower_elbow"></parent>
		<child link="right_upper_forearm_visual"></child>
	</joint>
	<joint name="right_w0_to_itb_fixed" type="fixed">
		<origin rpy="-1.57079632679 0 1.57079632679" xyz="-0.0565 0 0.12"></origin>
		<axis xyz="0 0 1"></axis>
		<parent link="right_upper_forearm"></parent>
		<child link="right_arm_itb"></child>
	</joint>
	<joint name="right_w1" type="revolute">
		<origin rpy="-1.57079632679 -1.57079632679 0" xyz="0.01 0 0.2707"></origin>
		<axis xyz="0 0 1"></axis>
		<parent link="right_upper_forearm"></parent>
		<child link="right_lower_forearm"></child>
		<limit effort="15.0" lower="-1.57079632679" upper="2.094" velocity="4.0"></limit>
		<dynamics damping="0.7" friction="0.0"></dynamics>
	</joint>
	<joint name="right_w2" type="revolute">
		<origin rpy="1.57079632679 0 1.57079632679" xyz="0.115975 0 0"></origin>
		<axis xyz="0 0 1"></axis>
		<parent link="right_lower_forearm"></parent>
		<child link="right_wrist"></child>
		<limit effort="15.0" lower="-3.059" upper="3.059" velocity="4.0"></limit>
		<dynamics damping="0.7" friction="0.0"></dynamics>
	</joint>
	<joint name="right_hand" type="fixed">
		<origin rpy="0 0 0" xyz="0 0 0.11355"></origin>
		<axis xyz="0 0 1"></axis>
		<parent link="right_wrist"></parent>
		<child link="right_hand"></child>
	</joint>
	<joint name="right_hand_camera" type="fixed">
		<origin rpy="0 0 -1.57079633" xyz="0.03825 0.012 0.015355"></origin>
		<parent link="right_hand"></parent>
		<child link="right_hand_camera"></child>
	</joint>
	<joint name="right_hand_camera_axis" type="fixed">
		<origin rpy="0 0 0" xyz="0.03825 0.012 0.015355"></origin>
		<parent link="right_hand"></parent>
		<child link="right_hand_camera_axis"></child>
	</joint>
	<joint name="right_hand_range" type="fixed">
		<origin rpy="0 -1.57079632679 -1.57079632679" xyz="0.032 -0.020245 0.0288"></origin>
		<parent link="right_hand"></parent>
		<child link="right_hand_range"></child>
	</joint>
	<joint name="right_hand_accelerometer" type="fixed">
		<origin rpy="0 0 0" xyz="0.00198 0.000133 -0.0146"></origin>
		<parent link="right_hand"></parent>
		<child link="right_hand_accelerometer"></child>
	</joint>
	<joint name="left_torso_arm_mount" type="fixed">
		<origin rpy="0 0 0.7854" xyz="0.024645 0.219645 0.118588"></origin>
		<parent link="torso"></parent>
		<child link="left_arm_mount"></child>
	</joint>
	<joint name="left_s0" type="revolute">
		<origin rpy="0 0 0" xyz="0.055695 0 0.011038"></origin>
		<axis xyz="0 0 1"></axis>
		<parent link="left_arm_mount"></parent>
		<child link="left_upper_shoulder"></child>
		<limit effort="50.0" lower="-1.70167993878" upper="1.70167993878" velocity="1.5"></limit>
		<dynamics damping="0.7" friction="0.0"></dynamics>
	</joint>
	<joint name="left_s1" type="revolute">
		<origin rpy="-1.57079632679 0 0" xyz="0.069 0 0.27035"></origin>
		<axis xyz="0 0 1"></axis>
		<parent link="left_upper_shoulder"></parent>
		<child link="left_lower_shoulder"></child>
		<limit effort="50.0" lower="-2.147" upper="1.047" velocity="1.5"></limit>
		<dynamics damping="0.7" friction="0.0"></dynamics>
	</joint>
	<joint name="left_e0" type="revolute">
		<origin rpy="1.57079632679 0 1.57079632679" xyz="0.102 0 0"></origin>
		<axis xyz="0 0 1"></axis>
		<parent link="left_lower_shoulder"></parent>
		<child link="left_upper_elbow"></child>
		<limit effort="50.0" lower="-3.05417993878" upper="3.05417993878" velocity="1.5"></limit>
		<dynamics damping="0.7" friction="0.0"></dynamics>
	</joint>
	<joint name="left_e0_fixed" type="fixed">
		<origin rpy="1.57079632679 0 1.57079632679" xyz="0.107 0 0"></origin>
		<axis xyz="0 0 1"></axis>
		<parent link="left_lower_shoulder"></parent>
		<child link="left_upper_elbow_visual"></child>
	</joint>
	<joint name="left_e1" type="revolute">
		<origin rpy="-1.57079632679 -1.57079632679 0" xyz="0.069 0 0.26242"></origin>
		<axis xyz="0 0 1"></axis>
		<parent link="left_upper_elbow"></parent>
		<child link="left_lower_elbow"></child>
		<limit effort="50.0" lower="-0.05" upper="2.618" velocity="1.5"></limit>
		<dynamics damping="0.7" friction="0.0"></dynamics>
	</joint>
	<joint name="left_w0" type="revolute">
		<origin rpy="1.57079632679 0 1.57079632679" xyz="0.10359 0 0"></origin>
		<axis xyz="0 0 1"></axis>
		<parent link="left_lower_elbow"></parent>
		<child link="left_upper_forearm"></child>
		<limit effort="15.0" lower="-3.059" upper="3.059" velocity="4.0"></limit>
		<dynamics damping="0.7" friction="0.0"></dynamics>
	</joint>
	<joint name="left_w0_fixed" type="fixed">
		<origin rpy="1.57079632679 0 1.57079632679" xyz="0.088 0 0"></origin>
		<axis xyz="0 0 1"></axis>
		<parent link="left_lower_elbow"></parent>
		<child link="left_upper_forearm_visual"></child>
	</joint>
	<joint name="left_w0_to_itb_fixed" type="fixed">
		<origin rpy="-1.57079632679 0 1.57079632679" xyz="-0.0565 0 0.12"></origin>
		<axis xyz="0 0 1"></axis>
		<parent link="left_upper_forearm"></parent>
		<child link="left_arm_itb"></child>
	</joint>
	<joint name="left_w1" type="revolute">
		<origin rpy="-1.57079632679 -1.57079632679 0" xyz="0.01 0 0.2707"></origin>
		<axis xyz="0 0 1"></axis>
		<parent link="left_upper_forearm"></parent>
		<child link="left_lower_forearm"></child>
		<limit effort="15.0" lower="-1.57079632679" upper="2.094" velocity="4.0"></limit>
		<dynamics damping="0.7" friction="0.0"></dynamics>
	</joint>
	<joint name="left_w2" type="revolute">
		<origin rpy="1.57079632679 0 1.57079632679" xyz="0.115975 0 0"></origin>
		<axis xyz="0 0 1"></axis>
		<parent link="left_lower_forearm"></parent>
		<child link="left_wrist"></child>
		<limit effort="15.0" lower="-3.059" upper="3.059" velocity="4.0"></limit>
		<dynamics damping="0.7" friction="0.0"></dynamics>
	</joint>
	<joint name="left_hand" type="fixed">
		<origin rpy="0 0 0" xyz="0 0 0.11355"></origin>
		<axis xyz="0 0 1"></axis>
		<parent link="left_wrist"></parent>
		<child link="left_hand"></child>
	</joint>
	<joint name="left_hand_camera" type="fixed">
		<origin rpy="0 0 -1.57079633" xyz="0.03825 0.012 0.015355"></origin>
		<parent link="left_hand"></parent>
		<child link="left_hand_camera"></child>
	</joint>
	<joint name="left_hand_camera_axis" type="fixed">
		<origin rpy="0 0 0" xyz="0.03825 0.012 0.015355"></origin>
		<parent link="left_hand"></parent>
		<child link="left_hand_camera_axis"></child>
	</joint>
	<joint name="left_hand_range" type="fixed">
		<origin rpy="0 -1.57079632679 -1.57079632679" xyz="0.032 -0.020245 0.0288"></origin>
		<parent link="left_hand"></parent>
		<child link="left_hand_range"></child>
	</joint>
	<joint name="left_hand_accelerometer" type="fixed">
		<origin rpy="0 0 0" xyz="0.00198 0.000133 -0.0146"></origin>
		<parent link="left_hand"></parent>
		<child link="left_hand_accelerometer"></child>
	</joint>
	<joint name="pedestal_fixed" type="fixed">
		<origin rpy="0 0 0" xyz="0.0 0.0 0.0"></origin>
		<parent link="torso"></parent>
		<child link="pedestal"></child>
	</joint>
	<joint name="l_gripper_l_finger_tip_joint" type="fixed">
		<origin rpy="0 0 0" xyz="0.0 0.01725 0.1127"></origin>
		<parent link="l_gripper_l_finger"></parent>
		<child link="l_gripper_l_finger_tip"></child>
	</joint>
	<joint name="l_gripper_r_finger_tip_joint" type="fixed">
		<origin rpy="0 0 0" xyz="0.0 -0.01725 0.1127"></origin>
		<parent link="l_gripper_r_finger"></parent>
		<child link="l_gripper_r_finger_tip"></child>
	</joint>
	<joint name="left_gripper_base" type="fixed">
		<origin rpy="0 0 0" xyz="0 0 0.025"></origin>
		<parent link="left_hand"></parent>
		<child link="left_gripper_base"></child>
	</joint>
	<joint name="left_endpoint" type="fixed">
		<origin rpy="0 0 0" xyz="0 0 0.13269999999999998"></origin>
		<parent link="left_gripper_base"></parent>
		<child link="left_gripper"></child>
	</joint>
	<joint name="l_gripper_l_finger_joint_2" type="fixed">
		<origin rpy="0 0 0" xyz="0.0 0.019333 0.02"></origin>
		<axis xyz="0 1 0"></axis>
		<parent link="left_gripper_base"></parent>
		<child link="l_gripper_l_finger_2"></child>
	</joint>
	<joint name="l_gripper_l_finger_joint" type="fixed">
		<origin rpy="0 0 0" xyz="0.0 0.019333 0.02"></origin>
		<axis xyz="0 1 0"></axis>
		<parent link="left_gripper_base"></parent>
		<child link="l_gripper_l_finger"></child>
	</joint>
	<joint name="l_gripper_r_finger_joint_2" type="fixed">
		<origin rpy="0 0 0" xyz="0.0 -0.019333 0.02"></origin>
		<axis xyz="0 1 0"></axis>
		<parent link="left_gripper_base"></parent>
		<child link="l_gripper_r_finger_2"></child>
	</joint>
	<joint name="l_gripper_r_finger_joint" type="fixed">
		<origin rpy="0 0 0" xyz="0.0 -0.019333 0.02"></origin>
		<axis xyz="0 1 0"></axis>
		<parent link="left_gripper_base"></parent>
		<child link="l_gripper_r_finger"></child>
	</joint>
	<joint name="r_gripper_l_finger_tip_joint" type="fixed">
		<origin rpy="0 0 0" xyz="0.0 0.01725 0.1127"></origin>
		<parent link="r_gripper_l_finger"></parent>
		<child link="r_gripper_l_finger_tip"></child>
	</joint>
	<joint name="r_gripper_r_finger_tip_joint" type="fixed">
		<origin rpy="0 0 0" xyz="0.0 -0.01725 0.1127"></origin>
		<parent link="r_gripper_r_finger"></parent>
		<child link="r_gripper_r_finger_tip"></child>
	</joint>
	<joint name="right_gripper_base" type="fixed">
		<origin rpy="0 0 0" xyz="0 0 0.025"></origin>
		<parent link="right_hand"></parent>
		<child link="right_gripper_base"></child>
	</joint>
	<joint name="right_endpoint" type="fixed">
		<origin rpy="0 0 0" xyz="0 0 0.13269999999999998"></origin>
		<parent link="right_gripper_base"></parent>
		<child link="right_gripper"></child>
	</joint>
	<joint name="r_gripper_l_finger_joint_2" type="fixed">
		<origin rpy="0 0 0" xyz="0.0 0.019333 0.02"></origin>
		<axis xyz="0 1 0"></axis>
		<parent link="right_gripper_base"></parent>
		<child link="r_gripper_l_finger_2"></child>
	</joint>
	<joint name="r_gripper_l_finger_joint" type="fixed">
		<origin rpy="0 0 0" xyz="0.0 0.019333 0.02"></origin>
		<axis xyz="0 1 0"></axis>
		<parent link="right_gripper_base"></parent>
		<child link="r_gripper_l_finger"></child>
	</joint>
	<joint name="r_gripper_r_finger_joint_2" type="fixed">
		<origin rpy="0 0 0" xyz="0.0 -0.019333 0.02"></origin>
		<axis xyz="0 1 0"></axis>
		<parent link="right_gripper_base"></parent>
		<child link="r_gripper_r_finger_2"></child>
	</joint>
	<joint name="r_gripper_r_finger_joint" type="fixed">
		<origin rpy="0 0 0" xyz="0.0 -0.019333 0.02"></origin>
		<axis xyz="0 1 0"></axis>
		<parent link="right_gripper_base"></parent>
		<child link="r_gripper_r_finger"></child>
	</joint>
	<gazebo reference="l_gripper_l_finger">
		<mu1>1000</mu1>
		<mu2>1000</mu2>
		<fdir1>0.0 0.0 1.0</fdir1>
		<kp>1e5</kp>
		<kd>1.0</kd>
	</gazebo>
	<gazebo reference="l_gripper_r_finger">
		<mu1>1000</mu1>
		<mu2>1000</mu2>
		<fdir1>0.0 0.0 1.0</fdir1>
		<kp>1e5</kp>
		<kd>1.0</kd>
	</gazebo>
	<gazebo reference="l_gripper_r_finger_joint">
		<implicitSpringDamper>1</implicitSpringDamper>
	</gazebo>
	<gazebo reference="l_gripper_l_finger_joint">
		<implicitSpringDamper>1</implicitSpringDamper>
	</gazebo>
	<gazebo reference="r_gripper_l_finger">
		<mu1>1000</mu1>
		<mu2>1000</mu2>
		<fdir1>0.0 0.0 1.0</fdir1>
		<kp>1e5</kp>
		<kd>1.0</kd>
	</gazebo>
	<gazebo reference="r_gripper_r_finger">
		<mu1>1000</mu1>
		<mu2>1000</mu2>
		<fdir1>0.0 0.0 1.0</fdir1>
		<kp>1e5</kp>
		<kd>1.0</kd>
	</gazebo>
	<gazebo reference="r_gripper_r_finger_joint">
		<implicitSpringDamper>1</implicitSpringDamper>
	</gazebo>
	<gazebo reference="r_gripper_l_finger_joint">
		<implicitSpringDamper>1</implicitSpringDamper>
	</gazebo>
	<transmission name="gripper_left1">
		<type>transmission_interface/SimpleTransmission</type>
		<joint name="l_gripper_r_finger_joint">
			<hardwareInterface>EffortJointInterface</hardwareInterface>
		</joint>
		<actuator name="gripper_l1_motor1">
			<hardwareInterface>EffortJointInterface</hardwareInterface>
			<mechanicalReduction>1</mechanicalReduction>
		</actuator>
	</transmission>
	<transmission name="gripper_left2">
		<type>transmission_interface/SimpleTransmission</type>
		<joint name="l_gripper_l_finger_joint">
			<hardwareInterface>EffortJointInterface</hardwareInterface>
		</joint>
		<actuator name="gripper_l1_motor2">
			<hardwareInterface>EffortJointInterface</hardwareInterface>
			<mechanicalReduction>1</mechanicalReduction>
		</actuator>
	</transmission>
	<transmission name="gripper_right1">
		<type>transmission_interface/SimpleTransmission</type>
		<joint name="r_gripper_r_finger_joint">
			<hardwareInterface>EffortJointInterface</hardwareInterface>
		</joint>
		<actuator name="gripper_r1_motor1">
			<hardwareInterface>EffortJointInterface</hardwareInterface>
			<mechanicalReduction>1</mechanicalReduction>
		</actuator>
	</transmission>
	<transmission name="gripper_right2">
		<type>transmission_interface/SimpleTransmission</type>
		<joint name="r_gripper_l_finger_joint">
			<hardwareInterface>EffortJointInterface</hardwareInterface>
		</joint>
		<actuator name="gripper_r1_motor2">
			<hardwareInterface>EffortJointInterface</hardwareInterface>
			<mechanicalReduction>1</mechanicalReduction>
		</actuator>
	</transmission>
</robot>